请访问：http://127.0.0.1:8081/version 来获取最新的库版本信息，确保使用最新版本的 AKShare 和 AKTools
当前的 AKTools 版本为：0.0.90，AKShare 版本为：1.16.75
点击打开 HTTP API 主页：http://127.0.0.1:8081/
点击打开接口导览：http://127.0.0.1:8081/docs
INFO:     Started server process [6461]
INFO:     Waiting for application startup.
INFO:     Application startup complete.
INFO:     Uvicorn running on http://127.0.0.1:8081 (Press CTRL+C to quit)
INFO:     127.0.0.1:63292 - "GET /api/public/stock_zh_index_spot_em HTTP/1.1" 500 Internal Server Error
ERROR:    Exception in ASGI application
Traceback (most recent call last):
  File "/Library/Frameworks/Python.framework/Versions/3.12/lib/python3.12/site-packages/urllib3/connectionpool.py", line 466, in _make_request
    self._validate_conn(conn)
  File "/Library/Frameworks/Python.framework/Versions/3.12/lib/python3.12/site-packages/urllib3/connectionpool.py", line 1095, in _validate_conn
    conn.connect()
  File "/Library/Frameworks/Python.framework/Versions/3.12/lib/python3.12/site-packages/urllib3/connection.py", line 730, in connect
    sock_and_verified = _ssl_wrap_socket_and_match_hostname(
                        ^^^^^^^^^^^^^^^^^^^^^^^^^^^^^^^^^^^^
  File "/Library/Frameworks/Python.framework/Versions/3.12/lib/python3.12/site-packages/urllib3/connection.py", line 909, in _ssl_wrap_socket_and_match_hostname
    ssl_sock = ssl_wrap_socket(
               ^^^^^^^^^^^^^^^^
  File "/Library/Frameworks/Python.framework/Versions/3.12/lib/python3.12/site-packages/urllib3/util/ssl_.py", line 469, in ssl_wrap_socket
    ssl_sock = _ssl_wrap_socket_impl(sock, context, tls_in_tls, server_hostname)
               ^^^^^^^^^^^^^^^^^^^^^^^^^^^^^^^^^^^^^^^^^^^^^^^^^^^^^^^^^^^^^^^^^
  File "/Library/Frameworks/Python.framework/Versions/3.12/lib/python3.12/site-packages/urllib3/util/ssl_.py", line 513, in _ssl_wrap_socket_impl
    return ssl_context.wrap_socket(sock, server_hostname=server_hostname)
           ^^^^^^^^^^^^^^^^^^^^^^^^^^^^^^^^^^^^^^^^^^^^^^^^^^^^^^^^^^^^^^
  File "/Library/Frameworks/Python.framework/Versions/3.12/lib/python3.12/ssl.py", line 455, in wrap_socket
    return self.sslsocket_class._create(
           ^^^^^^^^^^^^^^^^^^^^^^^^^^^^^
  File "/Library/Frameworks/Python.framework/Versions/3.12/lib/python3.12/ssl.py", line 1041, in _create
    self.do_handshake()
  File "/Library/Frameworks/Python.framework/Versions/3.12/lib/python3.12/ssl.py", line 1319, in do_handshake
    self._sslobj.do_handshake()
TimeoutError: _ssl.c:983: The handshake operation timed out

The above exception was the direct cause of the following exception:

Traceback (most recent call last):
  File "/Library/Frameworks/Python.framework/Versions/3.12/lib/python3.12/site-packages/requests/adapters.py", line 667, in send
    resp = conn.urlopen(
           ^^^^^^^^^^^^^
  File "/Library/Frameworks/Python.framework/Versions/3.12/lib/python3.12/site-packages/urllib3/connectionpool.py", line 843, in urlopen
    retries = retries.increment(
              ^^^^^^^^^^^^^^^^^^
  File "/Library/Frameworks/Python.framework/Versions/3.12/lib/python3.12/site-packages/urllib3/util/retry.py", line 474, in increment
    raise reraise(type(error), error, _stacktrace)
          ^^^^^^^^^^^^^^^^^^^^^^^^^^^^^^^^^^^^^^^^
  File "/Library/Frameworks/Python.framework/Versions/3.12/lib/python3.12/site-packages/urllib3/util/util.py", line 39, in reraise
    raise value
  File "/Library/Frameworks/Python.framework/Versions/3.12/lib/python3.12/site-packages/urllib3/connectionpool.py", line 789, in urlopen
    response = self._make_request(
               ^^^^^^^^^^^^^^^^^^^
  File "/Library/Frameworks/Python.framework/Versions/3.12/lib/python3.12/site-packages/urllib3/connectionpool.py", line 490, in _make_request
    raise new_e
  File "/Library/Frameworks/Python.framework/Versions/3.12/lib/python3.12/site-packages/urllib3/connectionpool.py", line 468, in _make_request
    self._raise_timeout(err=e, url=url, timeout_value=conn.timeout)
  File "/Library/Frameworks/Python.framework/Versions/3.12/lib/python3.12/site-packages/urllib3/connectionpool.py", line 369, in _raise_timeout
    raise ReadTimeoutError(
urllib3.exceptions.ReadTimeoutError: HTTPSConnectionPool(host='48.push2.eastmoney.com', port=443): Read timed out. (read timeout=15)

During handling of the above exception, another exception occurred:

Traceback (most recent call last):
  File "/Library/Frameworks/Python.framework/Versions/3.12/lib/python3.12/site-packages/uvicorn/protocols/http/httptools_impl.py", line 401, in run_asgi
    result = await app(  # type: ignore[func-returns-value]
             ^^^^^^^^^^^^^^^^^^^^^^^^^^^^^^^^^^^^^^^^^^^^^^
  File "/Library/Frameworks/Python.framework/Versions/3.12/lib/python3.12/site-packages/uvicorn/middleware/proxy_headers.py", line 70, in __call__
    return await self.app(scope, receive, send)
           ^^^^^^^^^^^^^^^^^^^^^^^^^^^^^^^^^^^^
  File "/Library/Frameworks/Python.framework/Versions/3.12/lib/python3.12/site-packages/fastapi/applications.py", line 1054, in __call__
    await super().__call__(scope, receive, send)
  File "/Library/Frameworks/Python.framework/Versions/3.12/lib/python3.12/site-packages/starlette/applications.py", line 112, in __call__
    await self.middleware_stack(scope, receive, send)
  File "/Library/Frameworks/Python.framework/Versions/3.12/lib/python3.12/site-packages/starlette/middleware/errors.py", line 187, in __call__
    raise exc
  File "/Library/Frameworks/Python.framework/Versions/3.12/lib/python3.12/site-packages/starlette/middleware/errors.py", line 165, in __call__
    await self.app(scope, receive, _send)
  File "/Library/Frameworks/Python.framework/Versions/3.12/lib/python3.12/site-packages/starlette/middleware/cors.py", line 85, in __call__
    await self.app(scope, receive, send)
  File "/Library/Frameworks/Python.framework/Versions/3.12/lib/python3.12/site-packages/starlette/middleware/exceptions.py", line 62, in __call__
    await wrap_app_handling_exceptions(self.app, conn)(scope, receive, send)
  File "/Library/Frameworks/Python.framework/Versions/3.12/lib/python3.12/site-packages/starlette/_exception_handler.py", line 53, in wrapped_app
    raise exc
  File "/Library/Frameworks/Python.framework/Versions/3.12/lib/python3.12/site-packages/starlette/_exception_handler.py", line 42, in wrapped_app
    await app(scope, receive, sender)
  File "/Library/Frameworks/Python.framework/Versions/3.12/lib/python3.12/site-packages/starlette/routing.py", line 715, in __call__
    await self.middleware_stack(scope, receive, send)
  File "/Library/Frameworks/Python.framework/Versions/3.12/lib/python3.12/site-packages/starlette/routing.py", line 735, in app
    await route.handle(scope, receive, send)
  File "/Library/Frameworks/Python.framework/Versions/3.12/lib/python3.12/site-packages/starlette/routing.py", line 288, in handle
    await self.app(scope, receive, send)
  File "/Library/Frameworks/Python.framework/Versions/3.12/lib/python3.12/site-packages/starlette/routing.py", line 76, in app
    await wrap_app_handling_exceptions(app, request)(scope, receive, send)
  File "/Library/Frameworks/Python.framework/Versions/3.12/lib/python3.12/site-packages/starlette/_exception_handler.py", line 53, in wrapped_app
    raise exc
  File "/Library/Frameworks/Python.framework/Versions/3.12/lib/python3.12/site-packages/starlette/_exception_handler.py", line 42, in wrapped_app
    await app(scope, receive, sender)
  File "/Library/Frameworks/Python.framework/Versions/3.12/lib/python3.12/site-packages/starlette/routing.py", line 73, in app
    response = await f(request)
               ^^^^^^^^^^^^^^^^
  File "/Library/Frameworks/Python.framework/Versions/3.12/lib/python3.12/site-packages/fastapi/routing.py", line 301, in app
    raw_response = await run_endpoint_function(
                   ^^^^^^^^^^^^^^^^^^^^^^^^^^^^
  File "/Library/Frameworks/Python.framework/Versions/3.12/lib/python3.12/site-packages/fastapi/routing.py", line 214, in run_endpoint_function
    return await run_in_threadpool(dependant.call, **values)
           ^^^^^^^^^^^^^^^^^^^^^^^^^^^^^^^^^^^^^^^^^^^^^^^^^
  File "/Library/Frameworks/Python.framework/Versions/3.12/lib/python3.12/site-packages/starlette/concurrency.py", line 37, in run_in_threadpool
    return await anyio.to_thread.run_sync(func)
           ^^^^^^^^^^^^^^^^^^^^^^^^^^^^^^^^^^^^
  File "/Library/Frameworks/Python.framework/Versions/3.12/lib/python3.12/site-packages/anyio/to_thread.py", line 56, in run_sync
    return await get_async_backend().run_sync_in_worker_thread(
           ^^^^^^^^^^^^^^^^^^^^^^^^^^^^^^^^^^^^^^^^^^^^^^^^^^^^
  File "/Library/Frameworks/Python.framework/Versions/3.12/lib/python3.12/site-packages/anyio/_backends/_asyncio.py", line 2461, in run_sync_in_worker_thread
    return await future
           ^^^^^^^^^^^^
  File "/Library/Frameworks/Python.framework/Versions/3.12/lib/python3.12/site-packages/anyio/_backends/_asyncio.py", line 962, in run
    result = context.run(func, *args)
             ^^^^^^^^^^^^^^^^^^^^^^^^
  File "/Library/Frameworks/Python.framework/Versions/3.12/lib/python3.12/site-packages/aktools/core/api.py", line 141, in root
    received_df = eval("ak." + item_id + "()")
                  ^^^^^^^^^^^^^^^^^^^^^^^^^^^^
  File "<string>", line 1, in <module>
  File "/Library/Frameworks/Python.framework/Versions/3.12/lib/python3.12/site-packages/akshare/index/index_stock_zh.py", line 241, in stock_zh_index_spot_em
    temp_df = fetch_paginated_data(url, params)
              ^^^^^^^^^^^^^^^^^^^^^^^^^^^^^^^^^
  File "/Library/Frameworks/Python.framework/Versions/3.12/lib/python3.12/site-packages/akshare/utils/func.py", line 32, in fetch_paginated_data
    r = requests.get(url, params=params, timeout=timeout)
        ^^^^^^^^^^^^^^^^^^^^^^^^^^^^^^^^^^^^^^^^^^^^^^^^^
  File "/Library/Frameworks/Python.framework/Versions/3.12/lib/python3.12/site-packages/requests/api.py", line 73, in get
    return request("get", url, params=params, **kwargs)
           ^^^^^^^^^^^^^^^^^^^^^^^^^^^^^^^^^^^^^^^^^^^^
  File "/Library/Frameworks/Python.framework/Versions/3.12/lib/python3.12/site-packages/requests/api.py", line 59, in request
    return session.request(method=method, url=url, **kwargs)
           ^^^^^^^^^^^^^^^^^^^^^^^^^^^^^^^^^^^^^^^^^^^^^^^^^
  File "/Library/Frameworks/Python.framework/Versions/3.12/lib/python3.12/site-packages/requests/sessions.py", line 589, in request
    resp = self.send(prep, **send_kwargs)
           ^^^^^^^^^^^^^^^^^^^^^^^^^^^^^^
  File "/Library/Frameworks/Python.framework/Versions/3.12/lib/python3.12/site-packages/requests/sessions.py", line 703, in send
    r = adapter.send(request, **kwargs)
        ^^^^^^^^^^^^^^^^^^^^^^^^^^^^^^^
  File "/Library/Frameworks/Python.framework/Versions/3.12/lib/python3.12/site-packages/requests/adapters.py", line 713, in send
    raise ReadTimeout(e, request=request)
requests.exceptions.ReadTimeout: HTTPSConnectionPool(host='48.push2.eastmoney.com', port=443): Read timed out. (read timeout=15)
INFO:     127.0.0.1:63308 - "GET /api/public/stock_zh_a_spot_em HTTP/1.1" 200 OK
INFO:     127.0.0.1:63572 - "GET /api/public/stock_zh_a_spot_em HTTP/1.1" 200 OK
INFO:     127.0.0.1:63572 - "GET /api/public/stock_zh_a_spot_em HTTP/1.1" 200 OK
INFO:     127.0.0.1:63572 - "GET /api/public/stock_zh_a_spot_em HTTP/1.1" 200 OK
ERROR:    Exception in ASGI application
Traceback (most recent call last):
  File "/Library/Frameworks/Python.framework/Versions/3.12/lib/python3.12/site-packages/aiohttp/connector.py", line 1122, in _wrap_create_connection
    return await self._loop.create_connection(*args, **kwargs, sock=sock)
           ^^^^^^^^^^^^^^^^^^^^^^^^^^^^^^^^^^^^^^^^^^^^^^^^^^^^^^^^^^^^^^
  File "/Library/Frameworks/Python.framework/Versions/3.12/lib/python3.12/asyncio/base_events.py", line 1148, in create_connection
    transport, protocol = await self._create_connection_transport(
                          ^^^^^^^^^^^^^^^^^^^^^^^^^^^^^^^^^^^^^^^^
  File "/Library/Frameworks/Python.framework/Versions/3.12/lib/python3.12/asyncio/base_events.py", line 1181, in _create_connection_transport
    await waiter
  File "/Library/Frameworks/Python.framework/Versions/3.12/lib/python3.12/asyncio/futures.py", line 291, in __await__
    yield self  # This tells Task to wait for completion.
    ^^^^^^^^^^
  File "/Library/Frameworks/Python.framework/Versions/3.12/lib/python3.12/asyncio/tasks.py", line 385, in __wakeup
    future.result()
  File "/Library/Frameworks/Python.framework/Versions/3.12/lib/python3.12/asyncio/futures.py", line 198, in result
    raise exc
asyncio.exceptions.CancelledError

The above exception was the direct cause of the following exception:

Traceback (most recent call last):
  File "/Library/Frameworks/Python.framework/Versions/3.12/lib/python3.12/site-packages/aiohttp/client.py", line 703, in _request
    conn = await self._connector.connect(
           ^^^^^^^^^^^^^^^^^^^^^^^^^^^^^^
  File "/Library/Frameworks/Python.framework/Versions/3.12/lib/python3.12/site-packages/aiohttp/connector.py", line 548, in connect
    proto = await self._create_connection(req, traces, timeout)
            ^^^^^^^^^^^^^^^^^^^^^^^^^^^^^^^^^^^^^^^^^^^^^^^^^^^
  File "/Library/Frameworks/Python.framework/Versions/3.12/lib/python3.12/site-packages/aiohttp/connector.py", line 1056, in _create_connection
    _, proto = await self._create_direct_connection(req, traces, timeout)
               ^^^^^^^^^^^^^^^^^^^^^^^^^^^^^^^^^^^^^^^^^^^^^^^^^^^^^^^^^^
  File "/Library/Frameworks/Python.framework/Versions/3.12/lib/python3.12/site-packages/aiohttp/connector.py", line 1400, in _create_direct_connection
    raise last_exc
  File "/Library/Frameworks/Python.framework/Versions/3.12/lib/python3.12/site-packages/aiohttp/connector.py", line 1369, in _create_direct_connection
    transp, proto = await self._wrap_create_connection(
                    ^^^^^^^^^^^^^^^^^^^^^^^^^^^^^^^^^^^
  File "/Library/Frameworks/Python.framework/Versions/3.12/lib/python3.12/site-packages/aiohttp/connector.py", line 1112, in _wrap_create_connection
    async with ceil_timeout(
               ^^^^^^^^^^^^^
  File "/Library/Frameworks/Python.framework/Versions/3.12/lib/python3.12/asyncio/timeouts.py", line 115, in __aexit__
    raise TimeoutError from exc_val
TimeoutError

The above exception was the direct cause of the following exception:

Traceback (most recent call last):
  File "/Library/Frameworks/Python.framework/Versions/3.12/lib/python3.12/site-packages/uvicorn/protocols/http/httptools_impl.py", line 401, in run_asgi
    result = await app(  # type: ignore[func-returns-value]
             ^^^^^^^^^^^^^^^^^^^^^^^^^^^^^^^^^^^^^^^^^^^^^^
  File "/Library/Frameworks/Python.framework/Versions/3.12/lib/python3.12/site-packages/uvicorn/middleware/proxy_headers.py", line 70, in __call__
    return await self.app(scope, receive, send)
           ^^^^^^^^^^^^^^^^^^^^^^^^^^^^^^^^^^^^
  File "/Library/Frameworks/Python.framework/Versions/3.12/lib/python3.12/site-packages/fastapi/applications.py", line 1054, in __call__
    await super().__call__(scope, receive, send)
  File "/Library/Frameworks/Python.framework/Versions/3.12/lib/python3.12/site-packages/starlette/applications.py", line 112, in __call__
    await self.middleware_stack(scope, receive, send)
  File "/Library/Frameworks/Python.framework/Versions/3.12/lib/python3.12/site-packages/starlette/middleware/errors.py", line 187, in __call__
    raise exc
  File "/Library/Frameworks/Python.framework/Versions/3.12/lib/python3.12/site-packages/starlette/middleware/errors.py", line 165, in __call__
    await self.app(scope, receive, _send)
  File "/Library/Frameworks/Python.framework/Versions/3.12/lib/python3.12/site-packages/starlette/middleware/cors.py", line 85, in __call__
    await self.app(scope, receive, send)
  File "/Library/Frameworks/Python.framework/Versions/3.12/lib/python3.12/site-packages/starlette/middleware/exceptions.py", line 62, in __call__
    await wrap_app_handling_exceptions(self.app, conn)(scope, receive, send)
  File "/Library/Frameworks/Python.framework/Versions/3.12/lib/python3.12/site-packages/starlette/_exception_handler.py", line 53, in wrapped_app
    raise exc
  File "/Library/Frameworks/Python.framework/Versions/3.12/lib/python3.12/site-packages/starlette/_exception_handler.py", line 42, in wrapped_app
    await app(scope, receive, sender)
  File "/Library/Frameworks/Python.framework/Versions/3.12/lib/python3.12/site-packages/starlette/routing.py", line 715, in __call__
    await self.middleware_stack(scope, receive, send)
  File "/Library/Frameworks/Python.framework/Versions/3.12/lib/python3.12/site-packages/starlette/routing.py", line 735, in app
    await route.handle(scope, receive, send)
  File "/Library/Frameworks/Python.framework/Versions/3.12/lib/python3.12/site-packages/starlette/routing.py", line 288, in handle
    await self.app(scope, receive, send)
  File "/Library/Frameworks/Python.framework/Versions/3.12/lib/python3.12/site-packages/starlette/routing.py", line 76, in app
    await wrap_app_handling_exceptions(app, request)(scope, receive, send)
  File "/Library/Frameworks/Python.framework/Versions/3.12/lib/python3.12/site-packages/starlette/_exception_handler.py", line 53, in wrapped_app
    raise exc
  File "/Library/Frameworks/Python.framework/Versions/3.12/lib/python3.12/site-packages/starlette/_exception_handler.py", line 42, in wrapped_app
    await app(scope, receive, sender)
  File "/Library/Frameworks/Python.framework/Versions/3.12/lib/python3.12/site-packages/starlette/routing.py", line 73, in app
    response = await f(request)
               ^^^^^^^^^^^^^^^^
  File "/Library/Frameworks/Python.framework/Versions/3.12/lib/python3.12/site-packages/fastapi/routing.py", line 301, in app
    raw_response = await run_endpoint_function(
                   ^^^^^^^^^^^^^^^^^^^^^^^^^^^^
  File "/Library/Frameworks/Python.framework/Versions/3.12/lib/python3.12/site-packages/fastapi/routing.py", line 214, in run_endpoint_function
    return await run_in_threadpool(dependant.call, **values)
           ^^^^^^^^^^^^^^^^^^^^^^^^^^^^^^^^^^^^^^^^^^^^^^^^^
  File "/Library/Frameworks/Python.framework/Versions/3.12/lib/python3.12/site-packages/starlette/concurrency.py", line 37, in run_in_threadpool
    return await anyio.to_thread.run_sync(func)
           ^^^^^^^^^^^^^^^^^^^^^^^^^^^^^^^^^^^^
  File "/Library/Frameworks/Python.framework/Versions/3.12/lib/python3.12/site-packages/anyio/to_thread.py", line 56, in run_sync
    return await get_async_backend().run_sync_in_worker_thread(
           ^^^^^^^^^^^^^^^^^^^^^^^^^^^^^^^^^^^^^^^^^^^^^^^^^^^^
  File "/Library/Frameworks/Python.framework/Versions/3.12/lib/python3.12/site-packages/anyio/_backends/_asyncio.py", line 2461, in run_sync_in_worker_thread
    return await future
           ^^^^^^^^^^^^
  File "/Library/Frameworks/Python.framework/Versions/3.12/lib/python3.12/asyncio/futures.py", line 291, in __await__
    yield self  # This tells Task to wait for completion.
    ^^^^^^^^^^
  File "/Library/Frameworks/Python.framework/Versions/3.12/lib/python3.12/asyncio/tasks.py", line 385, in __wakeup
    future.result()
  File "/Library/Frameworks/Python.framework/Versions/3.12/lib/python3.12/asyncio/futures.py", line 203, in result
    raise self._exception.with_traceback(self._exception_tb)
  File "/Library/Frameworks/Python.framework/Versions/3.12/lib/python3.12/site-packages/anyio/_backends/_asyncio.py", line 962, in run
    result = context.run(func, *args)
             ^^^^^^^^^^^^^^^^^^^^^^^^
  File "/Library/Frameworks/Python.framework/Versions/3.12/lib/python3.12/site-packages/aktools/core/api.py", line 141, in root
    received_df = eval("ak." + item_id + "()")
                  ^^^^^^^^^^^^^^^^^^^^^^^^^^^^
  File "<string>", line 1, in <module>
  File "/Library/Frameworks/Python.framework/Versions/3.12/lib/python3.12/site-packages/akshare/stock_a/stock_zh_a_spot.py", line 231, in stock_zh_a_spot_em
    return asyncio.run(stock_zh_a_spot_em_async())
           ^^^^^^^^^^^^^^^^^^^^^^^^^^^^^^^^^^^^^^^
  File "/Library/Frameworks/Python.framework/Versions/3.12/lib/python3.12/site-packages/nest_asyncio.py", line 30, in run
    return loop.run_until_complete(task)
           ^^^^^^^^^^^^^^^^^^^^^^^^^^^^^
  File "/Library/Frameworks/Python.framework/Versions/3.12/lib/python3.12/site-packages/nest_asyncio.py", line 98, in run_until_complete
    return f.result()
           ^^^^^^^^^^
  File "/Library/Frameworks/Python.framework/Versions/3.12/lib/python3.12/asyncio/futures.py", line 203, in result
    raise self._exception.with_traceback(self._exception_tb)
  File "/Library/Frameworks/Python.framework/Versions/3.12/lib/python3.12/asyncio/tasks.py", line 314, in __step_run_and_handle_result
    result = coro.send(None)
             ^^^^^^^^^^^^^^^
  File "/Library/Frameworks/Python.framework/Versions/3.12/lib/python3.12/site-packages/akshare/stock_a/stock_zh_a_spot.py", line 217, in stock_zh_a_spot_em_async
    results = await fetch_all_pages_async(url, params)
              ^^^^^^^^^^^^^^^^^^^^^^^^^^^^^^^^^^^^^^^^
  File "/Library/Frameworks/Python.framework/Versions/3.12/lib/python3.12/site-packages/akshare/stock_a/stock_zh_a_spot.py", line 53, in fetch_all_pages_async
    results = await asyncio.gather(*tasks)
              ^^^^^^^^^^^^^^^^^^^^^^^^^^^^
  File "/Library/Frameworks/Python.framework/Versions/3.12/lib/python3.12/asyncio/tasks.py", line 385, in __wakeup
    future.result()
  File "/Library/Frameworks/Python.framework/Versions/3.12/lib/python3.12/asyncio/tasks.py", line 316, in __step_run_and_handle_result
    result = coro.throw(exc)
             ^^^^^^^^^^^^^^^
  File "/Library/Frameworks/Python.framework/Versions/3.12/lib/python3.12/site-packages/akshare/stock_a/stock_zh_a_spot.py", line 21, in fetch_single_page
    async with session.get(url, params=params, ssl=False) as response:
               ^^^^^^^^^^^^^^^^^^^^^^^^^^^^^^^^^^^^^^^^^^
  File "/Library/Frameworks/Python.framework/Versions/3.12/lib/python3.12/site-packages/aiohttp/client.py", line 1425, in __aenter__
    self._resp: _RetType = await self._coro
                           ^^^^^^^^^^^^^^^^
  File "/Library/Frameworks/Python.framework/Versions/3.12/lib/python3.12/site-packages/aiohttp/client.py", line 707, in _request
    raise ConnectionTimeoutError(
aiohttp.client_exceptions.ConnectionTimeoutError: Connection timeout to host https://82.push2.eastmoney.com/api/qt/clist/get
