请访问：http://127.0.0.1:8081/version 来获取最新的库版本信息，确保使用最新版本的 AKShare 和 AKTools
当前的 AKTools 版本为：0.0.90，AKShare 版本为：1.16.75
点击打开 HTTP API 主页：http://127.0.0.1:8081/
点击打开接口导览：http://127.0.0.1:8081/docs
INFO:     Started server process [62951]
INFO:     Waiting for application startup.
INFO:     Application startup complete.
INFO:     Uvicorn running on http://127.0.0.1:8081 (Press CTRL+C to quit)
  0%|          | 0/2 [00:00<?, ?it/s] 50%|█████     | 1/2 [00:03<00:03,  3.45s/it]100%|██████████| 2/2 [00:05<00:00,  2.49s/it]                                             INFO:     127.0.0.1:56769 - "GET /api/public/stock_zh_index_spot_em HTTP/1.1" 200 OK
INFO:     127.0.0.1:56778 - "GET /api/public/stock_zh_a_spot_em HTTP/1.1" 200 OK
  0%|          | 0/2 [00:00<?, ?it/s] 50%|█████     | 1/2 [00:03<00:03,  3.69s/it]100%|██████████| 2/2 [00:11<00:00,  6.22s/it]                                               0%|          | 0/2 [00:00<?, ?it/s] 50%|█████     | 1/2 [00:04<00:04,  4.43s/it]100%|██████████| 2/2 [00:09<00:00,  5.02s/it]                                             INFO:     127.0.0.1:56927 - "GET /api/public/stock_zh_index_spot_em HTTP/1.1" 200 OK
  0%|          | 0/2 [00:00<?, ?it/s] 50%|█████     | 1/2 [00:05<00:05,  5.96s/it]ERROR:    Exception in ASGI application
Traceback (most recent call last):
  File "/Library/Frameworks/Python.framework/Versions/3.12/lib/python3.12/site-packages/aiohttp/connector.py", line 1122, in _wrap_create_connection
    return await self._loop.create_connection(*args, **kwargs, sock=sock)
           ^^^^^^^^^^^^^^^^^^^^^^^^^^^^^^^^^^^^^^^^^^^^^^^^^^^^^^^^^^^^^^
  File "/Library/Frameworks/Python.framework/Versions/3.12/lib/python3.12/asyncio/base_events.py", line 1148, in create_connection
    transport, protocol = await self._create_connection_transport(
                          ^^^^^^^^^^^^^^^^^^^^^^^^^^^^^^^^^^^^^^^^
  File "/Library/Frameworks/Python.framework/Versions/3.12/lib/python3.12/asyncio/base_events.py", line 1181, in _create_connection_transport
    await waiter
  File "/Library/Frameworks/Python.framework/Versions/3.12/lib/python3.12/asyncio/futures.py", line 291, in __await__
    yield self  # This tells Task to wait for completion.
    ^^^^^^^^^^
  File "/Library/Frameworks/Python.framework/Versions/3.12/lib/python3.12/asyncio/tasks.py", line 385, in __wakeup
    future.result()
  File "/Library/Frameworks/Python.framework/Versions/3.12/lib/python3.12/asyncio/futures.py", line 198, in result
    raise exc
asyncio.exceptions.CancelledError

The above exception was the direct cause of the following exception:

Traceback (most recent call last):
  File "/Library/Frameworks/Python.framework/Versions/3.12/lib/python3.12/site-packages/aiohttp/client.py", line 703, in _request
    conn = await self._connector.connect(
           ^^^^^^^^^^^^^^^^^^^^^^^^^^^^^^
  File "/Library/Frameworks/Python.framework/Versions/3.12/lib/python3.12/site-packages/aiohttp/connector.py", line 548, in connect
    proto = await self._create_connection(req, traces, timeout)
            ^^^^^^^^^^^^^^^^^^^^^^^^^^^^^^^^^^^^^^^^^^^^^^^^^^^
  File "/Library/Frameworks/Python.framework/Versions/3.12/lib/python3.12/site-packages/aiohttp/connector.py", line 1056, in _create_connection
    _, proto = await self._create_direct_connection(req, traces, timeout)
               ^^^^^^^^^^^^^^^^^^^^^^^^^^^^^^^^^^^^^^^^^^^^^^^^^^^^^^^^^^
  File "/Library/Frameworks/Python.framework/Versions/3.12/lib/python3.12/site-packages/aiohttp/connector.py", line 1400, in _create_direct_connection
    raise last_exc
  File "/Library/Frameworks/Python.framework/Versions/3.12/lib/python3.12/site-packages/aiohttp/connector.py", line 1369, in _create_direct_connection
    transp, proto = await self._wrap_create_connection(
                    ^^^^^^^^^^^^^^^^^^^^^^^^^^^^^^^^^^^
  File "/Library/Frameworks/Python.framework/Versions/3.12/lib/python3.12/site-packages/aiohttp/connector.py", line 1112, in _wrap_create_connection
    async with ceil_timeout(
               ^^^^^^^^^^^^^
  File "/Library/Frameworks/Python.framework/Versions/3.12/lib/python3.12/asyncio/timeouts.py", line 115, in __aexit__
    raise TimeoutError from exc_val
TimeoutError

The above exception was the direct cause of the following exception:

Traceback (most recent call last):
  File "/Library/Frameworks/Python.framework/Versions/3.12/lib/python3.12/site-packages/uvicorn/protocols/http/httptools_impl.py", line 401, in run_asgi
    result = await app(  # type: ignore[func-returns-value]
             ^^^^^^^^^^^^^^^^^^^^^^^^^^^^^^^^^^^^^^^^^^^^^^
  File "/Library/Frameworks/Python.framework/Versions/3.12/lib/python3.12/site-packages/uvicorn/middleware/proxy_headers.py", line 70, in __call__
    return await self.app(scope, receive, send)
           ^^^^^^^^^^^^^^^^^^^^^^^^^^^^^^^^^^^^
  File "/Library/Frameworks/Python.framework/Versions/3.12/lib/python3.12/site-packages/fastapi/applications.py", line 1054, in __call__
    await super().__call__(scope, receive, send)
  File "/Library/Frameworks/Python.framework/Versions/3.12/lib/python3.12/site-packages/starlette/applications.py", line 112, in __call__
    await self.middleware_stack(scope, receive, send)
  File "/Library/Frameworks/Python.framework/Versions/3.12/lib/python3.12/site-packages/starlette/middleware/errors.py", line 187, in __call__
    raise exc
  File "/Library/Frameworks/Python.framework/Versions/3.12/lib/python3.12/site-packages/starlette/middleware/errors.py", line 165, in __call__
    await self.app(scope, receive, _send)
  File "/Library/Frameworks/Python.framework/Versions/3.12/lib/python3.12/site-packages/starlette/middleware/cors.py", line 85, in __call__
    await self.app(scope, receive, send)
  File "/Library/Frameworks/Python.framework/Versions/3.12/lib/python3.12/site-packages/starlette/middleware/exceptions.py", line 62, in __call__
    await wrap_app_handling_exceptions(self.app, conn)(scope, receive, send)
  File "/Library/Frameworks/Python.framework/Versions/3.12/lib/python3.12/site-packages/starlette/_exception_handler.py", line 53, in wrapped_app
    raise exc
  File "/Library/Frameworks/Python.framework/Versions/3.12/lib/python3.12/site-packages/starlette/_exception_handler.py", line 42, in wrapped_app
    await app(scope, receive, sender)
  File "/Library/Frameworks/Python.framework/Versions/3.12/lib/python3.12/site-packages/starlette/routing.py", line 715, in __call__
    await self.middleware_stack(scope, receive, send)
  File "/Library/Frameworks/Python.framework/Versions/3.12/lib/python3.12/site-packages/starlette/routing.py", line 735, in app
    await route.handle(scope, receive, send)
  File "/Library/Frameworks/Python.framework/Versions/3.12/lib/python3.12/site-packages/starlette/routing.py", line 288, in handle
    await self.app(scope, receive, send)
  File "/Library/Frameworks/Python.framework/Versions/3.12/lib/python3.12/site-packages/starlette/routing.py", line 76, in app
    await wrap_app_handling_exceptions(app, request)(scope, receive, send)
  File "/Library/Frameworks/Python.framework/Versions/3.12/lib/python3.12/site-packages/starlette/_exception_handler.py", line 53, in wrapped_app
    raise exc
  File "/Library/Frameworks/Python.framework/Versions/3.12/lib/python3.12/site-packages/starlette/_exception_handler.py", line 42, in wrapped_app
    await app(scope, receive, sender)
  File "/Library/Frameworks/Python.framework/Versions/3.12/lib/python3.12/site-packages/starlette/routing.py", line 73, in app
    response = await f(request)
               ^^^^^^^^^^^^^^^^
  File "/Library/Frameworks/Python.framework/Versions/3.12/lib/python3.12/site-packages/fastapi/routing.py", line 301, in app
    raw_response = await run_endpoint_function(
                   ^^^^^^^^^^^^^^^^^^^^^^^^^^^^
  File "/Library/Frameworks/Python.framework/Versions/3.12/lib/python3.12/site-packages/fastapi/routing.py", line 214, in run_endpoint_function
    return await run_in_threadpool(dependant.call, **values)
           ^^^^^^^^^^^^^^^^^^^^^^^^^^^^^^^^^^^^^^^^^^^^^^^^^
  File "/Library/Frameworks/Python.framework/Versions/3.12/lib/python3.12/site-packages/starlette/concurrency.py", line 37, in run_in_threadpool
    return await anyio.to_thread.run_sync(func)
           ^^^^^^^^^^^^^^^^^^^^^^^^^^^^^^^^^^^^
  File "/Library/Frameworks/Python.framework/Versions/3.12/lib/python3.12/site-packages/anyio/to_thread.py", line 56, in run_sync
    return await get_async_backend().run_sync_in_worker_thread(
           ^^^^^^^^^^^^^^^^^^^^^^^^^^^^^^^^^^^^^^^^^^^^^^^^^^^^
  File "/Library/Frameworks/Python.framework/Versions/3.12/lib/python3.12/site-packages/anyio/_backends/_asyncio.py", line 2461, in run_sync_in_worker_thread
    return await future
           ^^^^^^^^^^^^
  File "/Library/Frameworks/Python.framework/Versions/3.12/lib/python3.12/asyncio/futures.py", line 291, in __await__
    yield self  # This tells Task to wait for completion.
    ^^^^^^^^^^
  File "/Library/Frameworks/Python.framework/Versions/3.12/lib/python3.12/asyncio/tasks.py", line 385, in __wakeup
    future.result()
  File "/Library/Frameworks/Python.framework/Versions/3.12/lib/python3.12/asyncio/futures.py", line 203, in result
    raise self._exception.with_traceback(self._exception_tb)
  File "/Library/Frameworks/Python.framework/Versions/3.12/lib/python3.12/site-packages/anyio/_backends/_asyncio.py", line 962, in run
    result = context.run(func, *args)
             ^^^^^^^^^^^^^^^^^^^^^^^^
  File "/Library/Frameworks/Python.framework/Versions/3.12/lib/python3.12/site-packages/aktools/core/api.py", line 141, in root
    received_df = eval("ak." + item_id + "()")
                  ^^^^^^^^^^^^^^^^^^^^^^^^^^^^
  File "<string>", line 1, in <module>
  File "/Library/Frameworks/Python.framework/Versions/3.12/lib/python3.12/site-packages/akshare/stock_a/stock_zh_a_spot.py", line 231, in stock_zh_a_spot_em
    return asyncio.run(stock_zh_a_spot_em_async())
           ^^^^^^^^^^^^^^^^^^^^^^^^^^^^^^^^^^^^^^^
  File "/Library/Frameworks/Python.framework/Versions/3.12/lib/python3.12/site-packages/nest_asyncio.py", line 30, in run
    return loop.run_until_complete(task)
           ^^^^^^^^^^^^^^^^^^^^^^^^^^^^^
  File "/Library/Frameworks/Python.framework/Versions/3.12/lib/python3.12/site-packages/nest_asyncio.py", line 98, in run_until_complete
    return f.result()
           ^^^^^^^^^^
  File "/Library/Frameworks/Python.framework/Versions/3.12/lib/python3.12/asyncio/futures.py", line 203, in result
    raise self._exception.with_traceback(self._exception_tb)
  File "/Library/Frameworks/Python.framework/Versions/3.12/lib/python3.12/asyncio/tasks.py", line 314, in __step_run_and_handle_result
    result = coro.send(None)
             ^^^^^^^^^^^^^^^
  File "/Library/Frameworks/Python.framework/Versions/3.12/lib/python3.12/site-packages/akshare/stock_a/stock_zh_a_spot.py", line 217, in stock_zh_a_spot_em_async
    results = await fetch_all_pages_async(url, params)
              ^^^^^^^^^^^^^^^^^^^^^^^^^^^^^^^^^^^^^^^^
  File "/Library/Frameworks/Python.framework/Versions/3.12/lib/python3.12/site-packages/akshare/stock_a/stock_zh_a_spot.py", line 53, in fetch_all_pages_async
    results = await asyncio.gather(*tasks)
              ^^^^^^^^^^^^^^^^^^^^^^^^^^^^
  File "/Library/Frameworks/Python.framework/Versions/3.12/lib/python3.12/asyncio/tasks.py", line 385, in __wakeup
    future.result()
  File "/Library/Frameworks/Python.framework/Versions/3.12/lib/python3.12/asyncio/tasks.py", line 316, in __step_run_and_handle_result
    result = coro.throw(exc)
             ^^^^^^^^^^^^^^^
  File "/Library/Frameworks/Python.framework/Versions/3.12/lib/python3.12/site-packages/akshare/stock_a/stock_zh_a_spot.py", line 21, in fetch_single_page
    async with session.get(url, params=params, ssl=False) as response:
               ^^^^^^^^^^^^^^^^^^^^^^^^^^^^^^^^^^^^^^^^^^
  File "/Library/Frameworks/Python.framework/Versions/3.12/lib/python3.12/site-packages/aiohttp/client.py", line 1425, in __aenter__
    self._resp: _RetType = await self._coro
                           ^^^^^^^^^^^^^^^^
  File "/Library/Frameworks/Python.framework/Versions/3.12/lib/python3.12/site-packages/aiohttp/client.py", line 707, in _request
    raise ConnectionTimeoutError(
aiohttp.client_exceptions.ConnectionTimeoutError: Connection timeout to host https://82.push2.eastmoney.com/api/qt/clist/get

  0%|          | 0/2 [00:00<?, ?it/s][A
 50%|█████     | 1/2 [00:02<00:02,  2.06s/it][A
100%|██████████| 2/2 [00:04<00:00,  2.10s/it][A
                                             [AINFO:     127.0.0.1:57038 - "GET /api/public/stock_zh_index_spot_em HTTP/1.1" 200 OK
100%|██████████| 2/2 [00:17<00:00,  9.24s/it]                                             INFO:     127.0.0.1:57025 - "GET /api/public/stock_zh_index_spot_em HTTP/1.1" 200 OK
  0%|          | 0/2 [00:00<?, ?it/s] 50%|█████     | 1/2 [00:01<00:01,  1.87s/it]100%|██████████| 2/2 [00:12<00:00,  6.74s/it]                                             INFO:     127.0.0.1:57183 - "GET /api/public/stock_zh_index_spot_em HTTP/1.1" 200 OK
  0%|          | 0/2 [00:00<?, ?it/s] 50%|█████     | 1/2 [00:04<00:04,  4.43s/it]ERROR:    Exception in ASGI application
Traceback (most recent call last):
  File "/Library/Frameworks/Python.framework/Versions/3.12/lib/python3.12/site-packages/aiohttp/connector.py", line 1122, in _wrap_create_connection
    return await self._loop.create_connection(*args, **kwargs, sock=sock)
           ^^^^^^^^^^^^^^^^^^^^^^^^^^^^^^^^^^^^^^^^^^^^^^^^^^^^^^^^^^^^^^
  File "/Library/Frameworks/Python.framework/Versions/3.12/lib/python3.12/asyncio/base_events.py", line 1148, in create_connection
    transport, protocol = await self._create_connection_transport(
                          ^^^^^^^^^^^^^^^^^^^^^^^^^^^^^^^^^^^^^^^^
  File "/Library/Frameworks/Python.framework/Versions/3.12/lib/python3.12/asyncio/base_events.py", line 1181, in _create_connection_transport
    await waiter
  File "/Library/Frameworks/Python.framework/Versions/3.12/lib/python3.12/asyncio/futures.py", line 291, in __await__
    yield self  # This tells Task to wait for completion.
    ^^^^^^^^^^
  File "/Library/Frameworks/Python.framework/Versions/3.12/lib/python3.12/asyncio/tasks.py", line 385, in __wakeup
    future.result()
  File "/Library/Frameworks/Python.framework/Versions/3.12/lib/python3.12/asyncio/futures.py", line 198, in result
    raise exc
asyncio.exceptions.CancelledError

The above exception was the direct cause of the following exception:

Traceback (most recent call last):
  File "/Library/Frameworks/Python.framework/Versions/3.12/lib/python3.12/site-packages/aiohttp/client.py", line 703, in _request
    conn = await self._connector.connect(
           ^^^^^^^^^^^^^^^^^^^^^^^^^^^^^^
  File "/Library/Frameworks/Python.framework/Versions/3.12/lib/python3.12/site-packages/aiohttp/connector.py", line 548, in connect
    proto = await self._create_connection(req, traces, timeout)
            ^^^^^^^^^^^^^^^^^^^^^^^^^^^^^^^^^^^^^^^^^^^^^^^^^^^
  File "/Library/Frameworks/Python.framework/Versions/3.12/lib/python3.12/site-packages/aiohttp/connector.py", line 1056, in _create_connection
    _, proto = await self._create_direct_connection(req, traces, timeout)
               ^^^^^^^^^^^^^^^^^^^^^^^^^^^^^^^^^^^^^^^^^^^^^^^^^^^^^^^^^^
  File "/Library/Frameworks/Python.framework/Versions/3.12/lib/python3.12/site-packages/aiohttp/connector.py", line 1400, in _create_direct_connection
    raise last_exc
  File "/Library/Frameworks/Python.framework/Versions/3.12/lib/python3.12/site-packages/aiohttp/connector.py", line 1369, in _create_direct_connection
    transp, proto = await self._wrap_create_connection(
                    ^^^^^^^^^^^^^^^^^^^^^^^^^^^^^^^^^^^
  File "/Library/Frameworks/Python.framework/Versions/3.12/lib/python3.12/site-packages/aiohttp/connector.py", line 1112, in _wrap_create_connection
    async with ceil_timeout(
               ^^^^^^^^^^^^^
  File "/Library/Frameworks/Python.framework/Versions/3.12/lib/python3.12/asyncio/timeouts.py", line 115, in __aexit__
    raise TimeoutError from exc_val
TimeoutError

The above exception was the direct cause of the following exception:

Traceback (most recent call last):
  File "/Library/Frameworks/Python.framework/Versions/3.12/lib/python3.12/site-packages/uvicorn/protocols/http/httptools_impl.py", line 401, in run_asgi
    result = await app(  # type: ignore[func-returns-value]
             ^^^^^^^^^^^^^^^^^^^^^^^^^^^^^^^^^^^^^^^^^^^^^^
  File "/Library/Frameworks/Python.framework/Versions/3.12/lib/python3.12/site-packages/uvicorn/middleware/proxy_headers.py", line 70, in __call__
    return await self.app(scope, receive, send)
           ^^^^^^^^^^^^^^^^^^^^^^^^^^^^^^^^^^^^
  File "/Library/Frameworks/Python.framework/Versions/3.12/lib/python3.12/site-packages/fastapi/applications.py", line 1054, in __call__
    await super().__call__(scope, receive, send)
  File "/Library/Frameworks/Python.framework/Versions/3.12/lib/python3.12/site-packages/starlette/applications.py", line 112, in __call__
    await self.middleware_stack(scope, receive, send)
  File "/Library/Frameworks/Python.framework/Versions/3.12/lib/python3.12/site-packages/starlette/middleware/errors.py", line 187, in __call__
    raise exc
  File "/Library/Frameworks/Python.framework/Versions/3.12/lib/python3.12/site-packages/starlette/middleware/errors.py", line 165, in __call__
    await self.app(scope, receive, _send)
  File "/Library/Frameworks/Python.framework/Versions/3.12/lib/python3.12/site-packages/starlette/middleware/cors.py", line 85, in __call__
    await self.app(scope, receive, send)
  File "/Library/Frameworks/Python.framework/Versions/3.12/lib/python3.12/site-packages/starlette/middleware/exceptions.py", line 62, in __call__
    await wrap_app_handling_exceptions(self.app, conn)(scope, receive, send)
  File "/Library/Frameworks/Python.framework/Versions/3.12/lib/python3.12/site-packages/starlette/_exception_handler.py", line 53, in wrapped_app
    raise exc
  File "/Library/Frameworks/Python.framework/Versions/3.12/lib/python3.12/site-packages/starlette/_exception_handler.py", line 42, in wrapped_app
    await app(scope, receive, sender)
  File "/Library/Frameworks/Python.framework/Versions/3.12/lib/python3.12/site-packages/starlette/routing.py", line 715, in __call__
    await self.middleware_stack(scope, receive, send)
  File "/Library/Frameworks/Python.framework/Versions/3.12/lib/python3.12/site-packages/starlette/routing.py", line 735, in app
    await route.handle(scope, receive, send)
  File "/Library/Frameworks/Python.framework/Versions/3.12/lib/python3.12/site-packages/starlette/routing.py", line 288, in handle
    await self.app(scope, receive, send)
  File "/Library/Frameworks/Python.framework/Versions/3.12/lib/python3.12/site-packages/starlette/routing.py", line 76, in app
    await wrap_app_handling_exceptions(app, request)(scope, receive, send)
  File "/Library/Frameworks/Python.framework/Versions/3.12/lib/python3.12/site-packages/starlette/_exception_handler.py", line 53, in wrapped_app
    raise exc
  File "/Library/Frameworks/Python.framework/Versions/3.12/lib/python3.12/site-packages/starlette/_exception_handler.py", line 42, in wrapped_app
    await app(scope, receive, sender)
  File "/Library/Frameworks/Python.framework/Versions/3.12/lib/python3.12/site-packages/starlette/routing.py", line 73, in app
    response = await f(request)
               ^^^^^^^^^^^^^^^^
  File "/Library/Frameworks/Python.framework/Versions/3.12/lib/python3.12/site-packages/fastapi/routing.py", line 301, in app
    raw_response = await run_endpoint_function(
                   ^^^^^^^^^^^^^^^^^^^^^^^^^^^^
  File "/Library/Frameworks/Python.framework/Versions/3.12/lib/python3.12/site-packages/fastapi/routing.py", line 214, in run_endpoint_function
    return await run_in_threadpool(dependant.call, **values)
           ^^^^^^^^^^^^^^^^^^^^^^^^^^^^^^^^^^^^^^^^^^^^^^^^^
  File "/Library/Frameworks/Python.framework/Versions/3.12/lib/python3.12/site-packages/starlette/concurrency.py", line 37, in run_in_threadpool
    return await anyio.to_thread.run_sync(func)
           ^^^^^^^^^^^^^^^^^^^^^^^^^^^^^^^^^^^^
  File "/Library/Frameworks/Python.framework/Versions/3.12/lib/python3.12/site-packages/anyio/to_thread.py", line 56, in run_sync
    return await get_async_backend().run_sync_in_worker_thread(
           ^^^^^^^^^^^^^^^^^^^^^^^^^^^^^^^^^^^^^^^^^^^^^^^^^^^^
  File "/Library/Frameworks/Python.framework/Versions/3.12/lib/python3.12/site-packages/anyio/_backends/_asyncio.py", line 2461, in run_sync_in_worker_thread
    return await future
           ^^^^^^^^^^^^
  File "/Library/Frameworks/Python.framework/Versions/3.12/lib/python3.12/asyncio/futures.py", line 291, in __await__
    yield self  # This tells Task to wait for completion.
    ^^^^^^^^^^
  File "/Library/Frameworks/Python.framework/Versions/3.12/lib/python3.12/asyncio/tasks.py", line 385, in __wakeup
    future.result()
  File "/Library/Frameworks/Python.framework/Versions/3.12/lib/python3.12/asyncio/futures.py", line 203, in result
    raise self._exception.with_traceback(self._exception_tb)
  File "/Library/Frameworks/Python.framework/Versions/3.12/lib/python3.12/site-packages/anyio/_backends/_asyncio.py", line 962, in run
    result = context.run(func, *args)
             ^^^^^^^^^^^^^^^^^^^^^^^^
  File "/Library/Frameworks/Python.framework/Versions/3.12/lib/python3.12/site-packages/aktools/core/api.py", line 141, in root
    received_df = eval("ak." + item_id + "()")
                  ^^^^^^^^^^^^^^^^^^^^^^^^^^^^
  File "<string>", line 1, in <module>
  File "/Library/Frameworks/Python.framework/Versions/3.12/lib/python3.12/site-packages/akshare/stock_a/stock_zh_a_spot.py", line 231, in stock_zh_a_spot_em
    return asyncio.run(stock_zh_a_spot_em_async())
           ^^^^^^^^^^^^^^^^^^^^^^^^^^^^^^^^^^^^^^^
  File "/Library/Frameworks/Python.framework/Versions/3.12/lib/python3.12/site-packages/nest_asyncio.py", line 30, in run
    return loop.run_until_complete(task)
           ^^^^^^^^^^^^^^^^^^^^^^^^^^^^^
  File "/Library/Frameworks/Python.framework/Versions/3.12/lib/python3.12/site-packages/nest_asyncio.py", line 98, in run_until_complete
    return f.result()
           ^^^^^^^^^^
  File "/Library/Frameworks/Python.framework/Versions/3.12/lib/python3.12/asyncio/futures.py", line 203, in result
    raise self._exception.with_traceback(self._exception_tb)
  File "/Library/Frameworks/Python.framework/Versions/3.12/lib/python3.12/asyncio/tasks.py", line 314, in __step_run_and_handle_result
    result = coro.send(None)
             ^^^^^^^^^^^^^^^
  File "/Library/Frameworks/Python.framework/Versions/3.12/lib/python3.12/site-packages/akshare/stock_a/stock_zh_a_spot.py", line 217, in stock_zh_a_spot_em_async
    results = await fetch_all_pages_async(url, params)
              ^^^^^^^^^^^^^^^^^^^^^^^^^^^^^^^^^^^^^^^^
  File "/Library/Frameworks/Python.framework/Versions/3.12/lib/python3.12/site-packages/akshare/stock_a/stock_zh_a_spot.py", line 53, in fetch_all_pages_async
    results = await asyncio.gather(*tasks)
              ^^^^^^^^^^^^^^^^^^^^^^^^^^^^
  File "/Library/Frameworks/Python.framework/Versions/3.12/lib/python3.12/asyncio/tasks.py", line 385, in __wakeup
    future.result()
  File "/Library/Frameworks/Python.framework/Versions/3.12/lib/python3.12/asyncio/tasks.py", line 316, in __step_run_and_handle_result
    result = coro.throw(exc)
             ^^^^^^^^^^^^^^^
  File "/Library/Frameworks/Python.framework/Versions/3.12/lib/python3.12/site-packages/akshare/stock_a/stock_zh_a_spot.py", line 21, in fetch_single_page
    async with session.get(url, params=params, ssl=False) as response:
               ^^^^^^^^^^^^^^^^^^^^^^^^^^^^^^^^^^^^^^^^^^
  File "/Library/Frameworks/Python.framework/Versions/3.12/lib/python3.12/site-packages/aiohttp/client.py", line 1425, in __aenter__
    self._resp: _RetType = await self._coro
                           ^^^^^^^^^^^^^^^^
  File "/Library/Frameworks/Python.framework/Versions/3.12/lib/python3.12/site-packages/aiohttp/client.py", line 707, in _request
    raise ConnectionTimeoutError(
aiohttp.client_exceptions.ConnectionTimeoutError: Connection timeout to host https://82.push2.eastmoney.com/api/qt/clist/get
100%|██████████| 2/2 [00:05<00:00,  2.49s/it]                                             INFO:     127.0.0.1:57351 - "GET /api/public/stock_zh_index_spot_em HTTP/1.1" 200 OK
INFO:     127.0.0.1:57361 - "GET /api/public/stock_zh_a_spot_em HTTP/1.1" 200 OK
ERROR:    Exception in ASGI application
Traceback (most recent call last):
  File "/Library/Frameworks/Python.framework/Versions/3.12/lib/python3.12/site-packages/aiohttp/connector.py", line 1122, in _wrap_create_connection
    return await self._loop.create_connection(*args, **kwargs, sock=sock)
           ^^^^^^^^^^^^^^^^^^^^^^^^^^^^^^^^^^^^^^^^^^^^^^^^^^^^^^^^^^^^^^
  File "/Library/Frameworks/Python.framework/Versions/3.12/lib/python3.12/asyncio/base_events.py", line 1148, in create_connection
    transport, protocol = await self._create_connection_transport(
                          ^^^^^^^^^^^^^^^^^^^^^^^^^^^^^^^^^^^^^^^^
  File "/Library/Frameworks/Python.framework/Versions/3.12/lib/python3.12/asyncio/base_events.py", line 1181, in _create_connection_transport
    await waiter
  File "/Library/Frameworks/Python.framework/Versions/3.12/lib/python3.12/asyncio/futures.py", line 291, in __await__
    yield self  # This tells Task to wait for completion.
    ^^^^^^^^^^
  File "/Library/Frameworks/Python.framework/Versions/3.12/lib/python3.12/asyncio/tasks.py", line 385, in __wakeup
    future.result()
  File "/Library/Frameworks/Python.framework/Versions/3.12/lib/python3.12/asyncio/futures.py", line 198, in result
    raise exc
asyncio.exceptions.CancelledError

The above exception was the direct cause of the following exception:

Traceback (most recent call last):
  File "/Library/Frameworks/Python.framework/Versions/3.12/lib/python3.12/site-packages/aiohttp/client.py", line 703, in _request
    conn = await self._connector.connect(
           ^^^^^^^^^^^^^^^^^^^^^^^^^^^^^^
  File "/Library/Frameworks/Python.framework/Versions/3.12/lib/python3.12/site-packages/aiohttp/connector.py", line 548, in connect
    proto = await self._create_connection(req, traces, timeout)
            ^^^^^^^^^^^^^^^^^^^^^^^^^^^^^^^^^^^^^^^^^^^^^^^^^^^
  File "/Library/Frameworks/Python.framework/Versions/3.12/lib/python3.12/site-packages/aiohttp/connector.py", line 1056, in _create_connection
    _, proto = await self._create_direct_connection(req, traces, timeout)
               ^^^^^^^^^^^^^^^^^^^^^^^^^^^^^^^^^^^^^^^^^^^^^^^^^^^^^^^^^^
  File "/Library/Frameworks/Python.framework/Versions/3.12/lib/python3.12/site-packages/aiohttp/connector.py", line 1400, in _create_direct_connection
    raise last_exc
  File "/Library/Frameworks/Python.framework/Versions/3.12/lib/python3.12/site-packages/aiohttp/connector.py", line 1369, in _create_direct_connection
    transp, proto = await self._wrap_create_connection(
                    ^^^^^^^^^^^^^^^^^^^^^^^^^^^^^^^^^^^
  File "/Library/Frameworks/Python.framework/Versions/3.12/lib/python3.12/site-packages/aiohttp/connector.py", line 1112, in _wrap_create_connection
    async with ceil_timeout(
               ^^^^^^^^^^^^^
  File "/Library/Frameworks/Python.framework/Versions/3.12/lib/python3.12/asyncio/timeouts.py", line 115, in __aexit__
    raise TimeoutError from exc_val
TimeoutError

The above exception was the direct cause of the following exception:

Traceback (most recent call last):
  File "/Library/Frameworks/Python.framework/Versions/3.12/lib/python3.12/site-packages/uvicorn/protocols/http/httptools_impl.py", line 401, in run_asgi
    result = await app(  # type: ignore[func-returns-value]
             ^^^^^^^^^^^^^^^^^^^^^^^^^^^^^^^^^^^^^^^^^^^^^^
  File "/Library/Frameworks/Python.framework/Versions/3.12/lib/python3.12/site-packages/uvicorn/middleware/proxy_headers.py", line 70, in __call__
    return await self.app(scope, receive, send)
           ^^^^^^^^^^^^^^^^^^^^^^^^^^^^^^^^^^^^
  File "/Library/Frameworks/Python.framework/Versions/3.12/lib/python3.12/site-packages/fastapi/applications.py", line 1054, in __call__
    await super().__call__(scope, receive, send)
  File "/Library/Frameworks/Python.framework/Versions/3.12/lib/python3.12/site-packages/starlette/applications.py", line 112, in __call__
    await self.middleware_stack(scope, receive, send)
  File "/Library/Frameworks/Python.framework/Versions/3.12/lib/python3.12/site-packages/starlette/middleware/errors.py", line 187, in __call__
    raise exc
  File "/Library/Frameworks/Python.framework/Versions/3.12/lib/python3.12/site-packages/starlette/middleware/errors.py", line 165, in __call__
    await self.app(scope, receive, _send)
  File "/Library/Frameworks/Python.framework/Versions/3.12/lib/python3.12/site-packages/starlette/middleware/cors.py", line 85, in __call__
    await self.app(scope, receive, send)
  File "/Library/Frameworks/Python.framework/Versions/3.12/lib/python3.12/site-packages/starlette/middleware/exceptions.py", line 62, in __call__
    await wrap_app_handling_exceptions(self.app, conn)(scope, receive, send)
  File "/Library/Frameworks/Python.framework/Versions/3.12/lib/python3.12/site-packages/starlette/_exception_handler.py", line 53, in wrapped_app
    raise exc
  File "/Library/Frameworks/Python.framework/Versions/3.12/lib/python3.12/site-packages/starlette/_exception_handler.py", line 42, in wrapped_app
    await app(scope, receive, sender)
  File "/Library/Frameworks/Python.framework/Versions/3.12/lib/python3.12/site-packages/starlette/routing.py", line 715, in __call__
    await self.middleware_stack(scope, receive, send)
  File "/Library/Frameworks/Python.framework/Versions/3.12/lib/python3.12/site-packages/starlette/routing.py", line 735, in app
    await route.handle(scope, receive, send)
  File "/Library/Frameworks/Python.framework/Versions/3.12/lib/python3.12/site-packages/starlette/routing.py", line 288, in handle
    await self.app(scope, receive, send)
  File "/Library/Frameworks/Python.framework/Versions/3.12/lib/python3.12/site-packages/starlette/routing.py", line 76, in app
    await wrap_app_handling_exceptions(app, request)(scope, receive, send)
  File "/Library/Frameworks/Python.framework/Versions/3.12/lib/python3.12/site-packages/starlette/_exception_handler.py", line 53, in wrapped_app
    raise exc
  File "/Library/Frameworks/Python.framework/Versions/3.12/lib/python3.12/site-packages/starlette/_exception_handler.py", line 42, in wrapped_app
    await app(scope, receive, sender)
  File "/Library/Frameworks/Python.framework/Versions/3.12/lib/python3.12/site-packages/starlette/routing.py", line 73, in app
    response = await f(request)
               ^^^^^^^^^^^^^^^^
  File "/Library/Frameworks/Python.framework/Versions/3.12/lib/python3.12/site-packages/fastapi/routing.py", line 301, in app
    raw_response = await run_endpoint_function(
                   ^^^^^^^^^^^^^^^^^^^^^^^^^^^^
  File "/Library/Frameworks/Python.framework/Versions/3.12/lib/python3.12/site-packages/fastapi/routing.py", line 214, in run_endpoint_function
    return await run_in_threadpool(dependant.call, **values)
           ^^^^^^^^^^^^^^^^^^^^^^^^^^^^^^^^^^^^^^^^^^^^^^^^^
  File "/Library/Frameworks/Python.framework/Versions/3.12/lib/python3.12/site-packages/starlette/concurrency.py", line 37, in run_in_threadpool
    return await anyio.to_thread.run_sync(func)
           ^^^^^^^^^^^^^^^^^^^^^^^^^^^^^^^^^^^^
  File "/Library/Frameworks/Python.framework/Versions/3.12/lib/python3.12/site-packages/anyio/to_thread.py", line 56, in run_sync
    return await get_async_backend().run_sync_in_worker_thread(
           ^^^^^^^^^^^^^^^^^^^^^^^^^^^^^^^^^^^^^^^^^^^^^^^^^^^^
  File "/Library/Frameworks/Python.framework/Versions/3.12/lib/python3.12/site-packages/anyio/_backends/_asyncio.py", line 2461, in run_sync_in_worker_thread
    return await future
           ^^^^^^^^^^^^
  File "/Library/Frameworks/Python.framework/Versions/3.12/lib/python3.12/asyncio/futures.py", line 291, in __await__
    yield self  # This tells Task to wait for completion.
    ^^^^^^^^^^
  File "/Library/Frameworks/Python.framework/Versions/3.12/lib/python3.12/asyncio/tasks.py", line 385, in __wakeup
    future.result()
  File "/Library/Frameworks/Python.framework/Versions/3.12/lib/python3.12/asyncio/futures.py", line 203, in result
    raise self._exception.with_traceback(self._exception_tb)
  File "/Library/Frameworks/Python.framework/Versions/3.12/lib/python3.12/site-packages/anyio/_backends/_asyncio.py", line 962, in run
    result = context.run(func, *args)
             ^^^^^^^^^^^^^^^^^^^^^^^^
  File "/Library/Frameworks/Python.framework/Versions/3.12/lib/python3.12/site-packages/aktools/core/api.py", line 141, in root
    received_df = eval("ak." + item_id + "()")
                  ^^^^^^^^^^^^^^^^^^^^^^^^^^^^
  File "<string>", line 1, in <module>
  File "/Library/Frameworks/Python.framework/Versions/3.12/lib/python3.12/site-packages/akshare/stock_a/stock_zh_a_spot.py", line 231, in stock_zh_a_spot_em
    return asyncio.run(stock_zh_a_spot_em_async())
           ^^^^^^^^^^^^^^^^^^^^^^^^^^^^^^^^^^^^^^^
  File "/Library/Frameworks/Python.framework/Versions/3.12/lib/python3.12/site-packages/nest_asyncio.py", line 30, in run
    return loop.run_until_complete(task)
           ^^^^^^^^^^^^^^^^^^^^^^^^^^^^^
  File "/Library/Frameworks/Python.framework/Versions/3.12/lib/python3.12/site-packages/nest_asyncio.py", line 98, in run_until_complete
    return f.result()
           ^^^^^^^^^^
  File "/Library/Frameworks/Python.framework/Versions/3.12/lib/python3.12/asyncio/futures.py", line 203, in result
    raise self._exception.with_traceback(self._exception_tb)
  File "/Library/Frameworks/Python.framework/Versions/3.12/lib/python3.12/asyncio/tasks.py", line 314, in __step_run_and_handle_result
    result = coro.send(None)
             ^^^^^^^^^^^^^^^
  File "/Library/Frameworks/Python.framework/Versions/3.12/lib/python3.12/site-packages/akshare/stock_a/stock_zh_a_spot.py", line 217, in stock_zh_a_spot_em_async
    results = await fetch_all_pages_async(url, params)
              ^^^^^^^^^^^^^^^^^^^^^^^^^^^^^^^^^^^^^^^^
  File "/Library/Frameworks/Python.framework/Versions/3.12/lib/python3.12/site-packages/akshare/stock_a/stock_zh_a_spot.py", line 53, in fetch_all_pages_async
    results = await asyncio.gather(*tasks)
              ^^^^^^^^^^^^^^^^^^^^^^^^^^^^
  File "/Library/Frameworks/Python.framework/Versions/3.12/lib/python3.12/asyncio/tasks.py", line 385, in __wakeup
    future.result()
  File "/Library/Frameworks/Python.framework/Versions/3.12/lib/python3.12/asyncio/tasks.py", line 316, in __step_run_and_handle_result
    result = coro.throw(exc)
             ^^^^^^^^^^^^^^^
  File "/Library/Frameworks/Python.framework/Versions/3.12/lib/python3.12/site-packages/akshare/stock_a/stock_zh_a_spot.py", line 21, in fetch_single_page
    async with session.get(url, params=params, ssl=False) as response:
               ^^^^^^^^^^^^^^^^^^^^^^^^^^^^^^^^^^^^^^^^^^
  File "/Library/Frameworks/Python.framework/Versions/3.12/lib/python3.12/site-packages/aiohttp/client.py", line 1425, in __aenter__
    self._resp: _RetType = await self._coro
                           ^^^^^^^^^^^^^^^^
  File "/Library/Frameworks/Python.framework/Versions/3.12/lib/python3.12/site-packages/aiohttp/client.py", line 707, in _request
    raise ConnectionTimeoutError(
aiohttp.client_exceptions.ConnectionTimeoutError: Connection timeout to host https://82.push2.eastmoney.com/api/qt/clist/get
  0%|          | 0/2 [00:00<?, ?it/s] 50%|█████     | 1/2 [00:04<00:04,  4.18s/it]100%|██████████| 2/2 [00:07<00:00,  3.77s/it]                                             INFO:     127.0.0.1:57505 - "GET /api/public/stock_zh_index_spot_em HTTP/1.1" 200 OK
  0%|          | 0/2 [00:00<?, ?it/s] 50%|█████     | 1/2 [00:05<00:05,  5.64s/it]100%|██████████| 2/2 [00:06<00:00,  3.00s/it]                                             INFO:     127.0.0.1:57624 - "GET /api/public/stock_zh_index_spot_em HTTP/1.1" 200 OK
ERROR:    Exception in ASGI application
Traceback (most recent call last):
  File "/Library/Frameworks/Python.framework/Versions/3.12/lib/python3.12/site-packages/aiohttp/connector.py", line 1115, in _wrap_create_connection
    sock = await aiohappyeyeballs.start_connection(
           ^^^^^^^^^^^^^^^^^^^^^^^^^^^^^^^^^^^^^^^^
  File "/Library/Frameworks/Python.framework/Versions/3.12/lib/python3.12/site-packages/aiohappyeyeballs/impl.py", line 71, in start_connection
    sock = await _connect_sock(
           ^^^^^^^^^^^^^^^^^^^^
  File "/Library/Frameworks/Python.framework/Versions/3.12/lib/python3.12/site-packages/aiohappyeyeballs/impl.py", line 163, in _connect_sock
    await loop.sock_connect(sock, address)
  File "/Library/Frameworks/Python.framework/Versions/3.12/lib/python3.12/asyncio/selector_events.py", line 651, in sock_connect
    return await fut
           ^^^^^^^^^
  File "/Library/Frameworks/Python.framework/Versions/3.12/lib/python3.12/asyncio/futures.py", line 291, in __await__
    yield self  # This tells Task to wait for completion.
    ^^^^^^^^^^
  File "/Library/Frameworks/Python.framework/Versions/3.12/lib/python3.12/asyncio/tasks.py", line 385, in __wakeup
    future.result()
  File "/Library/Frameworks/Python.framework/Versions/3.12/lib/python3.12/asyncio/futures.py", line 198, in result
    raise exc
asyncio.exceptions.CancelledError

The above exception was the direct cause of the following exception:

Traceback (most recent call last):
  File "/Library/Frameworks/Python.framework/Versions/3.12/lib/python3.12/site-packages/aiohttp/client.py", line 703, in _request
    conn = await self._connector.connect(
           ^^^^^^^^^^^^^^^^^^^^^^^^^^^^^^
  File "/Library/Frameworks/Python.framework/Versions/3.12/lib/python3.12/site-packages/aiohttp/connector.py", line 548, in connect
    proto = await self._create_connection(req, traces, timeout)
            ^^^^^^^^^^^^^^^^^^^^^^^^^^^^^^^^^^^^^^^^^^^^^^^^^^^
  File "/Library/Frameworks/Python.framework/Versions/3.12/lib/python3.12/site-packages/aiohttp/connector.py", line 1056, in _create_connection
    _, proto = await self._create_direct_connection(req, traces, timeout)
               ^^^^^^^^^^^^^^^^^^^^^^^^^^^^^^^^^^^^^^^^^^^^^^^^^^^^^^^^^^
  File "/Library/Frameworks/Python.framework/Versions/3.12/lib/python3.12/site-packages/aiohttp/connector.py", line 1400, in _create_direct_connection
    raise last_exc
  File "/Library/Frameworks/Python.framework/Versions/3.12/lib/python3.12/site-packages/aiohttp/connector.py", line 1369, in _create_direct_connection
    transp, proto = await self._wrap_create_connection(
                    ^^^^^^^^^^^^^^^^^^^^^^^^^^^^^^^^^^^
  File "/Library/Frameworks/Python.framework/Versions/3.12/lib/python3.12/site-packages/aiohttp/connector.py", line 1112, in _wrap_create_connection
    async with ceil_timeout(
               ^^^^^^^^^^^^^
  File "/Library/Frameworks/Python.framework/Versions/3.12/lib/python3.12/asyncio/timeouts.py", line 115, in __aexit__
    raise TimeoutError from exc_val
TimeoutError

The above exception was the direct cause of the following exception:

Traceback (most recent call last):
  File "/Library/Frameworks/Python.framework/Versions/3.12/lib/python3.12/site-packages/uvicorn/protocols/http/httptools_impl.py", line 401, in run_asgi
    result = await app(  # type: ignore[func-returns-value]
             ^^^^^^^^^^^^^^^^^^^^^^^^^^^^^^^^^^^^^^^^^^^^^^
  File "/Library/Frameworks/Python.framework/Versions/3.12/lib/python3.12/site-packages/uvicorn/middleware/proxy_headers.py", line 70, in __call__
    return await self.app(scope, receive, send)
           ^^^^^^^^^^^^^^^^^^^^^^^^^^^^^^^^^^^^
  File "/Library/Frameworks/Python.framework/Versions/3.12/lib/python3.12/site-packages/fastapi/applications.py", line 1054, in __call__
    await super().__call__(scope, receive, send)
  File "/Library/Frameworks/Python.framework/Versions/3.12/lib/python3.12/site-packages/starlette/applications.py", line 112, in __call__
    await self.middleware_stack(scope, receive, send)
  File "/Library/Frameworks/Python.framework/Versions/3.12/lib/python3.12/site-packages/starlette/middleware/errors.py", line 187, in __call__
    raise exc
  File "/Library/Frameworks/Python.framework/Versions/3.12/lib/python3.12/site-packages/starlette/middleware/errors.py", line 165, in __call__
    await self.app(scope, receive, _send)
  File "/Library/Frameworks/Python.framework/Versions/3.12/lib/python3.12/site-packages/starlette/middleware/cors.py", line 85, in __call__
    await self.app(scope, receive, send)
  File "/Library/Frameworks/Python.framework/Versions/3.12/lib/python3.12/site-packages/starlette/middleware/exceptions.py", line 62, in __call__
    await wrap_app_handling_exceptions(self.app, conn)(scope, receive, send)
  File "/Library/Frameworks/Python.framework/Versions/3.12/lib/python3.12/site-packages/starlette/_exception_handler.py", line 53, in wrapped_app
    raise exc
  File "/Library/Frameworks/Python.framework/Versions/3.12/lib/python3.12/site-packages/starlette/_exception_handler.py", line 42, in wrapped_app
    await app(scope, receive, sender)
  File "/Library/Frameworks/Python.framework/Versions/3.12/lib/python3.12/site-packages/starlette/routing.py", line 715, in __call__
    await self.middleware_stack(scope, receive, send)
  File "/Library/Frameworks/Python.framework/Versions/3.12/lib/python3.12/site-packages/starlette/routing.py", line 735, in app
    await route.handle(scope, receive, send)
  File "/Library/Frameworks/Python.framework/Versions/3.12/lib/python3.12/site-packages/starlette/routing.py", line 288, in handle
    await self.app(scope, receive, send)
  File "/Library/Frameworks/Python.framework/Versions/3.12/lib/python3.12/site-packages/starlette/routing.py", line 76, in app
    await wrap_app_handling_exceptions(app, request)(scope, receive, send)
  File "/Library/Frameworks/Python.framework/Versions/3.12/lib/python3.12/site-packages/starlette/_exception_handler.py", line 53, in wrapped_app
    raise exc
  File "/Library/Frameworks/Python.framework/Versions/3.12/lib/python3.12/site-packages/starlette/_exception_handler.py", line 42, in wrapped_app
    await app(scope, receive, sender)
  File "/Library/Frameworks/Python.framework/Versions/3.12/lib/python3.12/site-packages/starlette/routing.py", line 73, in app
    response = await f(request)
               ^^^^^^^^^^^^^^^^
  File "/Library/Frameworks/Python.framework/Versions/3.12/lib/python3.12/site-packages/fastapi/routing.py", line 301, in app
    raw_response = await run_endpoint_function(
                   ^^^^^^^^^^^^^^^^^^^^^^^^^^^^
  File "/Library/Frameworks/Python.framework/Versions/3.12/lib/python3.12/site-packages/fastapi/routing.py", line 214, in run_endpoint_function
    return await run_in_threadpool(dependant.call, **values)
           ^^^^^^^^^^^^^^^^^^^^^^^^^^^^^^^^^^^^^^^^^^^^^^^^^
  File "/Library/Frameworks/Python.framework/Versions/3.12/lib/python3.12/site-packages/starlette/concurrency.py", line 37, in run_in_threadpool
    return await anyio.to_thread.run_sync(func)
           ^^^^^^^^^^^^^^^^^^^^^^^^^^^^^^^^^^^^
  File "/Library/Frameworks/Python.framework/Versions/3.12/lib/python3.12/site-packages/anyio/to_thread.py", line 56, in run_sync
    return await get_async_backend().run_sync_in_worker_thread(
           ^^^^^^^^^^^^^^^^^^^^^^^^^^^^^^^^^^^^^^^^^^^^^^^^^^^^
  File "/Library/Frameworks/Python.framework/Versions/3.12/lib/python3.12/site-packages/anyio/_backends/_asyncio.py", line 2461, in run_sync_in_worker_thread
    return await future
           ^^^^^^^^^^^^
  File "/Library/Frameworks/Python.framework/Versions/3.12/lib/python3.12/asyncio/futures.py", line 291, in __await__
    yield self  # This tells Task to wait for completion.
    ^^^^^^^^^^
  File "/Library/Frameworks/Python.framework/Versions/3.12/lib/python3.12/asyncio/tasks.py", line 385, in __wakeup
    future.result()
  File "/Library/Frameworks/Python.framework/Versions/3.12/lib/python3.12/asyncio/futures.py", line 203, in result
    raise self._exception.with_traceback(self._exception_tb)
  File "/Library/Frameworks/Python.framework/Versions/3.12/lib/python3.12/site-packages/anyio/_backends/_asyncio.py", line 962, in run
    result = context.run(func, *args)
             ^^^^^^^^^^^^^^^^^^^^^^^^
  File "/Library/Frameworks/Python.framework/Versions/3.12/lib/python3.12/site-packages/aktools/core/api.py", line 141, in root
    received_df = eval("ak." + item_id + "()")
                  ^^^^^^^^^^^^^^^^^^^^^^^^^^^^
  File "<string>", line 1, in <module>
  File "/Library/Frameworks/Python.framework/Versions/3.12/lib/python3.12/site-packages/akshare/stock_a/stock_zh_a_spot.py", line 231, in stock_zh_a_spot_em
    return asyncio.run(stock_zh_a_spot_em_async())
           ^^^^^^^^^^^^^^^^^^^^^^^^^^^^^^^^^^^^^^^
  File "/Library/Frameworks/Python.framework/Versions/3.12/lib/python3.12/site-packages/nest_asyncio.py", line 30, in run
    return loop.run_until_complete(task)
           ^^^^^^^^^^^^^^^^^^^^^^^^^^^^^
  File "/Library/Frameworks/Python.framework/Versions/3.12/lib/python3.12/site-packages/nest_asyncio.py", line 98, in run_until_complete
    return f.result()
           ^^^^^^^^^^
  File "/Library/Frameworks/Python.framework/Versions/3.12/lib/python3.12/asyncio/futures.py", line 203, in result
    raise self._exception.with_traceback(self._exception_tb)
  File "/Library/Frameworks/Python.framework/Versions/3.12/lib/python3.12/asyncio/tasks.py", line 314, in __step_run_and_handle_result
    result = coro.send(None)
             ^^^^^^^^^^^^^^^
  File "/Library/Frameworks/Python.framework/Versions/3.12/lib/python3.12/site-packages/akshare/stock_a/stock_zh_a_spot.py", line 217, in stock_zh_a_spot_em_async
    results = await fetch_all_pages_async(url, params)
              ^^^^^^^^^^^^^^^^^^^^^^^^^^^^^^^^^^^^^^^^
  File "/Library/Frameworks/Python.framework/Versions/3.12/lib/python3.12/site-packages/akshare/stock_a/stock_zh_a_spot.py", line 53, in fetch_all_pages_async
    results = await asyncio.gather(*tasks)
              ^^^^^^^^^^^^^^^^^^^^^^^^^^^^
  File "/Library/Frameworks/Python.framework/Versions/3.12/lib/python3.12/asyncio/tasks.py", line 385, in __wakeup
    future.result()
  File "/Library/Frameworks/Python.framework/Versions/3.12/lib/python3.12/asyncio/tasks.py", line 316, in __step_run_and_handle_result
    result = coro.throw(exc)
             ^^^^^^^^^^^^^^^
  File "/Library/Frameworks/Python.framework/Versions/3.12/lib/python3.12/site-packages/akshare/stock_a/stock_zh_a_spot.py", line 21, in fetch_single_page
    async with session.get(url, params=params, ssl=False) as response:
               ^^^^^^^^^^^^^^^^^^^^^^^^^^^^^^^^^^^^^^^^^^
  File "/Library/Frameworks/Python.framework/Versions/3.12/lib/python3.12/site-packages/aiohttp/client.py", line 1425, in __aenter__
    self._resp: _RetType = await self._coro
                           ^^^^^^^^^^^^^^^^
  File "/Library/Frameworks/Python.framework/Versions/3.12/lib/python3.12/site-packages/aiohttp/client.py", line 707, in _request
    raise ConnectionTimeoutError(
aiohttp.client_exceptions.ConnectionTimeoutError: Connection timeout to host https://82.push2.eastmoney.com/api/qt/clist/get
INFO:     127.0.0.1:57634 - "GET /api/public/stock_zh_a_spot_em HTTP/1.1" 200 OK
INFO:     127.0.0.1:57634 - "GET /api/public/stock_zh_a_spot_em HTTP/1.1" 200 OK
INFO:     127.0.0.1:57634 - "GET /api/public/stock_zh_a_spot_em HTTP/1.1" 200 OK
  0%|          | 0/2 [00:00<?, ?it/s] 50%|█████     | 1/2 [00:00<00:00,  1.28it/s]100%|██████████| 2/2 [00:02<00:00,  1.56s/it]                                             INFO:     127.0.0.1:57634 - "GET /api/public/stock_zh_index_spot_em HTTP/1.1" 200 OK
INFO:     127.0.0.1:57825 - "GET /api/public/stock_zh_a_spot_em HTTP/1.1" 200 OK
INFO:     127.0.0.1:57825 - "GET /api/public/stock_zh_a_spot_em HTTP/1.1" 200 OK
  0%|          | 0/2 [00:00<?, ?it/s] 50%|█████     | 1/2 [00:01<00:01,  1.64s/it]100%|██████████| 2/2 [00:02<00:00,  1.28s/it]                                             INFO:     127.0.0.1:58056 - "GET /api/public/stock_zh_index_spot_em HTTP/1.1" 200 OK
ERROR:    Exception in ASGI application
Traceback (most recent call last):
  File "/Library/Frameworks/Python.framework/Versions/3.12/lib/python3.12/site-packages/aiohttp/connector.py", line 1122, in _wrap_create_connection
    return await self._loop.create_connection(*args, **kwargs, sock=sock)
           ^^^^^^^^^^^^^^^^^^^^^^^^^^^^^^^^^^^^^^^^^^^^^^^^^^^^^^^^^^^^^^
  File "/Library/Frameworks/Python.framework/Versions/3.12/lib/python3.12/asyncio/base_events.py", line 1148, in create_connection
    transport, protocol = await self._create_connection_transport(
                          ^^^^^^^^^^^^^^^^^^^^^^^^^^^^^^^^^^^^^^^^
  File "/Library/Frameworks/Python.framework/Versions/3.12/lib/python3.12/asyncio/base_events.py", line 1181, in _create_connection_transport
    await waiter
  File "/Library/Frameworks/Python.framework/Versions/3.12/lib/python3.12/asyncio/futures.py", line 291, in __await__
    yield self  # This tells Task to wait for completion.
    ^^^^^^^^^^
  File "/Library/Frameworks/Python.framework/Versions/3.12/lib/python3.12/asyncio/tasks.py", line 385, in __wakeup
    future.result()
  File "/Library/Frameworks/Python.framework/Versions/3.12/lib/python3.12/asyncio/futures.py", line 198, in result
    raise exc
asyncio.exceptions.CancelledError

The above exception was the direct cause of the following exception:

Traceback (most recent call last):
  File "/Library/Frameworks/Python.framework/Versions/3.12/lib/python3.12/site-packages/aiohttp/client.py", line 703, in _request
    conn = await self._connector.connect(
           ^^^^^^^^^^^^^^^^^^^^^^^^^^^^^^
  File "/Library/Frameworks/Python.framework/Versions/3.12/lib/python3.12/site-packages/aiohttp/connector.py", line 548, in connect
    proto = await self._create_connection(req, traces, timeout)
            ^^^^^^^^^^^^^^^^^^^^^^^^^^^^^^^^^^^^^^^^^^^^^^^^^^^
  File "/Library/Frameworks/Python.framework/Versions/3.12/lib/python3.12/site-packages/aiohttp/connector.py", line 1056, in _create_connection
    _, proto = await self._create_direct_connection(req, traces, timeout)
               ^^^^^^^^^^^^^^^^^^^^^^^^^^^^^^^^^^^^^^^^^^^^^^^^^^^^^^^^^^
  File "/Library/Frameworks/Python.framework/Versions/3.12/lib/python3.12/site-packages/aiohttp/connector.py", line 1400, in _create_direct_connection
    raise last_exc
  File "/Library/Frameworks/Python.framework/Versions/3.12/lib/python3.12/site-packages/aiohttp/connector.py", line 1369, in _create_direct_connection
    transp, proto = await self._wrap_create_connection(
                    ^^^^^^^^^^^^^^^^^^^^^^^^^^^^^^^^^^^
  File "/Library/Frameworks/Python.framework/Versions/3.12/lib/python3.12/site-packages/aiohttp/connector.py", line 1112, in _wrap_create_connection
    async with ceil_timeout(
               ^^^^^^^^^^^^^
  File "/Library/Frameworks/Python.framework/Versions/3.12/lib/python3.12/asyncio/timeouts.py", line 115, in __aexit__
    raise TimeoutError from exc_val
TimeoutError

The above exception was the direct cause of the following exception:

Traceback (most recent call last):
  File "/Library/Frameworks/Python.framework/Versions/3.12/lib/python3.12/site-packages/uvicorn/protocols/http/httptools_impl.py", line 401, in run_asgi
    result = await app(  # type: ignore[func-returns-value]
             ^^^^^^^^^^^^^^^^^^^^^^^^^^^^^^^^^^^^^^^^^^^^^^
  File "/Library/Frameworks/Python.framework/Versions/3.12/lib/python3.12/site-packages/uvicorn/middleware/proxy_headers.py", line 70, in __call__
    return await self.app(scope, receive, send)
           ^^^^^^^^^^^^^^^^^^^^^^^^^^^^^^^^^^^^
  File "/Library/Frameworks/Python.framework/Versions/3.12/lib/python3.12/site-packages/fastapi/applications.py", line 1054, in __call__
    await super().__call__(scope, receive, send)
  File "/Library/Frameworks/Python.framework/Versions/3.12/lib/python3.12/site-packages/starlette/applications.py", line 112, in __call__
    await self.middleware_stack(scope, receive, send)
  File "/Library/Frameworks/Python.framework/Versions/3.12/lib/python3.12/site-packages/starlette/middleware/errors.py", line 187, in __call__
    raise exc
  File "/Library/Frameworks/Python.framework/Versions/3.12/lib/python3.12/site-packages/starlette/middleware/errors.py", line 165, in __call__
    await self.app(scope, receive, _send)
  File "/Library/Frameworks/Python.framework/Versions/3.12/lib/python3.12/site-packages/starlette/middleware/cors.py", line 85, in __call__
    await self.app(scope, receive, send)
  File "/Library/Frameworks/Python.framework/Versions/3.12/lib/python3.12/site-packages/starlette/middleware/exceptions.py", line 62, in __call__
    await wrap_app_handling_exceptions(self.app, conn)(scope, receive, send)
  File "/Library/Frameworks/Python.framework/Versions/3.12/lib/python3.12/site-packages/starlette/_exception_handler.py", line 53, in wrapped_app
    raise exc
  File "/Library/Frameworks/Python.framework/Versions/3.12/lib/python3.12/site-packages/starlette/_exception_handler.py", line 42, in wrapped_app
    await app(scope, receive, sender)
  File "/Library/Frameworks/Python.framework/Versions/3.12/lib/python3.12/site-packages/starlette/routing.py", line 715, in __call__
    await self.middleware_stack(scope, receive, send)
  File "/Library/Frameworks/Python.framework/Versions/3.12/lib/python3.12/site-packages/starlette/routing.py", line 735, in app
    await route.handle(scope, receive, send)
  File "/Library/Frameworks/Python.framework/Versions/3.12/lib/python3.12/site-packages/starlette/routing.py", line 288, in handle
    await self.app(scope, receive, send)
  File "/Library/Frameworks/Python.framework/Versions/3.12/lib/python3.12/site-packages/starlette/routing.py", line 76, in app
    await wrap_app_handling_exceptions(app, request)(scope, receive, send)
  File "/Library/Frameworks/Python.framework/Versions/3.12/lib/python3.12/site-packages/starlette/_exception_handler.py", line 53, in wrapped_app
    raise exc
  File "/Library/Frameworks/Python.framework/Versions/3.12/lib/python3.12/site-packages/starlette/_exception_handler.py", line 42, in wrapped_app
    await app(scope, receive, sender)
  File "/Library/Frameworks/Python.framework/Versions/3.12/lib/python3.12/site-packages/starlette/routing.py", line 73, in app
    response = await f(request)
               ^^^^^^^^^^^^^^^^
  File "/Library/Frameworks/Python.framework/Versions/3.12/lib/python3.12/site-packages/fastapi/routing.py", line 301, in app
    raw_response = await run_endpoint_function(
                   ^^^^^^^^^^^^^^^^^^^^^^^^^^^^
  File "/Library/Frameworks/Python.framework/Versions/3.12/lib/python3.12/site-packages/fastapi/routing.py", line 214, in run_endpoint_function
    return await run_in_threadpool(dependant.call, **values)
           ^^^^^^^^^^^^^^^^^^^^^^^^^^^^^^^^^^^^^^^^^^^^^^^^^
  File "/Library/Frameworks/Python.framework/Versions/3.12/lib/python3.12/site-packages/starlette/concurrency.py", line 37, in run_in_threadpool
    return await anyio.to_thread.run_sync(func)
           ^^^^^^^^^^^^^^^^^^^^^^^^^^^^^^^^^^^^
  File "/Library/Frameworks/Python.framework/Versions/3.12/lib/python3.12/site-packages/anyio/to_thread.py", line 56, in run_sync
    return await get_async_backend().run_sync_in_worker_thread(
           ^^^^^^^^^^^^^^^^^^^^^^^^^^^^^^^^^^^^^^^^^^^^^^^^^^^^
  File "/Library/Frameworks/Python.framework/Versions/3.12/lib/python3.12/site-packages/anyio/_backends/_asyncio.py", line 2461, in run_sync_in_worker_thread
    return await future
           ^^^^^^^^^^^^
  File "/Library/Frameworks/Python.framework/Versions/3.12/lib/python3.12/asyncio/futures.py", line 291, in __await__
    yield self  # This tells Task to wait for completion.
    ^^^^^^^^^^
  File "/Library/Frameworks/Python.framework/Versions/3.12/lib/python3.12/asyncio/tasks.py", line 385, in __wakeup
    future.result()
  File "/Library/Frameworks/Python.framework/Versions/3.12/lib/python3.12/asyncio/futures.py", line 203, in result
    raise self._exception.with_traceback(self._exception_tb)
  File "/Library/Frameworks/Python.framework/Versions/3.12/lib/python3.12/site-packages/anyio/_backends/_asyncio.py", line 962, in run
    result = context.run(func, *args)
             ^^^^^^^^^^^^^^^^^^^^^^^^
  File "/Library/Frameworks/Python.framework/Versions/3.12/lib/python3.12/site-packages/aktools/core/api.py", line 141, in root
    received_df = eval("ak." + item_id + "()")
                  ^^^^^^^^^^^^^^^^^^^^^^^^^^^^
  File "<string>", line 1, in <module>
  File "/Library/Frameworks/Python.framework/Versions/3.12/lib/python3.12/site-packages/akshare/stock_a/stock_zh_a_spot.py", line 231, in stock_zh_a_spot_em
    return asyncio.run(stock_zh_a_spot_em_async())
           ^^^^^^^^^^^^^^^^^^^^^^^^^^^^^^^^^^^^^^^
  File "/Library/Frameworks/Python.framework/Versions/3.12/lib/python3.12/site-packages/nest_asyncio.py", line 30, in run
    return loop.run_until_complete(task)
           ^^^^^^^^^^^^^^^^^^^^^^^^^^^^^
  File "/Library/Frameworks/Python.framework/Versions/3.12/lib/python3.12/site-packages/nest_asyncio.py", line 98, in run_until_complete
    return f.result()
           ^^^^^^^^^^
  File "/Library/Frameworks/Python.framework/Versions/3.12/lib/python3.12/asyncio/futures.py", line 203, in result
    raise self._exception.with_traceback(self._exception_tb)
  File "/Library/Frameworks/Python.framework/Versions/3.12/lib/python3.12/asyncio/tasks.py", line 314, in __step_run_and_handle_result
    result = coro.send(None)
             ^^^^^^^^^^^^^^^
  File "/Library/Frameworks/Python.framework/Versions/3.12/lib/python3.12/site-packages/akshare/stock_a/stock_zh_a_spot.py", line 217, in stock_zh_a_spot_em_async
    results = await fetch_all_pages_async(url, params)
              ^^^^^^^^^^^^^^^^^^^^^^^^^^^^^^^^^^^^^^^^
  File "/Library/Frameworks/Python.framework/Versions/3.12/lib/python3.12/site-packages/akshare/stock_a/stock_zh_a_spot.py", line 53, in fetch_all_pages_async
    results = await asyncio.gather(*tasks)
              ^^^^^^^^^^^^^^^^^^^^^^^^^^^^
  File "/Library/Frameworks/Python.framework/Versions/3.12/lib/python3.12/asyncio/tasks.py", line 385, in __wakeup
    future.result()
  File "/Library/Frameworks/Python.framework/Versions/3.12/lib/python3.12/asyncio/tasks.py", line 316, in __step_run_and_handle_result
    result = coro.throw(exc)
             ^^^^^^^^^^^^^^^
  File "/Library/Frameworks/Python.framework/Versions/3.12/lib/python3.12/site-packages/akshare/stock_a/stock_zh_a_spot.py", line 21, in fetch_single_page
    async with session.get(url, params=params, ssl=False) as response:
               ^^^^^^^^^^^^^^^^^^^^^^^^^^^^^^^^^^^^^^^^^^
  File "/Library/Frameworks/Python.framework/Versions/3.12/lib/python3.12/site-packages/aiohttp/client.py", line 1425, in __aenter__
    self._resp: _RetType = await self._coro
                           ^^^^^^^^^^^^^^^^
  File "/Library/Frameworks/Python.framework/Versions/3.12/lib/python3.12/site-packages/aiohttp/client.py", line 707, in _request
    raise ConnectionTimeoutError(
aiohttp.client_exceptions.ConnectionTimeoutError: Connection timeout to host https://82.push2.eastmoney.com/api/qt/clist/get
  0%|          | 0/2 [00:00<?, ?it/s] 50%|█████     | 1/2 [00:01<00:01,  1.62s/it]100%|██████████| 2/2 [00:02<00:00,  1.39s/it]                                             INFO:     127.0.0.1:58156 - "GET /api/public/stock_zh_index_spot_em HTTP/1.1" 200 OK
INFO:     127.0.0.1:58165 - "GET /api/public/stock_zh_a_spot_em HTTP/1.1" 200 OK
INFO:     127.0.0.1:58165 - "GET /api/public/stock_zh_a_spot_em HTTP/1.1" 200 OK
  0%|          | 0/2 [00:00<?, ?it/s] 50%|█████     | 1/2 [00:10<00:10, 10.96s/it]100%|██████████| 2/2 [00:12<00:00,  5.68s/it]                                             INFO:     127.0.0.1:58443 - "GET /api/public/stock_zh_index_spot_em HTTP/1.1" 200 OK
  0%|          | 0/2 [00:00<?, ?it/s] 50%|█████     | 1/2 [00:02<00:02,  2.28s/it]                                             ERROR:    Exception in ASGI application
Traceback (most recent call last):
  File "/Library/Frameworks/Python.framework/Versions/3.12/lib/python3.12/site-packages/urllib3/connectionpool.py", line 536, in _make_request
    response = conn.getresponse()
               ^^^^^^^^^^^^^^^^^^
  File "/Library/Frameworks/Python.framework/Versions/3.12/lib/python3.12/site-packages/urllib3/connection.py", line 507, in getresponse
    httplib_response = super().getresponse()
                       ^^^^^^^^^^^^^^^^^^^^^
  File "/Library/Frameworks/Python.framework/Versions/3.12/lib/python3.12/http/client.py", line 1428, in getresponse
    response.begin()
  File "/Library/Frameworks/Python.framework/Versions/3.12/lib/python3.12/http/client.py", line 331, in begin
    version, status, reason = self._read_status()
                              ^^^^^^^^^^^^^^^^^^^
  File "/Library/Frameworks/Python.framework/Versions/3.12/lib/python3.12/http/client.py", line 292, in _read_status
    line = str(self.fp.readline(_MAXLINE + 1), "iso-8859-1")
               ^^^^^^^^^^^^^^^^^^^^^^^^^^^^^^
  File "/Library/Frameworks/Python.framework/Versions/3.12/lib/python3.12/socket.py", line 720, in readinto
    return self._sock.recv_into(b)
           ^^^^^^^^^^^^^^^^^^^^^^^
  File "/Library/Frameworks/Python.framework/Versions/3.12/lib/python3.12/ssl.py", line 1251, in recv_into
    return self.read(nbytes, buffer)
           ^^^^^^^^^^^^^^^^^^^^^^^^^
  File "/Library/Frameworks/Python.framework/Versions/3.12/lib/python3.12/ssl.py", line 1103, in read
    return self._sslobj.read(len, buffer)
           ^^^^^^^^^^^^^^^^^^^^^^^^^^^^^^
TimeoutError: The read operation timed out

The above exception was the direct cause of the following exception:

Traceback (most recent call last):
  File "/Library/Frameworks/Python.framework/Versions/3.12/lib/python3.12/site-packages/requests/adapters.py", line 667, in send
    resp = conn.urlopen(
           ^^^^^^^^^^^^^
  File "/Library/Frameworks/Python.framework/Versions/3.12/lib/python3.12/site-packages/urllib3/connectionpool.py", line 843, in urlopen
    retries = retries.increment(
              ^^^^^^^^^^^^^^^^^^
  File "/Library/Frameworks/Python.framework/Versions/3.12/lib/python3.12/site-packages/urllib3/util/retry.py", line 474, in increment
    raise reraise(type(error), error, _stacktrace)
          ^^^^^^^^^^^^^^^^^^^^^^^^^^^^^^^^^^^^^^^^
  File "/Library/Frameworks/Python.framework/Versions/3.12/lib/python3.12/site-packages/urllib3/util/util.py", line 39, in reraise
    raise value
  File "/Library/Frameworks/Python.framework/Versions/3.12/lib/python3.12/site-packages/urllib3/connectionpool.py", line 789, in urlopen
    response = self._make_request(
               ^^^^^^^^^^^^^^^^^^^
  File "/Library/Frameworks/Python.framework/Versions/3.12/lib/python3.12/site-packages/urllib3/connectionpool.py", line 538, in _make_request
    self._raise_timeout(err=e, url=url, timeout_value=read_timeout)
  File "/Library/Frameworks/Python.framework/Versions/3.12/lib/python3.12/site-packages/urllib3/connectionpool.py", line 369, in _raise_timeout
    raise ReadTimeoutError(
urllib3.exceptions.ReadTimeoutError: HTTPSConnectionPool(host='48.push2.eastmoney.com', port=443): Read timed out. (read timeout=15)

During handling of the above exception, another exception occurred:

Traceback (most recent call last):
  File "/Library/Frameworks/Python.framework/Versions/3.12/lib/python3.12/site-packages/uvicorn/protocols/http/httptools_impl.py", line 401, in run_asgi
    result = await app(  # type: ignore[func-returns-value]
             ^^^^^^^^^^^^^^^^^^^^^^^^^^^^^^^^^^^^^^^^^^^^^^
  File "/Library/Frameworks/Python.framework/Versions/3.12/lib/python3.12/site-packages/uvicorn/middleware/proxy_headers.py", line 70, in __call__
    return await self.app(scope, receive, send)
           ^^^^^^^^^^^^^^^^^^^^^^^^^^^^^^^^^^^^
  File "/Library/Frameworks/Python.framework/Versions/3.12/lib/python3.12/site-packages/fastapi/applications.py", line 1054, in __call__
    await super().__call__(scope, receive, send)
  File "/Library/Frameworks/Python.framework/Versions/3.12/lib/python3.12/site-packages/starlette/applications.py", line 112, in __call__
    await self.middleware_stack(scope, receive, send)
  File "/Library/Frameworks/Python.framework/Versions/3.12/lib/python3.12/site-packages/starlette/middleware/errors.py", line 187, in __call__
    raise exc
  File "/Library/Frameworks/Python.framework/Versions/3.12/lib/python3.12/site-packages/starlette/middleware/errors.py", line 165, in __call__
    await self.app(scope, receive, _send)
  File "/Library/Frameworks/Python.framework/Versions/3.12/lib/python3.12/site-packages/starlette/middleware/cors.py", line 85, in __call__
    await self.app(scope, receive, send)
  File "/Library/Frameworks/Python.framework/Versions/3.12/lib/python3.12/site-packages/starlette/middleware/exceptions.py", line 62, in __call__
    await wrap_app_handling_exceptions(self.app, conn)(scope, receive, send)
  File "/Library/Frameworks/Python.framework/Versions/3.12/lib/python3.12/site-packages/starlette/_exception_handler.py", line 53, in wrapped_app
    raise exc
  File "/Library/Frameworks/Python.framework/Versions/3.12/lib/python3.12/site-packages/starlette/_exception_handler.py", line 42, in wrapped_app
    await app(scope, receive, sender)
  File "/Library/Frameworks/Python.framework/Versions/3.12/lib/python3.12/site-packages/starlette/routing.py", line 715, in __call__
    await self.middleware_stack(scope, receive, send)
  File "/Library/Frameworks/Python.framework/Versions/3.12/lib/python3.12/site-packages/starlette/routing.py", line 735, in app
    await route.handle(scope, receive, send)
  File "/Library/Frameworks/Python.framework/Versions/3.12/lib/python3.12/site-packages/starlette/routing.py", line 288, in handle
    await self.app(scope, receive, send)
  File "/Library/Frameworks/Python.framework/Versions/3.12/lib/python3.12/site-packages/starlette/routing.py", line 76, in app
    await wrap_app_handling_exceptions(app, request)(scope, receive, send)
  File "/Library/Frameworks/Python.framework/Versions/3.12/lib/python3.12/site-packages/starlette/_exception_handler.py", line 53, in wrapped_app
    raise exc
  File "/Library/Frameworks/Python.framework/Versions/3.12/lib/python3.12/site-packages/starlette/_exception_handler.py", line 42, in wrapped_app
    await app(scope, receive, sender)
  File "/Library/Frameworks/Python.framework/Versions/3.12/lib/python3.12/site-packages/starlette/routing.py", line 73, in app
    response = await f(request)
               ^^^^^^^^^^^^^^^^
  File "/Library/Frameworks/Python.framework/Versions/3.12/lib/python3.12/site-packages/fastapi/routing.py", line 301, in app
    raw_response = await run_endpoint_function(
                   ^^^^^^^^^^^^^^^^^^^^^^^^^^^^
  File "/Library/Frameworks/Python.framework/Versions/3.12/lib/python3.12/site-packages/fastapi/routing.py", line 214, in run_endpoint_function
    return await run_in_threadpool(dependant.call, **values)
           ^^^^^^^^^^^^^^^^^^^^^^^^^^^^^^^^^^^^^^^^^^^^^^^^^
  File "/Library/Frameworks/Python.framework/Versions/3.12/lib/python3.12/site-packages/starlette/concurrency.py", line 37, in run_in_threadpool
    return await anyio.to_thread.run_sync(func)
           ^^^^^^^^^^^^^^^^^^^^^^^^^^^^^^^^^^^^
  File "/Library/Frameworks/Python.framework/Versions/3.12/lib/python3.12/site-packages/anyio/to_thread.py", line 56, in run_sync
    return await get_async_backend().run_sync_in_worker_thread(
           ^^^^^^^^^^^^^^^^^^^^^^^^^^^^^^^^^^^^^^^^^^^^^^^^^^^^
  File "/Library/Frameworks/Python.framework/Versions/3.12/lib/python3.12/site-packages/anyio/_backends/_asyncio.py", line 2461, in run_sync_in_worker_thread
    return await future
           ^^^^^^^^^^^^
  File "/Library/Frameworks/Python.framework/Versions/3.12/lib/python3.12/asyncio/futures.py", line 291, in __await__
    yield self  # This tells Task to wait for completion.
    ^^^^^^^^^^
  File "/Library/Frameworks/Python.framework/Versions/3.12/lib/python3.12/asyncio/tasks.py", line 385, in __wakeup
    future.result()
  File "/Library/Frameworks/Python.framework/Versions/3.12/lib/python3.12/asyncio/futures.py", line 203, in result
    raise self._exception.with_traceback(self._exception_tb)
  File "/Library/Frameworks/Python.framework/Versions/3.12/lib/python3.12/site-packages/anyio/_backends/_asyncio.py", line 962, in run
    result = context.run(func, *args)
             ^^^^^^^^^^^^^^^^^^^^^^^^
  File "/Library/Frameworks/Python.framework/Versions/3.12/lib/python3.12/site-packages/aktools/core/api.py", line 141, in root
    received_df = eval("ak." + item_id + "()")
                  ^^^^^^^^^^^^^^^^^^^^^^^^^^^^
  File "<string>", line 1, in <module>
  File "/Library/Frameworks/Python.framework/Versions/3.12/lib/python3.12/site-packages/akshare/index/index_stock_zh.py", line 241, in stock_zh_index_spot_em
    temp_df = fetch_paginated_data(url, params)
              ^^^^^^^^^^^^^^^^^^^^^^^^^^^^^^^^^
  File "/Library/Frameworks/Python.framework/Versions/3.12/lib/python3.12/site-packages/akshare/utils/func.py", line 46, in fetch_paginated_data
    r = requests.get(url, params=params, timeout=timeout)
        ^^^^^^^^^^^^^^^^^^^^^^^^^^^^^^^^^^^^^^^^^^^^^^^^^
  File "/Library/Frameworks/Python.framework/Versions/3.12/lib/python3.12/site-packages/requests/api.py", line 73, in get
    return request("get", url, params=params, **kwargs)
           ^^^^^^^^^^^^^^^^^^^^^^^^^^^^^^^^^^^^^^^^^^^^
  File "/Library/Frameworks/Python.framework/Versions/3.12/lib/python3.12/site-packages/requests/api.py", line 59, in request
    return session.request(method=method, url=url, **kwargs)
           ^^^^^^^^^^^^^^^^^^^^^^^^^^^^^^^^^^^^^^^^^^^^^^^^^
  File "/Library/Frameworks/Python.framework/Versions/3.12/lib/python3.12/site-packages/requests/sessions.py", line 589, in request
    resp = self.send(prep, **send_kwargs)
           ^^^^^^^^^^^^^^^^^^^^^^^^^^^^^^
  File "/Library/Frameworks/Python.framework/Versions/3.12/lib/python3.12/site-packages/requests/sessions.py", line 703, in send
    r = adapter.send(request, **kwargs)
        ^^^^^^^^^^^^^^^^^^^^^^^^^^^^^^^
  File "/Library/Frameworks/Python.framework/Versions/3.12/lib/python3.12/site-packages/requests/adapters.py", line 713, in send
    raise ReadTimeout(e, request=request)
requests.exceptions.ReadTimeout: HTTPSConnectionPool(host='48.push2.eastmoney.com', port=443): Read timed out. (read timeout=15)
  0%|          | 0/2 [00:00<?, ?it/s] 50%|█████     | 1/2 [00:03<00:03,  3.32s/it]100%|██████████| 2/2 [00:05<00:00,  2.55s/it]                                             INFO:     127.0.0.1:58577 - "GET /api/public/stock_zh_index_spot_em HTTP/1.1" 200 OK
INFO:     127.0.0.1:58585 - "GET /api/public/stock_zh_a_spot_em HTTP/1.1" 200 OK
ERROR:    Exception in ASGI application
Traceback (most recent call last):
  File "/Library/Frameworks/Python.framework/Versions/3.12/lib/python3.12/site-packages/aiohttp/client_reqrep.py", line 1059, in start
    message, payload = await protocol.read()  # type: ignore[union-attr]
                       ^^^^^^^^^^^^^^^^^^^^^
  File "/Library/Frameworks/Python.framework/Versions/3.12/lib/python3.12/site-packages/aiohttp/streams.py", line 672, in read
    await self._waiter
  File "/Library/Frameworks/Python.framework/Versions/3.12/lib/python3.12/asyncio/futures.py", line 291, in __await__
    yield self  # This tells Task to wait for completion.
    ^^^^^^^^^^
  File "/Library/Frameworks/Python.framework/Versions/3.12/lib/python3.12/asyncio/tasks.py", line 385, in __wakeup
    future.result()
  File "/Library/Frameworks/Python.framework/Versions/3.12/lib/python3.12/asyncio/futures.py", line 198, in result
    raise exc
asyncio.exceptions.CancelledError

The above exception was the direct cause of the following exception:

Traceback (most recent call last):
  File "/Library/Frameworks/Python.framework/Versions/3.12/lib/python3.12/site-packages/uvicorn/protocols/http/httptools_impl.py", line 401, in run_asgi
    result = await app(  # type: ignore[func-returns-value]
             ^^^^^^^^^^^^^^^^^^^^^^^^^^^^^^^^^^^^^^^^^^^^^^
  File "/Library/Frameworks/Python.framework/Versions/3.12/lib/python3.12/site-packages/uvicorn/middleware/proxy_headers.py", line 70, in __call__
    return await self.app(scope, receive, send)
           ^^^^^^^^^^^^^^^^^^^^^^^^^^^^^^^^^^^^
  File "/Library/Frameworks/Python.framework/Versions/3.12/lib/python3.12/site-packages/fastapi/applications.py", line 1054, in __call__
    await super().__call__(scope, receive, send)
  File "/Library/Frameworks/Python.framework/Versions/3.12/lib/python3.12/site-packages/starlette/applications.py", line 112, in __call__
    await self.middleware_stack(scope, receive, send)
  File "/Library/Frameworks/Python.framework/Versions/3.12/lib/python3.12/site-packages/starlette/middleware/errors.py", line 187, in __call__
    raise exc
  File "/Library/Frameworks/Python.framework/Versions/3.12/lib/python3.12/site-packages/starlette/middleware/errors.py", line 165, in __call__
    await self.app(scope, receive, _send)
  File "/Library/Frameworks/Python.framework/Versions/3.12/lib/python3.12/site-packages/starlette/middleware/cors.py", line 85, in __call__
    await self.app(scope, receive, send)
  File "/Library/Frameworks/Python.framework/Versions/3.12/lib/python3.12/site-packages/starlette/middleware/exceptions.py", line 62, in __call__
    await wrap_app_handling_exceptions(self.app, conn)(scope, receive, send)
  File "/Library/Frameworks/Python.framework/Versions/3.12/lib/python3.12/site-packages/starlette/_exception_handler.py", line 53, in wrapped_app
    raise exc
  File "/Library/Frameworks/Python.framework/Versions/3.12/lib/python3.12/site-packages/starlette/_exception_handler.py", line 42, in wrapped_app
    await app(scope, receive, sender)
  File "/Library/Frameworks/Python.framework/Versions/3.12/lib/python3.12/site-packages/starlette/routing.py", line 715, in __call__
    await self.middleware_stack(scope, receive, send)
  File "/Library/Frameworks/Python.framework/Versions/3.12/lib/python3.12/site-packages/starlette/routing.py", line 735, in app
    await route.handle(scope, receive, send)
  File "/Library/Frameworks/Python.framework/Versions/3.12/lib/python3.12/site-packages/starlette/routing.py", line 288, in handle
    await self.app(scope, receive, send)
  File "/Library/Frameworks/Python.framework/Versions/3.12/lib/python3.12/site-packages/starlette/routing.py", line 76, in app
    await wrap_app_handling_exceptions(app, request)(scope, receive, send)
  File "/Library/Frameworks/Python.framework/Versions/3.12/lib/python3.12/site-packages/starlette/_exception_handler.py", line 53, in wrapped_app
    raise exc
  File "/Library/Frameworks/Python.framework/Versions/3.12/lib/python3.12/site-packages/starlette/_exception_handler.py", line 42, in wrapped_app
    await app(scope, receive, sender)
  File "/Library/Frameworks/Python.framework/Versions/3.12/lib/python3.12/site-packages/starlette/routing.py", line 73, in app
    response = await f(request)
               ^^^^^^^^^^^^^^^^
  File "/Library/Frameworks/Python.framework/Versions/3.12/lib/python3.12/site-packages/fastapi/routing.py", line 301, in app
    raw_response = await run_endpoint_function(
                   ^^^^^^^^^^^^^^^^^^^^^^^^^^^^
  File "/Library/Frameworks/Python.framework/Versions/3.12/lib/python3.12/site-packages/fastapi/routing.py", line 214, in run_endpoint_function
    return await run_in_threadpool(dependant.call, **values)
           ^^^^^^^^^^^^^^^^^^^^^^^^^^^^^^^^^^^^^^^^^^^^^^^^^
  File "/Library/Frameworks/Python.framework/Versions/3.12/lib/python3.12/site-packages/starlette/concurrency.py", line 37, in run_in_threadpool
    return await anyio.to_thread.run_sync(func)
           ^^^^^^^^^^^^^^^^^^^^^^^^^^^^^^^^^^^^
  File "/Library/Frameworks/Python.framework/Versions/3.12/lib/python3.12/site-packages/anyio/to_thread.py", line 56, in run_sync
    return await get_async_backend().run_sync_in_worker_thread(
           ^^^^^^^^^^^^^^^^^^^^^^^^^^^^^^^^^^^^^^^^^^^^^^^^^^^^
  File "/Library/Frameworks/Python.framework/Versions/3.12/lib/python3.12/site-packages/anyio/_backends/_asyncio.py", line 2461, in run_sync_in_worker_thread
    return await future
           ^^^^^^^^^^^^
  File "/Library/Frameworks/Python.framework/Versions/3.12/lib/python3.12/asyncio/futures.py", line 291, in __await__
    yield self  # This tells Task to wait for completion.
    ^^^^^^^^^^
  File "/Library/Frameworks/Python.framework/Versions/3.12/lib/python3.12/asyncio/tasks.py", line 385, in __wakeup
    future.result()
  File "/Library/Frameworks/Python.framework/Versions/3.12/lib/python3.12/asyncio/futures.py", line 203, in result
    raise self._exception.with_traceback(self._exception_tb)
  File "/Library/Frameworks/Python.framework/Versions/3.12/lib/python3.12/site-packages/anyio/_backends/_asyncio.py", line 962, in run
    result = context.run(func, *args)
             ^^^^^^^^^^^^^^^^^^^^^^^^
  File "/Library/Frameworks/Python.framework/Versions/3.12/lib/python3.12/site-packages/aktools/core/api.py", line 141, in root
    received_df = eval("ak." + item_id + "()")
                  ^^^^^^^^^^^^^^^^^^^^^^^^^^^^
  File "<string>", line 1, in <module>
  File "/Library/Frameworks/Python.framework/Versions/3.12/lib/python3.12/site-packages/akshare/stock_a/stock_zh_a_spot.py", line 231, in stock_zh_a_spot_em
    return asyncio.run(stock_zh_a_spot_em_async())
           ^^^^^^^^^^^^^^^^^^^^^^^^^^^^^^^^^^^^^^^
  File "/Library/Frameworks/Python.framework/Versions/3.12/lib/python3.12/site-packages/nest_asyncio.py", line 30, in run
    return loop.run_until_complete(task)
           ^^^^^^^^^^^^^^^^^^^^^^^^^^^^^
  File "/Library/Frameworks/Python.framework/Versions/3.12/lib/python3.12/site-packages/nest_asyncio.py", line 98, in run_until_complete
    return f.result()
           ^^^^^^^^^^
  File "/Library/Frameworks/Python.framework/Versions/3.12/lib/python3.12/asyncio/futures.py", line 203, in result
    raise self._exception.with_traceback(self._exception_tb)
  File "/Library/Frameworks/Python.framework/Versions/3.12/lib/python3.12/asyncio/tasks.py", line 314, in __step_run_and_handle_result
    result = coro.send(None)
             ^^^^^^^^^^^^^^^
  File "/Library/Frameworks/Python.framework/Versions/3.12/lib/python3.12/site-packages/akshare/stock_a/stock_zh_a_spot.py", line 217, in stock_zh_a_spot_em_async
    results = await fetch_all_pages_async(url, params)
              ^^^^^^^^^^^^^^^^^^^^^^^^^^^^^^^^^^^^^^^^
  File "/Library/Frameworks/Python.framework/Versions/3.12/lib/python3.12/site-packages/akshare/stock_a/stock_zh_a_spot.py", line 53, in fetch_all_pages_async
    results = await asyncio.gather(*tasks)
              ^^^^^^^^^^^^^^^^^^^^^^^^^^^^
  File "/Library/Frameworks/Python.framework/Versions/3.12/lib/python3.12/asyncio/tasks.py", line 385, in __wakeup
    future.result()
  File "/Library/Frameworks/Python.framework/Versions/3.12/lib/python3.12/asyncio/tasks.py", line 316, in __step_run_and_handle_result
    result = coro.throw(exc)
             ^^^^^^^^^^^^^^^
  File "/Library/Frameworks/Python.framework/Versions/3.12/lib/python3.12/site-packages/akshare/stock_a/stock_zh_a_spot.py", line 21, in fetch_single_page
    async with session.get(url, params=params, ssl=False) as response:
               ^^^^^^^^^^^^^^^^^^^^^^^^^^^^^^^^^^^^^^^^^^
  File "/Library/Frameworks/Python.framework/Versions/3.12/lib/python3.12/site-packages/aiohttp/client.py", line 1425, in __aenter__
    self._resp: _RetType = await self._coro
                           ^^^^^^^^^^^^^^^^
  File "/Library/Frameworks/Python.framework/Versions/3.12/lib/python3.12/site-packages/aiohttp/client.py", line 730, in _request
    await resp.start(conn)
  File "/Library/Frameworks/Python.framework/Versions/3.12/lib/python3.12/site-packages/aiohttp/client_reqrep.py", line 1054, in start
    with self._timer:
         ^^^^^^^^^^^
  File "/Library/Frameworks/Python.framework/Versions/3.12/lib/python3.12/site-packages/aiohttp/helpers.py", line 685, in __exit__
    raise asyncio.TimeoutError from exc_val
TimeoutError
  0%|          | 0/2 [00:00<?, ?it/s] 50%|█████     | 1/2 [00:02<00:02,  2.18s/it]100%|██████████| 2/2 [00:07<00:00,  4.14s/it]                                             INFO:     127.0.0.1:58733 - "GET /api/public/stock_zh_index_spot_em HTTP/1.1" 200 OK
  0%|          | 0/2 [00:00<?, ?it/s] 50%|█████     | 1/2 [00:02<00:02,  2.36s/it]100%|██████████| 2/2 [00:04<00:00,  2.14s/it]                                             INFO:     127.0.0.1:58848 - "GET /api/public/stock_zh_index_spot_em HTTP/1.1" 200 OK
INFO:     127.0.0.1:58875 - "GET /api/public/stock_zh_a_spot_em HTTP/1.1" 200 OK
INFO:     127.0.0.1:58875 - "GET /api/public/stock_zh_a_spot_em HTTP/1.1" 200 OK
INFO:     127.0.0.1:58875 - "GET /api/public/stock_zh_a_spot_em HTTP/1.1" 200 OK
  0%|          | 0/2 [00:00<?, ?it/s] 50%|█████     | 1/2 [00:01<00:01,  1.24s/it]100%|██████████| 2/2 [00:01<00:00,  1.21it/s]                                             INFO:     127.0.0.1:58875 - "GET /api/public/stock_zh_index_spot_em HTTP/1.1" 200 OK
INFO:     127.0.0.1:59114 - "GET /api/public/stock_zh_a_spot_em HTTP/1.1" 200 OK
  0%|          | 0/2 [00:00<?, ?it/s] 50%|█████     | 1/2 [00:04<00:04,  4.45s/it]100%|██████████| 2/2 [00:09<00:00,  4.97s/it]                                             INFO:     127.0.0.1:59250 - "GET /api/public/stock_zh_index_spot_em HTTP/1.1" 200 OK
ERROR:    Exception in ASGI application
Traceback (most recent call last):
  File "/Library/Frameworks/Python.framework/Versions/3.12/lib/python3.12/site-packages/aiohttp/connector.py", line 1122, in _wrap_create_connection
    return await self._loop.create_connection(*args, **kwargs, sock=sock)
           ^^^^^^^^^^^^^^^^^^^^^^^^^^^^^^^^^^^^^^^^^^^^^^^^^^^^^^^^^^^^^^
  File "/Library/Frameworks/Python.framework/Versions/3.12/lib/python3.12/asyncio/base_events.py", line 1148, in create_connection
    transport, protocol = await self._create_connection_transport(
                          ^^^^^^^^^^^^^^^^^^^^^^^^^^^^^^^^^^^^^^^^
  File "/Library/Frameworks/Python.framework/Versions/3.12/lib/python3.12/asyncio/base_events.py", line 1181, in _create_connection_transport
    await waiter
  File "/Library/Frameworks/Python.framework/Versions/3.12/lib/python3.12/asyncio/futures.py", line 291, in __await__
    yield self  # This tells Task to wait for completion.
    ^^^^^^^^^^
  File "/Library/Frameworks/Python.framework/Versions/3.12/lib/python3.12/asyncio/tasks.py", line 385, in __wakeup
    future.result()
  File "/Library/Frameworks/Python.framework/Versions/3.12/lib/python3.12/asyncio/futures.py", line 198, in result
    raise exc
asyncio.exceptions.CancelledError

The above exception was the direct cause of the following exception:

Traceback (most recent call last):
  File "/Library/Frameworks/Python.framework/Versions/3.12/lib/python3.12/site-packages/aiohttp/client.py", line 703, in _request
    conn = await self._connector.connect(
           ^^^^^^^^^^^^^^^^^^^^^^^^^^^^^^
  File "/Library/Frameworks/Python.framework/Versions/3.12/lib/python3.12/site-packages/aiohttp/connector.py", line 548, in connect
    proto = await self._create_connection(req, traces, timeout)
            ^^^^^^^^^^^^^^^^^^^^^^^^^^^^^^^^^^^^^^^^^^^^^^^^^^^
  File "/Library/Frameworks/Python.framework/Versions/3.12/lib/python3.12/site-packages/aiohttp/connector.py", line 1056, in _create_connection
    _, proto = await self._create_direct_connection(req, traces, timeout)
               ^^^^^^^^^^^^^^^^^^^^^^^^^^^^^^^^^^^^^^^^^^^^^^^^^^^^^^^^^^
  File "/Library/Frameworks/Python.framework/Versions/3.12/lib/python3.12/site-packages/aiohttp/connector.py", line 1400, in _create_direct_connection
    raise last_exc
  File "/Library/Frameworks/Python.framework/Versions/3.12/lib/python3.12/site-packages/aiohttp/connector.py", line 1369, in _create_direct_connection
    transp, proto = await self._wrap_create_connection(
                    ^^^^^^^^^^^^^^^^^^^^^^^^^^^^^^^^^^^
  File "/Library/Frameworks/Python.framework/Versions/3.12/lib/python3.12/site-packages/aiohttp/connector.py", line 1112, in _wrap_create_connection
    async with ceil_timeout(
               ^^^^^^^^^^^^^
  File "/Library/Frameworks/Python.framework/Versions/3.12/lib/python3.12/asyncio/timeouts.py", line 115, in __aexit__
    raise TimeoutError from exc_val
TimeoutError

The above exception was the direct cause of the following exception:

Traceback (most recent call last):
  File "/Library/Frameworks/Python.framework/Versions/3.12/lib/python3.12/site-packages/uvicorn/protocols/http/httptools_impl.py", line 401, in run_asgi
    result = await app(  # type: ignore[func-returns-value]
             ^^^^^^^^^^^^^^^^^^^^^^^^^^^^^^^^^^^^^^^^^^^^^^
  File "/Library/Frameworks/Python.framework/Versions/3.12/lib/python3.12/site-packages/uvicorn/middleware/proxy_headers.py", line 70, in __call__
    return await self.app(scope, receive, send)
           ^^^^^^^^^^^^^^^^^^^^^^^^^^^^^^^^^^^^
  File "/Library/Frameworks/Python.framework/Versions/3.12/lib/python3.12/site-packages/fastapi/applications.py", line 1054, in __call__
    await super().__call__(scope, receive, send)
  File "/Library/Frameworks/Python.framework/Versions/3.12/lib/python3.12/site-packages/starlette/applications.py", line 112, in __call__
    await self.middleware_stack(scope, receive, send)
  File "/Library/Frameworks/Python.framework/Versions/3.12/lib/python3.12/site-packages/starlette/middleware/errors.py", line 187, in __call__
    raise exc
  File "/Library/Frameworks/Python.framework/Versions/3.12/lib/python3.12/site-packages/starlette/middleware/errors.py", line 165, in __call__
    await self.app(scope, receive, _send)
  File "/Library/Frameworks/Python.framework/Versions/3.12/lib/python3.12/site-packages/starlette/middleware/cors.py", line 85, in __call__
    await self.app(scope, receive, send)
  File "/Library/Frameworks/Python.framework/Versions/3.12/lib/python3.12/site-packages/starlette/middleware/exceptions.py", line 62, in __call__
    await wrap_app_handling_exceptions(self.app, conn)(scope, receive, send)
  File "/Library/Frameworks/Python.framework/Versions/3.12/lib/python3.12/site-packages/starlette/_exception_handler.py", line 53, in wrapped_app
    raise exc
  File "/Library/Frameworks/Python.framework/Versions/3.12/lib/python3.12/site-packages/starlette/_exception_handler.py", line 42, in wrapped_app
    await app(scope, receive, sender)
  File "/Library/Frameworks/Python.framework/Versions/3.12/lib/python3.12/site-packages/starlette/routing.py", line 715, in __call__
    await self.middleware_stack(scope, receive, send)
  File "/Library/Frameworks/Python.framework/Versions/3.12/lib/python3.12/site-packages/starlette/routing.py", line 735, in app
    await route.handle(scope, receive, send)
  File "/Library/Frameworks/Python.framework/Versions/3.12/lib/python3.12/site-packages/starlette/routing.py", line 288, in handle
    await self.app(scope, receive, send)
  File "/Library/Frameworks/Python.framework/Versions/3.12/lib/python3.12/site-packages/starlette/routing.py", line 76, in app
    await wrap_app_handling_exceptions(app, request)(scope, receive, send)
  File "/Library/Frameworks/Python.framework/Versions/3.12/lib/python3.12/site-packages/starlette/_exception_handler.py", line 53, in wrapped_app
    raise exc
  File "/Library/Frameworks/Python.framework/Versions/3.12/lib/python3.12/site-packages/starlette/_exception_handler.py", line 42, in wrapped_app
    await app(scope, receive, sender)
  File "/Library/Frameworks/Python.framework/Versions/3.12/lib/python3.12/site-packages/starlette/routing.py", line 73, in app
    response = await f(request)
               ^^^^^^^^^^^^^^^^
  File "/Library/Frameworks/Python.framework/Versions/3.12/lib/python3.12/site-packages/fastapi/routing.py", line 301, in app
    raw_response = await run_endpoint_function(
                   ^^^^^^^^^^^^^^^^^^^^^^^^^^^^
  File "/Library/Frameworks/Python.framework/Versions/3.12/lib/python3.12/site-packages/fastapi/routing.py", line 214, in run_endpoint_function
    return await run_in_threadpool(dependant.call, **values)
           ^^^^^^^^^^^^^^^^^^^^^^^^^^^^^^^^^^^^^^^^^^^^^^^^^
  File "/Library/Frameworks/Python.framework/Versions/3.12/lib/python3.12/site-packages/starlette/concurrency.py", line 37, in run_in_threadpool
    return await anyio.to_thread.run_sync(func)
           ^^^^^^^^^^^^^^^^^^^^^^^^^^^^^^^^^^^^
  File "/Library/Frameworks/Python.framework/Versions/3.12/lib/python3.12/site-packages/anyio/to_thread.py", line 56, in run_sync
    return await get_async_backend().run_sync_in_worker_thread(
           ^^^^^^^^^^^^^^^^^^^^^^^^^^^^^^^^^^^^^^^^^^^^^^^^^^^^
  File "/Library/Frameworks/Python.framework/Versions/3.12/lib/python3.12/site-packages/anyio/_backends/_asyncio.py", line 2461, in run_sync_in_worker_thread
    return await future
           ^^^^^^^^^^^^
  File "/Library/Frameworks/Python.framework/Versions/3.12/lib/python3.12/asyncio/futures.py", line 291, in __await__
    yield self  # This tells Task to wait for completion.
    ^^^^^^^^^^
  File "/Library/Frameworks/Python.framework/Versions/3.12/lib/python3.12/asyncio/tasks.py", line 385, in __wakeup
    future.result()
  File "/Library/Frameworks/Python.framework/Versions/3.12/lib/python3.12/asyncio/futures.py", line 203, in result
    raise self._exception.with_traceback(self._exception_tb)
  File "/Library/Frameworks/Python.framework/Versions/3.12/lib/python3.12/site-packages/anyio/_backends/_asyncio.py", line 962, in run
    result = context.run(func, *args)
             ^^^^^^^^^^^^^^^^^^^^^^^^
  File "/Library/Frameworks/Python.framework/Versions/3.12/lib/python3.12/site-packages/aktools/core/api.py", line 141, in root
    received_df = eval("ak." + item_id + "()")
                  ^^^^^^^^^^^^^^^^^^^^^^^^^^^^
  File "<string>", line 1, in <module>
  File "/Library/Frameworks/Python.framework/Versions/3.12/lib/python3.12/site-packages/akshare/stock_a/stock_zh_a_spot.py", line 231, in stock_zh_a_spot_em
    return asyncio.run(stock_zh_a_spot_em_async())
           ^^^^^^^^^^^^^^^^^^^^^^^^^^^^^^^^^^^^^^^
  File "/Library/Frameworks/Python.framework/Versions/3.12/lib/python3.12/site-packages/nest_asyncio.py", line 30, in run
    return loop.run_until_complete(task)
           ^^^^^^^^^^^^^^^^^^^^^^^^^^^^^
  File "/Library/Frameworks/Python.framework/Versions/3.12/lib/python3.12/site-packages/nest_asyncio.py", line 98, in run_until_complete
    return f.result()
           ^^^^^^^^^^
  File "/Library/Frameworks/Python.framework/Versions/3.12/lib/python3.12/asyncio/futures.py", line 203, in result
    raise self._exception.with_traceback(self._exception_tb)
  File "/Library/Frameworks/Python.framework/Versions/3.12/lib/python3.12/asyncio/tasks.py", line 314, in __step_run_and_handle_result
    result = coro.send(None)
             ^^^^^^^^^^^^^^^
  File "/Library/Frameworks/Python.framework/Versions/3.12/lib/python3.12/site-packages/akshare/stock_a/stock_zh_a_spot.py", line 217, in stock_zh_a_spot_em_async
    results = await fetch_all_pages_async(url, params)
              ^^^^^^^^^^^^^^^^^^^^^^^^^^^^^^^^^^^^^^^^
  File "/Library/Frameworks/Python.framework/Versions/3.12/lib/python3.12/site-packages/akshare/stock_a/stock_zh_a_spot.py", line 53, in fetch_all_pages_async
    results = await asyncio.gather(*tasks)
              ^^^^^^^^^^^^^^^^^^^^^^^^^^^^
  File "/Library/Frameworks/Python.framework/Versions/3.12/lib/python3.12/asyncio/tasks.py", line 385, in __wakeup
    future.result()
  File "/Library/Frameworks/Python.framework/Versions/3.12/lib/python3.12/asyncio/tasks.py", line 316, in __step_run_and_handle_result
    result = coro.throw(exc)
             ^^^^^^^^^^^^^^^
  File "/Library/Frameworks/Python.framework/Versions/3.12/lib/python3.12/site-packages/akshare/stock_a/stock_zh_a_spot.py", line 21, in fetch_single_page
    async with session.get(url, params=params, ssl=False) as response:
               ^^^^^^^^^^^^^^^^^^^^^^^^^^^^^^^^^^^^^^^^^^
  File "/Library/Frameworks/Python.framework/Versions/3.12/lib/python3.12/site-packages/aiohttp/client.py", line 1425, in __aenter__
    self._resp: _RetType = await self._coro
                           ^^^^^^^^^^^^^^^^
  File "/Library/Frameworks/Python.framework/Versions/3.12/lib/python3.12/site-packages/aiohttp/client.py", line 707, in _request
    raise ConnectionTimeoutError(
aiohttp.client_exceptions.ConnectionTimeoutError: Connection timeout to host https://82.push2.eastmoney.com/api/qt/clist/get
ERROR:    Exception in ASGI application
Traceback (most recent call last):
  File "/Library/Frameworks/Python.framework/Versions/3.12/lib/python3.12/site-packages/aiohttp/client_reqrep.py", line 1059, in start
    message, payload = await protocol.read()  # type: ignore[union-attr]
                       ^^^^^^^^^^^^^^^^^^^^^
  File "/Library/Frameworks/Python.framework/Versions/3.12/lib/python3.12/site-packages/aiohttp/streams.py", line 672, in read
    await self._waiter
  File "/Library/Frameworks/Python.framework/Versions/3.12/lib/python3.12/asyncio/futures.py", line 291, in __await__
    yield self  # This tells Task to wait for completion.
    ^^^^^^^^^^
  File "/Library/Frameworks/Python.framework/Versions/3.12/lib/python3.12/asyncio/tasks.py", line 385, in __wakeup
    future.result()
  File "/Library/Frameworks/Python.framework/Versions/3.12/lib/python3.12/asyncio/futures.py", line 198, in result
    raise exc
asyncio.exceptions.CancelledError

The above exception was the direct cause of the following exception:

Traceback (most recent call last):
  File "/Library/Frameworks/Python.framework/Versions/3.12/lib/python3.12/site-packages/uvicorn/protocols/http/httptools_impl.py", line 401, in run_asgi
    result = await app(  # type: ignore[func-returns-value]
             ^^^^^^^^^^^^^^^^^^^^^^^^^^^^^^^^^^^^^^^^^^^^^^
  File "/Library/Frameworks/Python.framework/Versions/3.12/lib/python3.12/site-packages/uvicorn/middleware/proxy_headers.py", line 70, in __call__
    return await self.app(scope, receive, send)
           ^^^^^^^^^^^^^^^^^^^^^^^^^^^^^^^^^^^^
  File "/Library/Frameworks/Python.framework/Versions/3.12/lib/python3.12/site-packages/fastapi/applications.py", line 1054, in __call__
    await super().__call__(scope, receive, send)
  File "/Library/Frameworks/Python.framework/Versions/3.12/lib/python3.12/site-packages/starlette/applications.py", line 112, in __call__
    await self.middleware_stack(scope, receive, send)
  File "/Library/Frameworks/Python.framework/Versions/3.12/lib/python3.12/site-packages/starlette/middleware/errors.py", line 187, in __call__
    raise exc
  File "/Library/Frameworks/Python.framework/Versions/3.12/lib/python3.12/site-packages/starlette/middleware/errors.py", line 165, in __call__
    await self.app(scope, receive, _send)
  File "/Library/Frameworks/Python.framework/Versions/3.12/lib/python3.12/site-packages/starlette/middleware/cors.py", line 85, in __call__
    await self.app(scope, receive, send)
  File "/Library/Frameworks/Python.framework/Versions/3.12/lib/python3.12/site-packages/starlette/middleware/exceptions.py", line 62, in __call__
    await wrap_app_handling_exceptions(self.app, conn)(scope, receive, send)
  File "/Library/Frameworks/Python.framework/Versions/3.12/lib/python3.12/site-packages/starlette/_exception_handler.py", line 53, in wrapped_app
    raise exc
  File "/Library/Frameworks/Python.framework/Versions/3.12/lib/python3.12/site-packages/starlette/_exception_handler.py", line 42, in wrapped_app
    await app(scope, receive, sender)
  File "/Library/Frameworks/Python.framework/Versions/3.12/lib/python3.12/site-packages/starlette/routing.py", line 715, in __call__
    await self.middleware_stack(scope, receive, send)
  File "/Library/Frameworks/Python.framework/Versions/3.12/lib/python3.12/site-packages/starlette/routing.py", line 735, in app
    await route.handle(scope, receive, send)
  File "/Library/Frameworks/Python.framework/Versions/3.12/lib/python3.12/site-packages/starlette/routing.py", line 288, in handle
    await self.app(scope, receive, send)
  File "/Library/Frameworks/Python.framework/Versions/3.12/lib/python3.12/site-packages/starlette/routing.py", line 76, in app
    await wrap_app_handling_exceptions(app, request)(scope, receive, send)
  File "/Library/Frameworks/Python.framework/Versions/3.12/lib/python3.12/site-packages/starlette/_exception_handler.py", line 53, in wrapped_app
    raise exc
  File "/Library/Frameworks/Python.framework/Versions/3.12/lib/python3.12/site-packages/starlette/_exception_handler.py", line 42, in wrapped_app
    await app(scope, receive, sender)
  File "/Library/Frameworks/Python.framework/Versions/3.12/lib/python3.12/site-packages/starlette/routing.py", line 73, in app
    response = await f(request)
               ^^^^^^^^^^^^^^^^
  File "/Library/Frameworks/Python.framework/Versions/3.12/lib/python3.12/site-packages/fastapi/routing.py", line 301, in app
    raw_response = await run_endpoint_function(
                   ^^^^^^^^^^^^^^^^^^^^^^^^^^^^
  File "/Library/Frameworks/Python.framework/Versions/3.12/lib/python3.12/site-packages/fastapi/routing.py", line 214, in run_endpoint_function
    return await run_in_threadpool(dependant.call, **values)
           ^^^^^^^^^^^^^^^^^^^^^^^^^^^^^^^^^^^^^^^^^^^^^^^^^
  File "/Library/Frameworks/Python.framework/Versions/3.12/lib/python3.12/site-packages/starlette/concurrency.py", line 37, in run_in_threadpool
    return await anyio.to_thread.run_sync(func)
           ^^^^^^^^^^^^^^^^^^^^^^^^^^^^^^^^^^^^
  File "/Library/Frameworks/Python.framework/Versions/3.12/lib/python3.12/site-packages/anyio/to_thread.py", line 56, in run_sync
    return await get_async_backend().run_sync_in_worker_thread(
           ^^^^^^^^^^^^^^^^^^^^^^^^^^^^^^^^^^^^^^^^^^^^^^^^^^^^
  File "/Library/Frameworks/Python.framework/Versions/3.12/lib/python3.12/site-packages/anyio/_backends/_asyncio.py", line 2461, in run_sync_in_worker_thread
    return await future
           ^^^^^^^^^^^^
  File "/Library/Frameworks/Python.framework/Versions/3.12/lib/python3.12/asyncio/futures.py", line 291, in __await__
    yield self  # This tells Task to wait for completion.
    ^^^^^^^^^^
  File "/Library/Frameworks/Python.framework/Versions/3.12/lib/python3.12/asyncio/tasks.py", line 385, in __wakeup
    future.result()
  File "/Library/Frameworks/Python.framework/Versions/3.12/lib/python3.12/asyncio/futures.py", line 203, in result
    raise self._exception.with_traceback(self._exception_tb)
  File "/Library/Frameworks/Python.framework/Versions/3.12/lib/python3.12/site-packages/anyio/_backends/_asyncio.py", line 962, in run
    result = context.run(func, *args)
             ^^^^^^^^^^^^^^^^^^^^^^^^
  File "/Library/Frameworks/Python.framework/Versions/3.12/lib/python3.12/site-packages/aktools/core/api.py", line 141, in root
    received_df = eval("ak." + item_id + "()")
                  ^^^^^^^^^^^^^^^^^^^^^^^^^^^^
  File "<string>", line 1, in <module>
  File "/Library/Frameworks/Python.framework/Versions/3.12/lib/python3.12/site-packages/akshare/stock_a/stock_zh_a_spot.py", line 231, in stock_zh_a_spot_em
    return asyncio.run(stock_zh_a_spot_em_async())
           ^^^^^^^^^^^^^^^^^^^^^^^^^^^^^^^^^^^^^^^
  File "/Library/Frameworks/Python.framework/Versions/3.12/lib/python3.12/site-packages/nest_asyncio.py", line 30, in run
    return loop.run_until_complete(task)
           ^^^^^^^^^^^^^^^^^^^^^^^^^^^^^
  File "/Library/Frameworks/Python.framework/Versions/3.12/lib/python3.12/site-packages/nest_asyncio.py", line 98, in run_until_complete
    return f.result()
           ^^^^^^^^^^
  File "/Library/Frameworks/Python.framework/Versions/3.12/lib/python3.12/asyncio/futures.py", line 203, in result
    raise self._exception.with_traceback(self._exception_tb)
  File "/Library/Frameworks/Python.framework/Versions/3.12/lib/python3.12/asyncio/tasks.py", line 314, in __step_run_and_handle_result
    result = coro.send(None)
             ^^^^^^^^^^^^^^^
  File "/Library/Frameworks/Python.framework/Versions/3.12/lib/python3.12/site-packages/akshare/stock_a/stock_zh_a_spot.py", line 217, in stock_zh_a_spot_em_async
    results = await fetch_all_pages_async(url, params)
              ^^^^^^^^^^^^^^^^^^^^^^^^^^^^^^^^^^^^^^^^
  File "/Library/Frameworks/Python.framework/Versions/3.12/lib/python3.12/site-packages/akshare/stock_a/stock_zh_a_spot.py", line 53, in fetch_all_pages_async
    results = await asyncio.gather(*tasks)
              ^^^^^^^^^^^^^^^^^^^^^^^^^^^^
  File "/Library/Frameworks/Python.framework/Versions/3.12/lib/python3.12/asyncio/tasks.py", line 385, in __wakeup
    future.result()
  File "/Library/Frameworks/Python.framework/Versions/3.12/lib/python3.12/asyncio/tasks.py", line 316, in __step_run_and_handle_result
    result = coro.throw(exc)
             ^^^^^^^^^^^^^^^
  File "/Library/Frameworks/Python.framework/Versions/3.12/lib/python3.12/site-packages/akshare/stock_a/stock_zh_a_spot.py", line 21, in fetch_single_page
    async with session.get(url, params=params, ssl=False) as response:
               ^^^^^^^^^^^^^^^^^^^^^^^^^^^^^^^^^^^^^^^^^^
  File "/Library/Frameworks/Python.framework/Versions/3.12/lib/python3.12/site-packages/aiohttp/client.py", line 1425, in __aenter__
    self._resp: _RetType = await self._coro
                           ^^^^^^^^^^^^^^^^
  File "/Library/Frameworks/Python.framework/Versions/3.12/lib/python3.12/site-packages/aiohttp/client.py", line 730, in _request
    await resp.start(conn)
  File "/Library/Frameworks/Python.framework/Versions/3.12/lib/python3.12/site-packages/aiohttp/client_reqrep.py", line 1054, in start
    with self._timer:
         ^^^^^^^^^^^
  File "/Library/Frameworks/Python.framework/Versions/3.12/lib/python3.12/site-packages/aiohttp/helpers.py", line 685, in __exit__
    raise asyncio.TimeoutError from exc_val
TimeoutError
INFO:     127.0.0.1:59258 - "GET /api/public/stock_zh_a_spot_em HTTP/1.1" 200 OK
  0%|          | 0/2 [00:00<?, ?it/s] 50%|█████     | 1/2 [00:04<00:04,  4.79s/it]100%|██████████| 2/2 [00:19<00:00, 10.89s/it]                                             INFO:     127.0.0.1:59394 - "GET /api/public/stock_zh_index_spot_em HTTP/1.1" 200 OK
INFO:     127.0.0.1:59406 - "GET /api/public/stock_zh_a_spot_em HTTP/1.1" 200 OK
ERROR:    Exception in ASGI application
Traceback (most recent call last):
  File "/Library/Frameworks/Python.framework/Versions/3.12/lib/python3.12/site-packages/aiohttp/streams.py", line 347, in _wait
    await waiter
  File "/Library/Frameworks/Python.framework/Versions/3.12/lib/python3.12/asyncio/futures.py", line 291, in __await__
    yield self  # This tells Task to wait for completion.
    ^^^^^^^^^^
  File "/Library/Frameworks/Python.framework/Versions/3.12/lib/python3.12/asyncio/tasks.py", line 385, in __wakeup
    future.result()
  File "/Library/Frameworks/Python.framework/Versions/3.12/lib/python3.12/asyncio/futures.py", line 198, in result
    raise exc
asyncio.exceptions.CancelledError

The above exception was the direct cause of the following exception:

Traceback (most recent call last):
  File "/Library/Frameworks/Python.framework/Versions/3.12/lib/python3.12/site-packages/uvicorn/protocols/http/httptools_impl.py", line 401, in run_asgi
    result = await app(  # type: ignore[func-returns-value]
             ^^^^^^^^^^^^^^^^^^^^^^^^^^^^^^^^^^^^^^^^^^^^^^
  File "/Library/Frameworks/Python.framework/Versions/3.12/lib/python3.12/site-packages/uvicorn/middleware/proxy_headers.py", line 70, in __call__
    return await self.app(scope, receive, send)
           ^^^^^^^^^^^^^^^^^^^^^^^^^^^^^^^^^^^^
  File "/Library/Frameworks/Python.framework/Versions/3.12/lib/python3.12/site-packages/fastapi/applications.py", line 1054, in __call__
    await super().__call__(scope, receive, send)
  File "/Library/Frameworks/Python.framework/Versions/3.12/lib/python3.12/site-packages/starlette/applications.py", line 112, in __call__
    await self.middleware_stack(scope, receive, send)
  File "/Library/Frameworks/Python.framework/Versions/3.12/lib/python3.12/site-packages/starlette/middleware/errors.py", line 187, in __call__
    raise exc
  File "/Library/Frameworks/Python.framework/Versions/3.12/lib/python3.12/site-packages/starlette/middleware/errors.py", line 165, in __call__
    await self.app(scope, receive, _send)
  File "/Library/Frameworks/Python.framework/Versions/3.12/lib/python3.12/site-packages/starlette/middleware/cors.py", line 85, in __call__
    await self.app(scope, receive, send)
  File "/Library/Frameworks/Python.framework/Versions/3.12/lib/python3.12/site-packages/starlette/middleware/exceptions.py", line 62, in __call__
    await wrap_app_handling_exceptions(self.app, conn)(scope, receive, send)
  File "/Library/Frameworks/Python.framework/Versions/3.12/lib/python3.12/site-packages/starlette/_exception_handler.py", line 53, in wrapped_app
    raise exc
  File "/Library/Frameworks/Python.framework/Versions/3.12/lib/python3.12/site-packages/starlette/_exception_handler.py", line 42, in wrapped_app
    await app(scope, receive, sender)
  File "/Library/Frameworks/Python.framework/Versions/3.12/lib/python3.12/site-packages/starlette/routing.py", line 715, in __call__
    await self.middleware_stack(scope, receive, send)
  File "/Library/Frameworks/Python.framework/Versions/3.12/lib/python3.12/site-packages/starlette/routing.py", line 735, in app
    await route.handle(scope, receive, send)
  File "/Library/Frameworks/Python.framework/Versions/3.12/lib/python3.12/site-packages/starlette/routing.py", line 288, in handle
    await self.app(scope, receive, send)
  File "/Library/Frameworks/Python.framework/Versions/3.12/lib/python3.12/site-packages/starlette/routing.py", line 76, in app
    await wrap_app_handling_exceptions(app, request)(scope, receive, send)
  File "/Library/Frameworks/Python.framework/Versions/3.12/lib/python3.12/site-packages/starlette/_exception_handler.py", line 53, in wrapped_app
    raise exc
  File "/Library/Frameworks/Python.framework/Versions/3.12/lib/python3.12/site-packages/starlette/_exception_handler.py", line 42, in wrapped_app
    await app(scope, receive, sender)
  File "/Library/Frameworks/Python.framework/Versions/3.12/lib/python3.12/site-packages/starlette/routing.py", line 73, in app
    response = await f(request)
               ^^^^^^^^^^^^^^^^
  File "/Library/Frameworks/Python.framework/Versions/3.12/lib/python3.12/site-packages/fastapi/routing.py", line 301, in app
    raw_response = await run_endpoint_function(
                   ^^^^^^^^^^^^^^^^^^^^^^^^^^^^
  File "/Library/Frameworks/Python.framework/Versions/3.12/lib/python3.12/site-packages/fastapi/routing.py", line 214, in run_endpoint_function
    return await run_in_threadpool(dependant.call, **values)
           ^^^^^^^^^^^^^^^^^^^^^^^^^^^^^^^^^^^^^^^^^^^^^^^^^
  File "/Library/Frameworks/Python.framework/Versions/3.12/lib/python3.12/site-packages/starlette/concurrency.py", line 37, in run_in_threadpool
    return await anyio.to_thread.run_sync(func)
           ^^^^^^^^^^^^^^^^^^^^^^^^^^^^^^^^^^^^
  File "/Library/Frameworks/Python.framework/Versions/3.12/lib/python3.12/site-packages/anyio/to_thread.py", line 56, in run_sync
    return await get_async_backend().run_sync_in_worker_thread(
           ^^^^^^^^^^^^^^^^^^^^^^^^^^^^^^^^^^^^^^^^^^^^^^^^^^^^
  File "/Library/Frameworks/Python.framework/Versions/3.12/lib/python3.12/site-packages/anyio/_backends/_asyncio.py", line 2461, in run_sync_in_worker_thread
    return await future
           ^^^^^^^^^^^^
  File "/Library/Frameworks/Python.framework/Versions/3.12/lib/python3.12/asyncio/futures.py", line 291, in __await__
    yield self  # This tells Task to wait for completion.
    ^^^^^^^^^^
  File "/Library/Frameworks/Python.framework/Versions/3.12/lib/python3.12/asyncio/tasks.py", line 385, in __wakeup
    future.result()
  File "/Library/Frameworks/Python.framework/Versions/3.12/lib/python3.12/asyncio/futures.py", line 203, in result
    raise self._exception.with_traceback(self._exception_tb)
  File "/Library/Frameworks/Python.framework/Versions/3.12/lib/python3.12/site-packages/anyio/_backends/_asyncio.py", line 962, in run
    result = context.run(func, *args)
             ^^^^^^^^^^^^^^^^^^^^^^^^
  File "/Library/Frameworks/Python.framework/Versions/3.12/lib/python3.12/site-packages/aktools/core/api.py", line 141, in root
    received_df = eval("ak." + item_id + "()")
                  ^^^^^^^^^^^^^^^^^^^^^^^^^^^^
  File "<string>", line 1, in <module>
  File "/Library/Frameworks/Python.framework/Versions/3.12/lib/python3.12/site-packages/akshare/stock_a/stock_zh_a_spot.py", line 231, in stock_zh_a_spot_em
    return asyncio.run(stock_zh_a_spot_em_async())
           ^^^^^^^^^^^^^^^^^^^^^^^^^^^^^^^^^^^^^^^
  File "/Library/Frameworks/Python.framework/Versions/3.12/lib/python3.12/site-packages/nest_asyncio.py", line 30, in run
    return loop.run_until_complete(task)
           ^^^^^^^^^^^^^^^^^^^^^^^^^^^^^
  File "/Library/Frameworks/Python.framework/Versions/3.12/lib/python3.12/site-packages/nest_asyncio.py", line 98, in run_until_complete
    return f.result()
           ^^^^^^^^^^
  File "/Library/Frameworks/Python.framework/Versions/3.12/lib/python3.12/asyncio/futures.py", line 203, in result
    raise self._exception.with_traceback(self._exception_tb)
  File "/Library/Frameworks/Python.framework/Versions/3.12/lib/python3.12/asyncio/tasks.py", line 314, in __step_run_and_handle_result
    result = coro.send(None)
             ^^^^^^^^^^^^^^^
  File "/Library/Frameworks/Python.framework/Versions/3.12/lib/python3.12/site-packages/akshare/stock_a/stock_zh_a_spot.py", line 217, in stock_zh_a_spot_em_async
    results = await fetch_all_pages_async(url, params)
              ^^^^^^^^^^^^^^^^^^^^^^^^^^^^^^^^^^^^^^^^
  File "/Library/Frameworks/Python.framework/Versions/3.12/lib/python3.12/site-packages/akshare/stock_a/stock_zh_a_spot.py", line 53, in fetch_all_pages_async
    results = await asyncio.gather(*tasks)
              ^^^^^^^^^^^^^^^^^^^^^^^^^^^^
  File "/Library/Frameworks/Python.framework/Versions/3.12/lib/python3.12/asyncio/tasks.py", line 385, in __wakeup
    future.result()
  File "/Library/Frameworks/Python.framework/Versions/3.12/lib/python3.12/asyncio/tasks.py", line 316, in __step_run_and_handle_result
    result = coro.throw(exc)
             ^^^^^^^^^^^^^^^
  File "/Library/Frameworks/Python.framework/Versions/3.12/lib/python3.12/site-packages/akshare/stock_a/stock_zh_a_spot.py", line 22, in fetch_single_page
    return await response.json()
           ^^^^^^^^^^^^^^^^^^^^^
  File "/Library/Frameworks/Python.framework/Versions/3.12/lib/python3.12/site-packages/aiohttp/client_reqrep.py", line 1276, in json
    await self.read()
  File "/Library/Frameworks/Python.framework/Versions/3.12/lib/python3.12/site-packages/aiohttp/client_reqrep.py", line 1218, in read
    self._body = await self.content.read()
                 ^^^^^^^^^^^^^^^^^^^^^^^^^
  File "/Library/Frameworks/Python.framework/Versions/3.12/lib/python3.12/site-packages/aiohttp/streams.py", line 418, in read
    block = await self.readany()
            ^^^^^^^^^^^^^^^^^^^^
  File "/Library/Frameworks/Python.framework/Versions/3.12/lib/python3.12/site-packages/aiohttp/streams.py", line 440, in readany
    await self._wait("readany")
  File "/Library/Frameworks/Python.framework/Versions/3.12/lib/python3.12/site-packages/aiohttp/streams.py", line 346, in _wait
    with self._timer:
         ^^^^^^^^^^^
  File "/Library/Frameworks/Python.framework/Versions/3.12/lib/python3.12/site-packages/aiohttp/helpers.py", line 685, in __exit__
    raise asyncio.TimeoutError from exc_val
TimeoutError
  0%|          | 0/2 [00:00<?, ?it/s] 50%|█████     | 1/2 [00:11<00:11, 11.95s/it]100%|██████████| 2/2 [00:14<00:00,  6.41s/it]                                             INFO:     127.0.0.1:59540 - "GET /api/public/stock_zh_index_spot_em HTTP/1.1" 200 OK
ERROR:    Exception in ASGI application
Traceback (most recent call last):
  File "/Library/Frameworks/Python.framework/Versions/3.12/lib/python3.12/site-packages/aiohttp/connector.py", line 1122, in _wrap_create_connection
    return await self._loop.create_connection(*args, **kwargs, sock=sock)
           ^^^^^^^^^^^^^^^^^^^^^^^^^^^^^^^^^^^^^^^^^^^^^^^^^^^^^^^^^^^^^^
  File "/Library/Frameworks/Python.framework/Versions/3.12/lib/python3.12/asyncio/base_events.py", line 1148, in create_connection
    transport, protocol = await self._create_connection_transport(
                          ^^^^^^^^^^^^^^^^^^^^^^^^^^^^^^^^^^^^^^^^
  File "/Library/Frameworks/Python.framework/Versions/3.12/lib/python3.12/asyncio/base_events.py", line 1181, in _create_connection_transport
    await waiter
  File "/Library/Frameworks/Python.framework/Versions/3.12/lib/python3.12/asyncio/futures.py", line 291, in __await__
    yield self  # This tells Task to wait for completion.
    ^^^^^^^^^^
  File "/Library/Frameworks/Python.framework/Versions/3.12/lib/python3.12/asyncio/tasks.py", line 385, in __wakeup
    future.result()
  File "/Library/Frameworks/Python.framework/Versions/3.12/lib/python3.12/asyncio/futures.py", line 198, in result
    raise exc
asyncio.exceptions.CancelledError

The above exception was the direct cause of the following exception:

Traceback (most recent call last):
  File "/Library/Frameworks/Python.framework/Versions/3.12/lib/python3.12/site-packages/aiohttp/client.py", line 703, in _request
    conn = await self._connector.connect(
           ^^^^^^^^^^^^^^^^^^^^^^^^^^^^^^
  File "/Library/Frameworks/Python.framework/Versions/3.12/lib/python3.12/site-packages/aiohttp/connector.py", line 548, in connect
    proto = await self._create_connection(req, traces, timeout)
            ^^^^^^^^^^^^^^^^^^^^^^^^^^^^^^^^^^^^^^^^^^^^^^^^^^^
  File "/Library/Frameworks/Python.framework/Versions/3.12/lib/python3.12/site-packages/aiohttp/connector.py", line 1056, in _create_connection
    _, proto = await self._create_direct_connection(req, traces, timeout)
               ^^^^^^^^^^^^^^^^^^^^^^^^^^^^^^^^^^^^^^^^^^^^^^^^^^^^^^^^^^
  File "/Library/Frameworks/Python.framework/Versions/3.12/lib/python3.12/site-packages/aiohttp/connector.py", line 1400, in _create_direct_connection
    raise last_exc
  File "/Library/Frameworks/Python.framework/Versions/3.12/lib/python3.12/site-packages/aiohttp/connector.py", line 1369, in _create_direct_connection
    transp, proto = await self._wrap_create_connection(
                    ^^^^^^^^^^^^^^^^^^^^^^^^^^^^^^^^^^^
  File "/Library/Frameworks/Python.framework/Versions/3.12/lib/python3.12/site-packages/aiohttp/connector.py", line 1112, in _wrap_create_connection
    async with ceil_timeout(
               ^^^^^^^^^^^^^
  File "/Library/Frameworks/Python.framework/Versions/3.12/lib/python3.12/asyncio/timeouts.py", line 115, in __aexit__
    raise TimeoutError from exc_val
TimeoutError

The above exception was the direct cause of the following exception:

Traceback (most recent call last):
  File "/Library/Frameworks/Python.framework/Versions/3.12/lib/python3.12/site-packages/uvicorn/protocols/http/httptools_impl.py", line 401, in run_asgi
    result = await app(  # type: ignore[func-returns-value]
             ^^^^^^^^^^^^^^^^^^^^^^^^^^^^^^^^^^^^^^^^^^^^^^
  File "/Library/Frameworks/Python.framework/Versions/3.12/lib/python3.12/site-packages/uvicorn/middleware/proxy_headers.py", line 70, in __call__
    return await self.app(scope, receive, send)
           ^^^^^^^^^^^^^^^^^^^^^^^^^^^^^^^^^^^^
  File "/Library/Frameworks/Python.framework/Versions/3.12/lib/python3.12/site-packages/fastapi/applications.py", line 1054, in __call__
    await super().__call__(scope, receive, send)
  File "/Library/Frameworks/Python.framework/Versions/3.12/lib/python3.12/site-packages/starlette/applications.py", line 112, in __call__
    await self.middleware_stack(scope, receive, send)
  File "/Library/Frameworks/Python.framework/Versions/3.12/lib/python3.12/site-packages/starlette/middleware/errors.py", line 187, in __call__
    raise exc
  File "/Library/Frameworks/Python.framework/Versions/3.12/lib/python3.12/site-packages/starlette/middleware/errors.py", line 165, in __call__
    await self.app(scope, receive, _send)
  File "/Library/Frameworks/Python.framework/Versions/3.12/lib/python3.12/site-packages/starlette/middleware/cors.py", line 85, in __call__
    await self.app(scope, receive, send)
  File "/Library/Frameworks/Python.framework/Versions/3.12/lib/python3.12/site-packages/starlette/middleware/exceptions.py", line 62, in __call__
    await wrap_app_handling_exceptions(self.app, conn)(scope, receive, send)
  File "/Library/Frameworks/Python.framework/Versions/3.12/lib/python3.12/site-packages/starlette/_exception_handler.py", line 53, in wrapped_app
    raise exc
  File "/Library/Frameworks/Python.framework/Versions/3.12/lib/python3.12/site-packages/starlette/_exception_handler.py", line 42, in wrapped_app
    await app(scope, receive, sender)
  File "/Library/Frameworks/Python.framework/Versions/3.12/lib/python3.12/site-packages/starlette/routing.py", line 715, in __call__
    await self.middleware_stack(scope, receive, send)
  File "/Library/Frameworks/Python.framework/Versions/3.12/lib/python3.12/site-packages/starlette/routing.py", line 735, in app
    await route.handle(scope, receive, send)
  File "/Library/Frameworks/Python.framework/Versions/3.12/lib/python3.12/site-packages/starlette/routing.py", line 288, in handle
    await self.app(scope, receive, send)
  File "/Library/Frameworks/Python.framework/Versions/3.12/lib/python3.12/site-packages/starlette/routing.py", line 76, in app
    await wrap_app_handling_exceptions(app, request)(scope, receive, send)
  File "/Library/Frameworks/Python.framework/Versions/3.12/lib/python3.12/site-packages/starlette/_exception_handler.py", line 53, in wrapped_app
    raise exc
  File "/Library/Frameworks/Python.framework/Versions/3.12/lib/python3.12/site-packages/starlette/_exception_handler.py", line 42, in wrapped_app
    await app(scope, receive, sender)
  File "/Library/Frameworks/Python.framework/Versions/3.12/lib/python3.12/site-packages/starlette/routing.py", line 73, in app
    response = await f(request)
               ^^^^^^^^^^^^^^^^
  File "/Library/Frameworks/Python.framework/Versions/3.12/lib/python3.12/site-packages/fastapi/routing.py", line 301, in app
    raw_response = await run_endpoint_function(
                   ^^^^^^^^^^^^^^^^^^^^^^^^^^^^
  File "/Library/Frameworks/Python.framework/Versions/3.12/lib/python3.12/site-packages/fastapi/routing.py", line 214, in run_endpoint_function
    return await run_in_threadpool(dependant.call, **values)
           ^^^^^^^^^^^^^^^^^^^^^^^^^^^^^^^^^^^^^^^^^^^^^^^^^
  File "/Library/Frameworks/Python.framework/Versions/3.12/lib/python3.12/site-packages/starlette/concurrency.py", line 37, in run_in_threadpool
    return await anyio.to_thread.run_sync(func)
           ^^^^^^^^^^^^^^^^^^^^^^^^^^^^^^^^^^^^
  File "/Library/Frameworks/Python.framework/Versions/3.12/lib/python3.12/site-packages/anyio/to_thread.py", line 56, in run_sync
    return await get_async_backend().run_sync_in_worker_thread(
           ^^^^^^^^^^^^^^^^^^^^^^^^^^^^^^^^^^^^^^^^^^^^^^^^^^^^
  File "/Library/Frameworks/Python.framework/Versions/3.12/lib/python3.12/site-packages/anyio/_backends/_asyncio.py", line 2461, in run_sync_in_worker_thread
    return await future
           ^^^^^^^^^^^^
  File "/Library/Frameworks/Python.framework/Versions/3.12/lib/python3.12/asyncio/futures.py", line 291, in __await__
    yield self  # This tells Task to wait for completion.
    ^^^^^^^^^^
  File "/Library/Frameworks/Python.framework/Versions/3.12/lib/python3.12/asyncio/tasks.py", line 385, in __wakeup
    future.result()
  File "/Library/Frameworks/Python.framework/Versions/3.12/lib/python3.12/asyncio/futures.py", line 203, in result
    raise self._exception.with_traceback(self._exception_tb)
  File "/Library/Frameworks/Python.framework/Versions/3.12/lib/python3.12/site-packages/anyio/_backends/_asyncio.py", line 962, in run
    result = context.run(func, *args)
             ^^^^^^^^^^^^^^^^^^^^^^^^
  File "/Library/Frameworks/Python.framework/Versions/3.12/lib/python3.12/site-packages/aktools/core/api.py", line 141, in root
    received_df = eval("ak." + item_id + "()")
                  ^^^^^^^^^^^^^^^^^^^^^^^^^^^^
  File "<string>", line 1, in <module>
  File "/Library/Frameworks/Python.framework/Versions/3.12/lib/python3.12/site-packages/akshare/stock_a/stock_zh_a_spot.py", line 231, in stock_zh_a_spot_em
    return asyncio.run(stock_zh_a_spot_em_async())
           ^^^^^^^^^^^^^^^^^^^^^^^^^^^^^^^^^^^^^^^
  File "/Library/Frameworks/Python.framework/Versions/3.12/lib/python3.12/site-packages/nest_asyncio.py", line 30, in run
    return loop.run_until_complete(task)
           ^^^^^^^^^^^^^^^^^^^^^^^^^^^^^
  File "/Library/Frameworks/Python.framework/Versions/3.12/lib/python3.12/site-packages/nest_asyncio.py", line 98, in run_until_complete
    return f.result()
           ^^^^^^^^^^
  File "/Library/Frameworks/Python.framework/Versions/3.12/lib/python3.12/asyncio/futures.py", line 203, in result
    raise self._exception.with_traceback(self._exception_tb)
  File "/Library/Frameworks/Python.framework/Versions/3.12/lib/python3.12/asyncio/tasks.py", line 314, in __step_run_and_handle_result
    result = coro.send(None)
             ^^^^^^^^^^^^^^^
  File "/Library/Frameworks/Python.framework/Versions/3.12/lib/python3.12/site-packages/akshare/stock_a/stock_zh_a_spot.py", line 217, in stock_zh_a_spot_em_async
    results = await fetch_all_pages_async(url, params)
              ^^^^^^^^^^^^^^^^^^^^^^^^^^^^^^^^^^^^^^^^
  File "/Library/Frameworks/Python.framework/Versions/3.12/lib/python3.12/site-packages/akshare/stock_a/stock_zh_a_spot.py", line 53, in fetch_all_pages_async
    results = await asyncio.gather(*tasks)
              ^^^^^^^^^^^^^^^^^^^^^^^^^^^^
  File "/Library/Frameworks/Python.framework/Versions/3.12/lib/python3.12/asyncio/tasks.py", line 385, in __wakeup
    future.result()
  File "/Library/Frameworks/Python.framework/Versions/3.12/lib/python3.12/asyncio/tasks.py", line 316, in __step_run_and_handle_result
    result = coro.throw(exc)
             ^^^^^^^^^^^^^^^
  File "/Library/Frameworks/Python.framework/Versions/3.12/lib/python3.12/site-packages/akshare/stock_a/stock_zh_a_spot.py", line 21, in fetch_single_page
    async with session.get(url, params=params, ssl=False) as response:
               ^^^^^^^^^^^^^^^^^^^^^^^^^^^^^^^^^^^^^^^^^^
  File "/Library/Frameworks/Python.framework/Versions/3.12/lib/python3.12/site-packages/aiohttp/client.py", line 1425, in __aenter__
    self._resp: _RetType = await self._coro
                           ^^^^^^^^^^^^^^^^
  File "/Library/Frameworks/Python.framework/Versions/3.12/lib/python3.12/site-packages/aiohttp/client.py", line 707, in _request
    raise ConnectionTimeoutError(
aiohttp.client_exceptions.ConnectionTimeoutError: Connection timeout to host https://82.push2.eastmoney.com/api/qt/clist/get
INFO:     127.0.0.1:60081 - "GET /api/public/stock_zh_a_spot_em HTTP/1.1" 200 OK
INFO:     127.0.0.1:60081 - "GET /api/public/stock_zh_a_spot_em HTTP/1.1" 200 OK
INFO:     127.0.0.1:60081 - "GET /api/public/stock_zh_a_spot_em HTTP/1.1" 500 Internal Server Error
ERROR:    Exception in ASGI application
Traceback (most recent call last):
  File "/Library/Frameworks/Python.framework/Versions/3.12/lib/python3.12/site-packages/aiohttp/connector.py", line 1122, in _wrap_create_connection
    return await self._loop.create_connection(*args, **kwargs, sock=sock)
           ^^^^^^^^^^^^^^^^^^^^^^^^^^^^^^^^^^^^^^^^^^^^^^^^^^^^^^^^^^^^^^
  File "/Library/Frameworks/Python.framework/Versions/3.12/lib/python3.12/asyncio/base_events.py", line 1148, in create_connection
    transport, protocol = await self._create_connection_transport(
                          ^^^^^^^^^^^^^^^^^^^^^^^^^^^^^^^^^^^^^^^^
  File "/Library/Frameworks/Python.framework/Versions/3.12/lib/python3.12/asyncio/base_events.py", line 1181, in _create_connection_transport
    await waiter
  File "/Library/Frameworks/Python.framework/Versions/3.12/lib/python3.12/asyncio/futures.py", line 291, in __await__
    yield self  # This tells Task to wait for completion.
    ^^^^^^^^^^
  File "/Library/Frameworks/Python.framework/Versions/3.12/lib/python3.12/asyncio/tasks.py", line 385, in __wakeup
    future.result()
  File "/Library/Frameworks/Python.framework/Versions/3.12/lib/python3.12/asyncio/futures.py", line 198, in result
    raise exc
asyncio.exceptions.CancelledError

The above exception was the direct cause of the following exception:

Traceback (most recent call last):
  File "/Library/Frameworks/Python.framework/Versions/3.12/lib/python3.12/site-packages/aiohttp/client.py", line 703, in _request
    conn = await self._connector.connect(
           ^^^^^^^^^^^^^^^^^^^^^^^^^^^^^^
  File "/Library/Frameworks/Python.framework/Versions/3.12/lib/python3.12/site-packages/aiohttp/connector.py", line 548, in connect
    proto = await self._create_connection(req, traces, timeout)
            ^^^^^^^^^^^^^^^^^^^^^^^^^^^^^^^^^^^^^^^^^^^^^^^^^^^
  File "/Library/Frameworks/Python.framework/Versions/3.12/lib/python3.12/site-packages/aiohttp/connector.py", line 1056, in _create_connection
    _, proto = await self._create_direct_connection(req, traces, timeout)
               ^^^^^^^^^^^^^^^^^^^^^^^^^^^^^^^^^^^^^^^^^^^^^^^^^^^^^^^^^^
  File "/Library/Frameworks/Python.framework/Versions/3.12/lib/python3.12/site-packages/aiohttp/connector.py", line 1400, in _create_direct_connection
    raise last_exc
  File "/Library/Frameworks/Python.framework/Versions/3.12/lib/python3.12/site-packages/aiohttp/connector.py", line 1369, in _create_direct_connection
    transp, proto = await self._wrap_create_connection(
                    ^^^^^^^^^^^^^^^^^^^^^^^^^^^^^^^^^^^
  File "/Library/Frameworks/Python.framework/Versions/3.12/lib/python3.12/site-packages/aiohttp/connector.py", line 1112, in _wrap_create_connection
    async with ceil_timeout(
               ^^^^^^^^^^^^^
  File "/Library/Frameworks/Python.framework/Versions/3.12/lib/python3.12/asyncio/timeouts.py", line 115, in __aexit__
    raise TimeoutError from exc_val
TimeoutError

The above exception was the direct cause of the following exception:

Traceback (most recent call last):
  File "/Library/Frameworks/Python.framework/Versions/3.12/lib/python3.12/site-packages/uvicorn/protocols/http/httptools_impl.py", line 401, in run_asgi
    result = await app(  # type: ignore[func-returns-value]
             ^^^^^^^^^^^^^^^^^^^^^^^^^^^^^^^^^^^^^^^^^^^^^^
  File "/Library/Frameworks/Python.framework/Versions/3.12/lib/python3.12/site-packages/uvicorn/middleware/proxy_headers.py", line 70, in __call__
    return await self.app(scope, receive, send)
           ^^^^^^^^^^^^^^^^^^^^^^^^^^^^^^^^^^^^
  File "/Library/Frameworks/Python.framework/Versions/3.12/lib/python3.12/site-packages/fastapi/applications.py", line 1054, in __call__
    await super().__call__(scope, receive, send)
  File "/Library/Frameworks/Python.framework/Versions/3.12/lib/python3.12/site-packages/starlette/applications.py", line 112, in __call__
    await self.middleware_stack(scope, receive, send)
  File "/Library/Frameworks/Python.framework/Versions/3.12/lib/python3.12/site-packages/starlette/middleware/errors.py", line 187, in __call__
    raise exc
  File "/Library/Frameworks/Python.framework/Versions/3.12/lib/python3.12/site-packages/starlette/middleware/errors.py", line 165, in __call__
    await self.app(scope, receive, _send)
  File "/Library/Frameworks/Python.framework/Versions/3.12/lib/python3.12/site-packages/starlette/middleware/cors.py", line 85, in __call__
    await self.app(scope, receive, send)
  File "/Library/Frameworks/Python.framework/Versions/3.12/lib/python3.12/site-packages/starlette/middleware/exceptions.py", line 62, in __call__
    await wrap_app_handling_exceptions(self.app, conn)(scope, receive, send)
  File "/Library/Frameworks/Python.framework/Versions/3.12/lib/python3.12/site-packages/starlette/_exception_handler.py", line 53, in wrapped_app
    raise exc
  File "/Library/Frameworks/Python.framework/Versions/3.12/lib/python3.12/site-packages/starlette/_exception_handler.py", line 42, in wrapped_app
    await app(scope, receive, sender)
  File "/Library/Frameworks/Python.framework/Versions/3.12/lib/python3.12/site-packages/starlette/routing.py", line 715, in __call__
    await self.middleware_stack(scope, receive, send)
  File "/Library/Frameworks/Python.framework/Versions/3.12/lib/python3.12/site-packages/starlette/routing.py", line 735, in app
    await route.handle(scope, receive, send)
  File "/Library/Frameworks/Python.framework/Versions/3.12/lib/python3.12/site-packages/starlette/routing.py", line 288, in handle
    await self.app(scope, receive, send)
  File "/Library/Frameworks/Python.framework/Versions/3.12/lib/python3.12/site-packages/starlette/routing.py", line 76, in app
    await wrap_app_handling_exceptions(app, request)(scope, receive, send)
  File "/Library/Frameworks/Python.framework/Versions/3.12/lib/python3.12/site-packages/starlette/_exception_handler.py", line 53, in wrapped_app
    raise exc
  File "/Library/Frameworks/Python.framework/Versions/3.12/lib/python3.12/site-packages/starlette/_exception_handler.py", line 42, in wrapped_app
    await app(scope, receive, sender)
  File "/Library/Frameworks/Python.framework/Versions/3.12/lib/python3.12/site-packages/starlette/routing.py", line 73, in app
    response = await f(request)
               ^^^^^^^^^^^^^^^^
  File "/Library/Frameworks/Python.framework/Versions/3.12/lib/python3.12/site-packages/fastapi/routing.py", line 301, in app
    raw_response = await run_endpoint_function(
                   ^^^^^^^^^^^^^^^^^^^^^^^^^^^^
  File "/Library/Frameworks/Python.framework/Versions/3.12/lib/python3.12/site-packages/fastapi/routing.py", line 214, in run_endpoint_function
    return await run_in_threadpool(dependant.call, **values)
           ^^^^^^^^^^^^^^^^^^^^^^^^^^^^^^^^^^^^^^^^^^^^^^^^^
  File "/Library/Frameworks/Python.framework/Versions/3.12/lib/python3.12/site-packages/starlette/concurrency.py", line 37, in run_in_threadpool
    return await anyio.to_thread.run_sync(func)
           ^^^^^^^^^^^^^^^^^^^^^^^^^^^^^^^^^^^^
  File "/Library/Frameworks/Python.framework/Versions/3.12/lib/python3.12/site-packages/anyio/to_thread.py", line 56, in run_sync
    return await get_async_backend().run_sync_in_worker_thread(
           ^^^^^^^^^^^^^^^^^^^^^^^^^^^^^^^^^^^^^^^^^^^^^^^^^^^^
  File "/Library/Frameworks/Python.framework/Versions/3.12/lib/python3.12/site-packages/anyio/_backends/_asyncio.py", line 2461, in run_sync_in_worker_thread
    return await future
           ^^^^^^^^^^^^
  File "/Library/Frameworks/Python.framework/Versions/3.12/lib/python3.12/asyncio/futures.py", line 291, in __await__
    yield self  # This tells Task to wait for completion.
    ^^^^^^^^^^
  File "/Library/Frameworks/Python.framework/Versions/3.12/lib/python3.12/asyncio/tasks.py", line 385, in __wakeup
    future.result()
  File "/Library/Frameworks/Python.framework/Versions/3.12/lib/python3.12/asyncio/futures.py", line 203, in result
    raise self._exception.with_traceback(self._exception_tb)
  File "/Library/Frameworks/Python.framework/Versions/3.12/lib/python3.12/site-packages/anyio/_backends/_asyncio.py", line 962, in run
    result = context.run(func, *args)
             ^^^^^^^^^^^^^^^^^^^^^^^^
  File "/Library/Frameworks/Python.framework/Versions/3.12/lib/python3.12/site-packages/aktools/core/api.py", line 141, in root
    received_df = eval("ak." + item_id + "()")
                  ^^^^^^^^^^^^^^^^^^^^^^^^^^^^
  File "<string>", line 1, in <module>
  File "/Library/Frameworks/Python.framework/Versions/3.12/lib/python3.12/site-packages/akshare/stock_a/stock_zh_a_spot.py", line 231, in stock_zh_a_spot_em
    return asyncio.run(stock_zh_a_spot_em_async())
           ^^^^^^^^^^^^^^^^^^^^^^^^^^^^^^^^^^^^^^^
  File "/Library/Frameworks/Python.framework/Versions/3.12/lib/python3.12/site-packages/nest_asyncio.py", line 30, in run
    return loop.run_until_complete(task)
           ^^^^^^^^^^^^^^^^^^^^^^^^^^^^^
  File "/Library/Frameworks/Python.framework/Versions/3.12/lib/python3.12/site-packages/nest_asyncio.py", line 98, in run_until_complete
    return f.result()
           ^^^^^^^^^^
  File "/Library/Frameworks/Python.framework/Versions/3.12/lib/python3.12/asyncio/futures.py", line 203, in result
    raise self._exception.with_traceback(self._exception_tb)
  File "/Library/Frameworks/Python.framework/Versions/3.12/lib/python3.12/asyncio/tasks.py", line 314, in __step_run_and_handle_result
    result = coro.send(None)
             ^^^^^^^^^^^^^^^
  File "/Library/Frameworks/Python.framework/Versions/3.12/lib/python3.12/site-packages/akshare/stock_a/stock_zh_a_spot.py", line 217, in stock_zh_a_spot_em_async
    results = await fetch_all_pages_async(url, params)
              ^^^^^^^^^^^^^^^^^^^^^^^^^^^^^^^^^^^^^^^^
  File "/Library/Frameworks/Python.framework/Versions/3.12/lib/python3.12/site-packages/akshare/stock_a/stock_zh_a_spot.py", line 53, in fetch_all_pages_async
    results = await asyncio.gather(*tasks)
              ^^^^^^^^^^^^^^^^^^^^^^^^^^^^
  File "/Library/Frameworks/Python.framework/Versions/3.12/lib/python3.12/asyncio/tasks.py", line 385, in __wakeup
    future.result()
  File "/Library/Frameworks/Python.framework/Versions/3.12/lib/python3.12/asyncio/tasks.py", line 316, in __step_run_and_handle_result
    result = coro.throw(exc)
             ^^^^^^^^^^^^^^^
  File "/Library/Frameworks/Python.framework/Versions/3.12/lib/python3.12/site-packages/akshare/stock_a/stock_zh_a_spot.py", line 21, in fetch_single_page
    async with session.get(url, params=params, ssl=False) as response:
               ^^^^^^^^^^^^^^^^^^^^^^^^^^^^^^^^^^^^^^^^^^
  File "/Library/Frameworks/Python.framework/Versions/3.12/lib/python3.12/site-packages/aiohttp/client.py", line 1425, in __aenter__
    self._resp: _RetType = await self._coro
                           ^^^^^^^^^^^^^^^^
  File "/Library/Frameworks/Python.framework/Versions/3.12/lib/python3.12/site-packages/aiohttp/client.py", line 707, in _request
    raise ConnectionTimeoutError(
aiohttp.client_exceptions.ConnectionTimeoutError: Connection timeout to host https://82.push2.eastmoney.com/api/qt/clist/get
INFO:     127.0.0.1:60423 - "GET /api/public/stock_zh_a_spot_em HTTP/1.1" 500 Internal Server Error
ERROR:    Exception in ASGI application
Traceback (most recent call last):
  File "/Library/Frameworks/Python.framework/Versions/3.12/lib/python3.12/site-packages/aiohttp/connector.py", line 1122, in _wrap_create_connection
    return await self._loop.create_connection(*args, **kwargs, sock=sock)
           ^^^^^^^^^^^^^^^^^^^^^^^^^^^^^^^^^^^^^^^^^^^^^^^^^^^^^^^^^^^^^^
  File "/Library/Frameworks/Python.framework/Versions/3.12/lib/python3.12/asyncio/base_events.py", line 1148, in create_connection
    transport, protocol = await self._create_connection_transport(
                          ^^^^^^^^^^^^^^^^^^^^^^^^^^^^^^^^^^^^^^^^
  File "/Library/Frameworks/Python.framework/Versions/3.12/lib/python3.12/asyncio/base_events.py", line 1181, in _create_connection_transport
    await waiter
  File "/Library/Frameworks/Python.framework/Versions/3.12/lib/python3.12/asyncio/futures.py", line 291, in __await__
    yield self  # This tells Task to wait for completion.
    ^^^^^^^^^^
  File "/Library/Frameworks/Python.framework/Versions/3.12/lib/python3.12/asyncio/tasks.py", line 385, in __wakeup
    future.result()
  File "/Library/Frameworks/Python.framework/Versions/3.12/lib/python3.12/asyncio/futures.py", line 198, in result
    raise exc
asyncio.exceptions.CancelledError

The above exception was the direct cause of the following exception:

Traceback (most recent call last):
  File "/Library/Frameworks/Python.framework/Versions/3.12/lib/python3.12/site-packages/aiohttp/client.py", line 703, in _request
    conn = await self._connector.connect(
           ^^^^^^^^^^^^^^^^^^^^^^^^^^^^^^
  File "/Library/Frameworks/Python.framework/Versions/3.12/lib/python3.12/site-packages/aiohttp/connector.py", line 548, in connect
    proto = await self._create_connection(req, traces, timeout)
            ^^^^^^^^^^^^^^^^^^^^^^^^^^^^^^^^^^^^^^^^^^^^^^^^^^^
  File "/Library/Frameworks/Python.framework/Versions/3.12/lib/python3.12/site-packages/aiohttp/connector.py", line 1056, in _create_connection
    _, proto = await self._create_direct_connection(req, traces, timeout)
               ^^^^^^^^^^^^^^^^^^^^^^^^^^^^^^^^^^^^^^^^^^^^^^^^^^^^^^^^^^
  File "/Library/Frameworks/Python.framework/Versions/3.12/lib/python3.12/site-packages/aiohttp/connector.py", line 1400, in _create_direct_connection
    raise last_exc
  File "/Library/Frameworks/Python.framework/Versions/3.12/lib/python3.12/site-packages/aiohttp/connector.py", line 1369, in _create_direct_connection
    transp, proto = await self._wrap_create_connection(
                    ^^^^^^^^^^^^^^^^^^^^^^^^^^^^^^^^^^^
  File "/Library/Frameworks/Python.framework/Versions/3.12/lib/python3.12/site-packages/aiohttp/connector.py", line 1112, in _wrap_create_connection
    async with ceil_timeout(
               ^^^^^^^^^^^^^
  File "/Library/Frameworks/Python.framework/Versions/3.12/lib/python3.12/asyncio/timeouts.py", line 115, in __aexit__
    raise TimeoutError from exc_val
TimeoutError

The above exception was the direct cause of the following exception:

Traceback (most recent call last):
  File "/Library/Frameworks/Python.framework/Versions/3.12/lib/python3.12/site-packages/uvicorn/protocols/http/httptools_impl.py", line 401, in run_asgi
    result = await app(  # type: ignore[func-returns-value]
             ^^^^^^^^^^^^^^^^^^^^^^^^^^^^^^^^^^^^^^^^^^^^^^
  File "/Library/Frameworks/Python.framework/Versions/3.12/lib/python3.12/site-packages/uvicorn/middleware/proxy_headers.py", line 70, in __call__
    return await self.app(scope, receive, send)
           ^^^^^^^^^^^^^^^^^^^^^^^^^^^^^^^^^^^^
  File "/Library/Frameworks/Python.framework/Versions/3.12/lib/python3.12/site-packages/fastapi/applications.py", line 1054, in __call__
    await super().__call__(scope, receive, send)
  File "/Library/Frameworks/Python.framework/Versions/3.12/lib/python3.12/site-packages/starlette/applications.py", line 112, in __call__
    await self.middleware_stack(scope, receive, send)
  File "/Library/Frameworks/Python.framework/Versions/3.12/lib/python3.12/site-packages/starlette/middleware/errors.py", line 187, in __call__
    raise exc
  File "/Library/Frameworks/Python.framework/Versions/3.12/lib/python3.12/site-packages/starlette/middleware/errors.py", line 165, in __call__
    await self.app(scope, receive, _send)
  File "/Library/Frameworks/Python.framework/Versions/3.12/lib/python3.12/site-packages/starlette/middleware/cors.py", line 85, in __call__
    await self.app(scope, receive, send)
  File "/Library/Frameworks/Python.framework/Versions/3.12/lib/python3.12/site-packages/starlette/middleware/exceptions.py", line 62, in __call__
    await wrap_app_handling_exceptions(self.app, conn)(scope, receive, send)
  File "/Library/Frameworks/Python.framework/Versions/3.12/lib/python3.12/site-packages/starlette/_exception_handler.py", line 53, in wrapped_app
    raise exc
  File "/Library/Frameworks/Python.framework/Versions/3.12/lib/python3.12/site-packages/starlette/_exception_handler.py", line 42, in wrapped_app
    await app(scope, receive, sender)
  File "/Library/Frameworks/Python.framework/Versions/3.12/lib/python3.12/site-packages/starlette/routing.py", line 715, in __call__
    await self.middleware_stack(scope, receive, send)
  File "/Library/Frameworks/Python.framework/Versions/3.12/lib/python3.12/site-packages/starlette/routing.py", line 735, in app
    await route.handle(scope, receive, send)
  File "/Library/Frameworks/Python.framework/Versions/3.12/lib/python3.12/site-packages/starlette/routing.py", line 288, in handle
    await self.app(scope, receive, send)
  File "/Library/Frameworks/Python.framework/Versions/3.12/lib/python3.12/site-packages/starlette/routing.py", line 76, in app
    await wrap_app_handling_exceptions(app, request)(scope, receive, send)
  File "/Library/Frameworks/Python.framework/Versions/3.12/lib/python3.12/site-packages/starlette/_exception_handler.py", line 53, in wrapped_app
    raise exc
  File "/Library/Frameworks/Python.framework/Versions/3.12/lib/python3.12/site-packages/starlette/_exception_handler.py", line 42, in wrapped_app
    await app(scope, receive, sender)
  File "/Library/Frameworks/Python.framework/Versions/3.12/lib/python3.12/site-packages/starlette/routing.py", line 73, in app
    response = await f(request)
               ^^^^^^^^^^^^^^^^
  File "/Library/Frameworks/Python.framework/Versions/3.12/lib/python3.12/site-packages/fastapi/routing.py", line 301, in app
    raw_response = await run_endpoint_function(
                   ^^^^^^^^^^^^^^^^^^^^^^^^^^^^
  File "/Library/Frameworks/Python.framework/Versions/3.12/lib/python3.12/site-packages/fastapi/routing.py", line 214, in run_endpoint_function
    return await run_in_threadpool(dependant.call, **values)
           ^^^^^^^^^^^^^^^^^^^^^^^^^^^^^^^^^^^^^^^^^^^^^^^^^
  File "/Library/Frameworks/Python.framework/Versions/3.12/lib/python3.12/site-packages/starlette/concurrency.py", line 37, in run_in_threadpool
    return await anyio.to_thread.run_sync(func)
           ^^^^^^^^^^^^^^^^^^^^^^^^^^^^^^^^^^^^
  File "/Library/Frameworks/Python.framework/Versions/3.12/lib/python3.12/site-packages/anyio/to_thread.py", line 56, in run_sync
    return await get_async_backend().run_sync_in_worker_thread(
           ^^^^^^^^^^^^^^^^^^^^^^^^^^^^^^^^^^^^^^^^^^^^^^^^^^^^
  File "/Library/Frameworks/Python.framework/Versions/3.12/lib/python3.12/site-packages/anyio/_backends/_asyncio.py", line 2461, in run_sync_in_worker_thread
    return await future
           ^^^^^^^^^^^^
  File "/Library/Frameworks/Python.framework/Versions/3.12/lib/python3.12/asyncio/futures.py", line 291, in __await__
    yield self  # This tells Task to wait for completion.
    ^^^^^^^^^^
  File "/Library/Frameworks/Python.framework/Versions/3.12/lib/python3.12/asyncio/tasks.py", line 385, in __wakeup
    future.result()
  File "/Library/Frameworks/Python.framework/Versions/3.12/lib/python3.12/asyncio/futures.py", line 203, in result
    raise self._exception.with_traceback(self._exception_tb)
  File "/Library/Frameworks/Python.framework/Versions/3.12/lib/python3.12/site-packages/anyio/_backends/_asyncio.py", line 962, in run
    result = context.run(func, *args)
             ^^^^^^^^^^^^^^^^^^^^^^^^
  File "/Library/Frameworks/Python.framework/Versions/3.12/lib/python3.12/site-packages/aktools/core/api.py", line 141, in root
    received_df = eval("ak." + item_id + "()")
                  ^^^^^^^^^^^^^^^^^^^^^^^^^^^^
  File "<string>", line 1, in <module>
  File "/Library/Frameworks/Python.framework/Versions/3.12/lib/python3.12/site-packages/akshare/stock_a/stock_zh_a_spot.py", line 231, in stock_zh_a_spot_em
    return asyncio.run(stock_zh_a_spot_em_async())
           ^^^^^^^^^^^^^^^^^^^^^^^^^^^^^^^^^^^^^^^
  File "/Library/Frameworks/Python.framework/Versions/3.12/lib/python3.12/site-packages/nest_asyncio.py", line 30, in run
    return loop.run_until_complete(task)
           ^^^^^^^^^^^^^^^^^^^^^^^^^^^^^
  File "/Library/Frameworks/Python.framework/Versions/3.12/lib/python3.12/site-packages/nest_asyncio.py", line 98, in run_until_complete
    return f.result()
           ^^^^^^^^^^
  File "/Library/Frameworks/Python.framework/Versions/3.12/lib/python3.12/asyncio/futures.py", line 203, in result
    raise self._exception.with_traceback(self._exception_tb)
  File "/Library/Frameworks/Python.framework/Versions/3.12/lib/python3.12/asyncio/tasks.py", line 314, in __step_run_and_handle_result
    result = coro.send(None)
             ^^^^^^^^^^^^^^^
  File "/Library/Frameworks/Python.framework/Versions/3.12/lib/python3.12/site-packages/akshare/stock_a/stock_zh_a_spot.py", line 217, in stock_zh_a_spot_em_async
    results = await fetch_all_pages_async(url, params)
              ^^^^^^^^^^^^^^^^^^^^^^^^^^^^^^^^^^^^^^^^
  File "/Library/Frameworks/Python.framework/Versions/3.12/lib/python3.12/site-packages/akshare/stock_a/stock_zh_a_spot.py", line 53, in fetch_all_pages_async
    results = await asyncio.gather(*tasks)
              ^^^^^^^^^^^^^^^^^^^^^^^^^^^^
  File "/Library/Frameworks/Python.framework/Versions/3.12/lib/python3.12/asyncio/tasks.py", line 385, in __wakeup
    future.result()
  File "/Library/Frameworks/Python.framework/Versions/3.12/lib/python3.12/asyncio/tasks.py", line 316, in __step_run_and_handle_result
    result = coro.throw(exc)
             ^^^^^^^^^^^^^^^
  File "/Library/Frameworks/Python.framework/Versions/3.12/lib/python3.12/site-packages/akshare/stock_a/stock_zh_a_spot.py", line 21, in fetch_single_page
    async with session.get(url, params=params, ssl=False) as response:
               ^^^^^^^^^^^^^^^^^^^^^^^^^^^^^^^^^^^^^^^^^^
  File "/Library/Frameworks/Python.framework/Versions/3.12/lib/python3.12/site-packages/aiohttp/client.py", line 1425, in __aenter__
    self._resp: _RetType = await self._coro
                           ^^^^^^^^^^^^^^^^
  File "/Library/Frameworks/Python.framework/Versions/3.12/lib/python3.12/site-packages/aiohttp/client.py", line 707, in _request
    raise ConnectionTimeoutError(
aiohttp.client_exceptions.ConnectionTimeoutError: Connection timeout to host https://82.push2.eastmoney.com/api/qt/clist/get
ERROR:    Exception in ASGI application
Traceback (most recent call last):
  File "/Library/Frameworks/Python.framework/Versions/3.12/lib/python3.12/site-packages/aiohttp/connector.py", line 1122, in _wrap_create_connection
    return await self._loop.create_connection(*args, **kwargs, sock=sock)
           ^^^^^^^^^^^^^^^^^^^^^^^^^^^^^^^^^^^^^^^^^^^^^^^^^^^^^^^^^^^^^^
  File "/Library/Frameworks/Python.framework/Versions/3.12/lib/python3.12/asyncio/base_events.py", line 1148, in create_connection
    transport, protocol = await self._create_connection_transport(
                          ^^^^^^^^^^^^^^^^^^^^^^^^^^^^^^^^^^^^^^^^
  File "/Library/Frameworks/Python.framework/Versions/3.12/lib/python3.12/asyncio/base_events.py", line 1181, in _create_connection_transport
    await waiter
  File "/Library/Frameworks/Python.framework/Versions/3.12/lib/python3.12/asyncio/futures.py", line 291, in __await__
    yield self  # This tells Task to wait for completion.
    ^^^^^^^^^^
  File "/Library/Frameworks/Python.framework/Versions/3.12/lib/python3.12/asyncio/tasks.py", line 385, in __wakeup
    future.result()
  File "/Library/Frameworks/Python.framework/Versions/3.12/lib/python3.12/asyncio/futures.py", line 198, in result
    raise exc
asyncio.exceptions.CancelledError

The above exception was the direct cause of the following exception:

Traceback (most recent call last):
  File "/Library/Frameworks/Python.framework/Versions/3.12/lib/python3.12/site-packages/aiohttp/client.py", line 703, in _request
    conn = await self._connector.connect(
           ^^^^^^^^^^^^^^^^^^^^^^^^^^^^^^
  File "/Library/Frameworks/Python.framework/Versions/3.12/lib/python3.12/site-packages/aiohttp/connector.py", line 548, in connect
    proto = await self._create_connection(req, traces, timeout)
            ^^^^^^^^^^^^^^^^^^^^^^^^^^^^^^^^^^^^^^^^^^^^^^^^^^^
  File "/Library/Frameworks/Python.framework/Versions/3.12/lib/python3.12/site-packages/aiohttp/connector.py", line 1056, in _create_connection
    _, proto = await self._create_direct_connection(req, traces, timeout)
               ^^^^^^^^^^^^^^^^^^^^^^^^^^^^^^^^^^^^^^^^^^^^^^^^^^^^^^^^^^
  File "/Library/Frameworks/Python.framework/Versions/3.12/lib/python3.12/site-packages/aiohttp/connector.py", line 1400, in _create_direct_connection
    raise last_exc
  File "/Library/Frameworks/Python.framework/Versions/3.12/lib/python3.12/site-packages/aiohttp/connector.py", line 1369, in _create_direct_connection
    transp, proto = await self._wrap_create_connection(
                    ^^^^^^^^^^^^^^^^^^^^^^^^^^^^^^^^^^^
  File "/Library/Frameworks/Python.framework/Versions/3.12/lib/python3.12/site-packages/aiohttp/connector.py", line 1112, in _wrap_create_connection
    async with ceil_timeout(
               ^^^^^^^^^^^^^
  File "/Library/Frameworks/Python.framework/Versions/3.12/lib/python3.12/asyncio/timeouts.py", line 115, in __aexit__
    raise TimeoutError from exc_val
TimeoutError

The above exception was the direct cause of the following exception:

Traceback (most recent call last):
  File "/Library/Frameworks/Python.framework/Versions/3.12/lib/python3.12/site-packages/uvicorn/protocols/http/httptools_impl.py", line 401, in run_asgi
    result = await app(  # type: ignore[func-returns-value]
             ^^^^^^^^^^^^^^^^^^^^^^^^^^^^^^^^^^^^^^^^^^^^^^
  File "/Library/Frameworks/Python.framework/Versions/3.12/lib/python3.12/site-packages/uvicorn/middleware/proxy_headers.py", line 70, in __call__
    return await self.app(scope, receive, send)
           ^^^^^^^^^^^^^^^^^^^^^^^^^^^^^^^^^^^^
  File "/Library/Frameworks/Python.framework/Versions/3.12/lib/python3.12/site-packages/fastapi/applications.py", line 1054, in __call__
    await super().__call__(scope, receive, send)
  File "/Library/Frameworks/Python.framework/Versions/3.12/lib/python3.12/site-packages/starlette/applications.py", line 112, in __call__
    await self.middleware_stack(scope, receive, send)
  File "/Library/Frameworks/Python.framework/Versions/3.12/lib/python3.12/site-packages/starlette/middleware/errors.py", line 187, in __call__
    raise exc
  File "/Library/Frameworks/Python.framework/Versions/3.12/lib/python3.12/site-packages/starlette/middleware/errors.py", line 165, in __call__
    await self.app(scope, receive, _send)
  File "/Library/Frameworks/Python.framework/Versions/3.12/lib/python3.12/site-packages/starlette/middleware/cors.py", line 85, in __call__
    await self.app(scope, receive, send)
  File "/Library/Frameworks/Python.framework/Versions/3.12/lib/python3.12/site-packages/starlette/middleware/exceptions.py", line 62, in __call__
    await wrap_app_handling_exceptions(self.app, conn)(scope, receive, send)
  File "/Library/Frameworks/Python.framework/Versions/3.12/lib/python3.12/site-packages/starlette/_exception_handler.py", line 53, in wrapped_app
    raise exc
  File "/Library/Frameworks/Python.framework/Versions/3.12/lib/python3.12/site-packages/starlette/_exception_handler.py", line 42, in wrapped_app
    await app(scope, receive, sender)
  File "/Library/Frameworks/Python.framework/Versions/3.12/lib/python3.12/site-packages/starlette/routing.py", line 715, in __call__
    await self.middleware_stack(scope, receive, send)
  File "/Library/Frameworks/Python.framework/Versions/3.12/lib/python3.12/site-packages/starlette/routing.py", line 735, in app
    await route.handle(scope, receive, send)
  File "/Library/Frameworks/Python.framework/Versions/3.12/lib/python3.12/site-packages/starlette/routing.py", line 288, in handle
    await self.app(scope, receive, send)
  File "/Library/Frameworks/Python.framework/Versions/3.12/lib/python3.12/site-packages/starlette/routing.py", line 76, in app
    await wrap_app_handling_exceptions(app, request)(scope, receive, send)
  File "/Library/Frameworks/Python.framework/Versions/3.12/lib/python3.12/site-packages/starlette/_exception_handler.py", line 53, in wrapped_app
    raise exc
  File "/Library/Frameworks/Python.framework/Versions/3.12/lib/python3.12/site-packages/starlette/_exception_handler.py", line 42, in wrapped_app
    await app(scope, receive, sender)
  File "/Library/Frameworks/Python.framework/Versions/3.12/lib/python3.12/site-packages/starlette/routing.py", line 73, in app
    response = await f(request)
               ^^^^^^^^^^^^^^^^
  File "/Library/Frameworks/Python.framework/Versions/3.12/lib/python3.12/site-packages/fastapi/routing.py", line 301, in app
    raw_response = await run_endpoint_function(
                   ^^^^^^^^^^^^^^^^^^^^^^^^^^^^
  File "/Library/Frameworks/Python.framework/Versions/3.12/lib/python3.12/site-packages/fastapi/routing.py", line 214, in run_endpoint_function
    return await run_in_threadpool(dependant.call, **values)
           ^^^^^^^^^^^^^^^^^^^^^^^^^^^^^^^^^^^^^^^^^^^^^^^^^
  File "/Library/Frameworks/Python.framework/Versions/3.12/lib/python3.12/site-packages/starlette/concurrency.py", line 37, in run_in_threadpool
    return await anyio.to_thread.run_sync(func)
           ^^^^^^^^^^^^^^^^^^^^^^^^^^^^^^^^^^^^
  File "/Library/Frameworks/Python.framework/Versions/3.12/lib/python3.12/site-packages/anyio/to_thread.py", line 56, in run_sync
    return await get_async_backend().run_sync_in_worker_thread(
           ^^^^^^^^^^^^^^^^^^^^^^^^^^^^^^^^^^^^^^^^^^^^^^^^^^^^
  File "/Library/Frameworks/Python.framework/Versions/3.12/lib/python3.12/site-packages/anyio/_backends/_asyncio.py", line 2461, in run_sync_in_worker_thread
    return await future
           ^^^^^^^^^^^^
  File "/Library/Frameworks/Python.framework/Versions/3.12/lib/python3.12/asyncio/futures.py", line 291, in __await__
    yield self  # This tells Task to wait for completion.
    ^^^^^^^^^^
  File "/Library/Frameworks/Python.framework/Versions/3.12/lib/python3.12/asyncio/tasks.py", line 385, in __wakeup
    future.result()
  File "/Library/Frameworks/Python.framework/Versions/3.12/lib/python3.12/asyncio/futures.py", line 203, in result
    raise self._exception.with_traceback(self._exception_tb)
  File "/Library/Frameworks/Python.framework/Versions/3.12/lib/python3.12/site-packages/anyio/_backends/_asyncio.py", line 962, in run
    result = context.run(func, *args)
             ^^^^^^^^^^^^^^^^^^^^^^^^
  File "/Library/Frameworks/Python.framework/Versions/3.12/lib/python3.12/site-packages/aktools/core/api.py", line 141, in root
    received_df = eval("ak." + item_id + "()")
                  ^^^^^^^^^^^^^^^^^^^^^^^^^^^^
  File "<string>", line 1, in <module>
  File "/Library/Frameworks/Python.framework/Versions/3.12/lib/python3.12/site-packages/akshare/stock_a/stock_zh_a_spot.py", line 231, in stock_zh_a_spot_em
    return asyncio.run(stock_zh_a_spot_em_async())
           ^^^^^^^^^^^^^^^^^^^^^^^^^^^^^^^^^^^^^^^
  File "/Library/Frameworks/Python.framework/Versions/3.12/lib/python3.12/site-packages/nest_asyncio.py", line 30, in run
    return loop.run_until_complete(task)
           ^^^^^^^^^^^^^^^^^^^^^^^^^^^^^
  File "/Library/Frameworks/Python.framework/Versions/3.12/lib/python3.12/site-packages/nest_asyncio.py", line 98, in run_until_complete
    return f.result()
           ^^^^^^^^^^
  File "/Library/Frameworks/Python.framework/Versions/3.12/lib/python3.12/asyncio/futures.py", line 203, in result
    raise self._exception.with_traceback(self._exception_tb)
  File "/Library/Frameworks/Python.framework/Versions/3.12/lib/python3.12/asyncio/tasks.py", line 314, in __step_run_and_handle_result
    result = coro.send(None)
             ^^^^^^^^^^^^^^^
  File "/Library/Frameworks/Python.framework/Versions/3.12/lib/python3.12/site-packages/akshare/stock_a/stock_zh_a_spot.py", line 217, in stock_zh_a_spot_em_async
    results = await fetch_all_pages_async(url, params)
              ^^^^^^^^^^^^^^^^^^^^^^^^^^^^^^^^^^^^^^^^
  File "/Library/Frameworks/Python.framework/Versions/3.12/lib/python3.12/site-packages/akshare/stock_a/stock_zh_a_spot.py", line 53, in fetch_all_pages_async
    results = await asyncio.gather(*tasks)
              ^^^^^^^^^^^^^^^^^^^^^^^^^^^^
  File "/Library/Frameworks/Python.framework/Versions/3.12/lib/python3.12/asyncio/tasks.py", line 385, in __wakeup
    future.result()
  File "/Library/Frameworks/Python.framework/Versions/3.12/lib/python3.12/asyncio/tasks.py", line 316, in __step_run_and_handle_result
    result = coro.throw(exc)
             ^^^^^^^^^^^^^^^
  File "/Library/Frameworks/Python.framework/Versions/3.12/lib/python3.12/site-packages/akshare/stock_a/stock_zh_a_spot.py", line 21, in fetch_single_page
    async with session.get(url, params=params, ssl=False) as response:
               ^^^^^^^^^^^^^^^^^^^^^^^^^^^^^^^^^^^^^^^^^^
  File "/Library/Frameworks/Python.framework/Versions/3.12/lib/python3.12/site-packages/aiohttp/client.py", line 1425, in __aenter__
    self._resp: _RetType = await self._coro
                           ^^^^^^^^^^^^^^^^
  File "/Library/Frameworks/Python.framework/Versions/3.12/lib/python3.12/site-packages/aiohttp/client.py", line 707, in _request
    raise ConnectionTimeoutError(
aiohttp.client_exceptions.ConnectionTimeoutError: Connection timeout to host https://82.push2.eastmoney.com/api/qt/clist/get
INFO:     127.0.0.1:61671 - "GET /api/public/stock_zh_a_spot_em HTTP/1.1" 200 OK
INFO:     127.0.0.1:61671 - "GET /api/public/stock_zh_a_spot_em HTTP/1.1" 500 Internal Server Error
ERROR:    Exception in ASGI application
Traceback (most recent call last):
  File "/Library/Frameworks/Python.framework/Versions/3.12/lib/python3.12/site-packages/aiohttp/connector.py", line 1115, in _wrap_create_connection
    sock = await aiohappyeyeballs.start_connection(
           ^^^^^^^^^^^^^^^^^^^^^^^^^^^^^^^^^^^^^^^^
  File "/Library/Frameworks/Python.framework/Versions/3.12/lib/python3.12/site-packages/aiohappyeyeballs/impl.py", line 71, in start_connection
    sock = await _connect_sock(
           ^^^^^^^^^^^^^^^^^^^^
  File "/Library/Frameworks/Python.framework/Versions/3.12/lib/python3.12/site-packages/aiohappyeyeballs/impl.py", line 163, in _connect_sock
    await loop.sock_connect(sock, address)
  File "/Library/Frameworks/Python.framework/Versions/3.12/lib/python3.12/asyncio/selector_events.py", line 651, in sock_connect
    return await fut
           ^^^^^^^^^
  File "/Library/Frameworks/Python.framework/Versions/3.12/lib/python3.12/asyncio/futures.py", line 291, in __await__
    yield self  # This tells Task to wait for completion.
    ^^^^^^^^^^
  File "/Library/Frameworks/Python.framework/Versions/3.12/lib/python3.12/asyncio/tasks.py", line 385, in __wakeup
    future.result()
  File "/Library/Frameworks/Python.framework/Versions/3.12/lib/python3.12/asyncio/futures.py", line 198, in result
    raise exc
asyncio.exceptions.CancelledError

The above exception was the direct cause of the following exception:

Traceback (most recent call last):
  File "/Library/Frameworks/Python.framework/Versions/3.12/lib/python3.12/site-packages/aiohttp/client.py", line 703, in _request
    conn = await self._connector.connect(
           ^^^^^^^^^^^^^^^^^^^^^^^^^^^^^^
  File "/Library/Frameworks/Python.framework/Versions/3.12/lib/python3.12/site-packages/aiohttp/connector.py", line 548, in connect
    proto = await self._create_connection(req, traces, timeout)
            ^^^^^^^^^^^^^^^^^^^^^^^^^^^^^^^^^^^^^^^^^^^^^^^^^^^
  File "/Library/Frameworks/Python.framework/Versions/3.12/lib/python3.12/site-packages/aiohttp/connector.py", line 1056, in _create_connection
    _, proto = await self._create_direct_connection(req, traces, timeout)
               ^^^^^^^^^^^^^^^^^^^^^^^^^^^^^^^^^^^^^^^^^^^^^^^^^^^^^^^^^^
  File "/Library/Frameworks/Python.framework/Versions/3.12/lib/python3.12/site-packages/aiohttp/connector.py", line 1400, in _create_direct_connection
    raise last_exc
  File "/Library/Frameworks/Python.framework/Versions/3.12/lib/python3.12/site-packages/aiohttp/connector.py", line 1369, in _create_direct_connection
    transp, proto = await self._wrap_create_connection(
                    ^^^^^^^^^^^^^^^^^^^^^^^^^^^^^^^^^^^
  File "/Library/Frameworks/Python.framework/Versions/3.12/lib/python3.12/site-packages/aiohttp/connector.py", line 1112, in _wrap_create_connection
    async with ceil_timeout(
               ^^^^^^^^^^^^^
  File "/Library/Frameworks/Python.framework/Versions/3.12/lib/python3.12/asyncio/timeouts.py", line 115, in __aexit__
    raise TimeoutError from exc_val
TimeoutError

The above exception was the direct cause of the following exception:

Traceback (most recent call last):
  File "/Library/Frameworks/Python.framework/Versions/3.12/lib/python3.12/site-packages/uvicorn/protocols/http/httptools_impl.py", line 401, in run_asgi
    result = await app(  # type: ignore[func-returns-value]
             ^^^^^^^^^^^^^^^^^^^^^^^^^^^^^^^^^^^^^^^^^^^^^^
  File "/Library/Frameworks/Python.framework/Versions/3.12/lib/python3.12/site-packages/uvicorn/middleware/proxy_headers.py", line 70, in __call__
    return await self.app(scope, receive, send)
           ^^^^^^^^^^^^^^^^^^^^^^^^^^^^^^^^^^^^
  File "/Library/Frameworks/Python.framework/Versions/3.12/lib/python3.12/site-packages/fastapi/applications.py", line 1054, in __call__
    await super().__call__(scope, receive, send)
  File "/Library/Frameworks/Python.framework/Versions/3.12/lib/python3.12/site-packages/starlette/applications.py", line 112, in __call__
    await self.middleware_stack(scope, receive, send)
  File "/Library/Frameworks/Python.framework/Versions/3.12/lib/python3.12/site-packages/starlette/middleware/errors.py", line 187, in __call__
    raise exc
  File "/Library/Frameworks/Python.framework/Versions/3.12/lib/python3.12/site-packages/starlette/middleware/errors.py", line 165, in __call__
    await self.app(scope, receive, _send)
  File "/Library/Frameworks/Python.framework/Versions/3.12/lib/python3.12/site-packages/starlette/middleware/cors.py", line 85, in __call__
    await self.app(scope, receive, send)
  File "/Library/Frameworks/Python.framework/Versions/3.12/lib/python3.12/site-packages/starlette/middleware/exceptions.py", line 62, in __call__
    await wrap_app_handling_exceptions(self.app, conn)(scope, receive, send)
  File "/Library/Frameworks/Python.framework/Versions/3.12/lib/python3.12/site-packages/starlette/_exception_handler.py", line 53, in wrapped_app
    raise exc
  File "/Library/Frameworks/Python.framework/Versions/3.12/lib/python3.12/site-packages/starlette/_exception_handler.py", line 42, in wrapped_app
    await app(scope, receive, sender)
  File "/Library/Frameworks/Python.framework/Versions/3.12/lib/python3.12/site-packages/starlette/routing.py", line 715, in __call__
    await self.middleware_stack(scope, receive, send)
  File "/Library/Frameworks/Python.framework/Versions/3.12/lib/python3.12/site-packages/starlette/routing.py", line 735, in app
    await route.handle(scope, receive, send)
  File "/Library/Frameworks/Python.framework/Versions/3.12/lib/python3.12/site-packages/starlette/routing.py", line 288, in handle
    await self.app(scope, receive, send)
  File "/Library/Frameworks/Python.framework/Versions/3.12/lib/python3.12/site-packages/starlette/routing.py", line 76, in app
    await wrap_app_handling_exceptions(app, request)(scope, receive, send)
  File "/Library/Frameworks/Python.framework/Versions/3.12/lib/python3.12/site-packages/starlette/_exception_handler.py", line 53, in wrapped_app
    raise exc
  File "/Library/Frameworks/Python.framework/Versions/3.12/lib/python3.12/site-packages/starlette/_exception_handler.py", line 42, in wrapped_app
    await app(scope, receive, sender)
  File "/Library/Frameworks/Python.framework/Versions/3.12/lib/python3.12/site-packages/starlette/routing.py", line 73, in app
    response = await f(request)
               ^^^^^^^^^^^^^^^^
  File "/Library/Frameworks/Python.framework/Versions/3.12/lib/python3.12/site-packages/fastapi/routing.py", line 301, in app
    raw_response = await run_endpoint_function(
                   ^^^^^^^^^^^^^^^^^^^^^^^^^^^^
  File "/Library/Frameworks/Python.framework/Versions/3.12/lib/python3.12/site-packages/fastapi/routing.py", line 214, in run_endpoint_function
    return await run_in_threadpool(dependant.call, **values)
           ^^^^^^^^^^^^^^^^^^^^^^^^^^^^^^^^^^^^^^^^^^^^^^^^^
  File "/Library/Frameworks/Python.framework/Versions/3.12/lib/python3.12/site-packages/starlette/concurrency.py", line 37, in run_in_threadpool
    return await anyio.to_thread.run_sync(func)
           ^^^^^^^^^^^^^^^^^^^^^^^^^^^^^^^^^^^^
  File "/Library/Frameworks/Python.framework/Versions/3.12/lib/python3.12/site-packages/anyio/to_thread.py", line 56, in run_sync
    return await get_async_backend().run_sync_in_worker_thread(
           ^^^^^^^^^^^^^^^^^^^^^^^^^^^^^^^^^^^^^^^^^^^^^^^^^^^^
  File "/Library/Frameworks/Python.framework/Versions/3.12/lib/python3.12/site-packages/anyio/_backends/_asyncio.py", line 2461, in run_sync_in_worker_thread
    return await future
           ^^^^^^^^^^^^
  File "/Library/Frameworks/Python.framework/Versions/3.12/lib/python3.12/asyncio/futures.py", line 291, in __await__
    yield self  # This tells Task to wait for completion.
    ^^^^^^^^^^
  File "/Library/Frameworks/Python.framework/Versions/3.12/lib/python3.12/asyncio/tasks.py", line 385, in __wakeup
    future.result()
  File "/Library/Frameworks/Python.framework/Versions/3.12/lib/python3.12/asyncio/futures.py", line 203, in result
    raise self._exception.with_traceback(self._exception_tb)
  File "/Library/Frameworks/Python.framework/Versions/3.12/lib/python3.12/site-packages/anyio/_backends/_asyncio.py", line 962, in run
    result = context.run(func, *args)
             ^^^^^^^^^^^^^^^^^^^^^^^^
  File "/Library/Frameworks/Python.framework/Versions/3.12/lib/python3.12/site-packages/aktools/core/api.py", line 141, in root
    received_df = eval("ak." + item_id + "()")
                  ^^^^^^^^^^^^^^^^^^^^^^^^^^^^
  File "<string>", line 1, in <module>
  File "/Library/Frameworks/Python.framework/Versions/3.12/lib/python3.12/site-packages/akshare/stock_a/stock_zh_a_spot.py", line 231, in stock_zh_a_spot_em
    return asyncio.run(stock_zh_a_spot_em_async())
           ^^^^^^^^^^^^^^^^^^^^^^^^^^^^^^^^^^^^^^^
  File "/Library/Frameworks/Python.framework/Versions/3.12/lib/python3.12/site-packages/nest_asyncio.py", line 30, in run
    return loop.run_until_complete(task)
           ^^^^^^^^^^^^^^^^^^^^^^^^^^^^^
  File "/Library/Frameworks/Python.framework/Versions/3.12/lib/python3.12/site-packages/nest_asyncio.py", line 98, in run_until_complete
    return f.result()
           ^^^^^^^^^^
  File "/Library/Frameworks/Python.framework/Versions/3.12/lib/python3.12/asyncio/futures.py", line 203, in result
    raise self._exception.with_traceback(self._exception_tb)
  File "/Library/Frameworks/Python.framework/Versions/3.12/lib/python3.12/asyncio/tasks.py", line 314, in __step_run_and_handle_result
    result = coro.send(None)
             ^^^^^^^^^^^^^^^
  File "/Library/Frameworks/Python.framework/Versions/3.12/lib/python3.12/site-packages/akshare/stock_a/stock_zh_a_spot.py", line 217, in stock_zh_a_spot_em_async
    results = await fetch_all_pages_async(url, params)
              ^^^^^^^^^^^^^^^^^^^^^^^^^^^^^^^^^^^^^^^^
  File "/Library/Frameworks/Python.framework/Versions/3.12/lib/python3.12/site-packages/akshare/stock_a/stock_zh_a_spot.py", line 53, in fetch_all_pages_async
    results = await asyncio.gather(*tasks)
              ^^^^^^^^^^^^^^^^^^^^^^^^^^^^
  File "/Library/Frameworks/Python.framework/Versions/3.12/lib/python3.12/asyncio/tasks.py", line 385, in __wakeup
    future.result()
  File "/Library/Frameworks/Python.framework/Versions/3.12/lib/python3.12/asyncio/tasks.py", line 316, in __step_run_and_handle_result
    result = coro.throw(exc)
             ^^^^^^^^^^^^^^^
  File "/Library/Frameworks/Python.framework/Versions/3.12/lib/python3.12/site-packages/akshare/stock_a/stock_zh_a_spot.py", line 21, in fetch_single_page
    async with session.get(url, params=params, ssl=False) as response:
               ^^^^^^^^^^^^^^^^^^^^^^^^^^^^^^^^^^^^^^^^^^
  File "/Library/Frameworks/Python.framework/Versions/3.12/lib/python3.12/site-packages/aiohttp/client.py", line 1425, in __aenter__
    self._resp: _RetType = await self._coro
                           ^^^^^^^^^^^^^^^^
  File "/Library/Frameworks/Python.framework/Versions/3.12/lib/python3.12/site-packages/aiohttp/client.py", line 707, in _request
    raise ConnectionTimeoutError(
aiohttp.client_exceptions.ConnectionTimeoutError: Connection timeout to host https://82.push2.eastmoney.com/api/qt/clist/get
INFO:     127.0.0.1:61887 - "GET /api/public/stock_zh_a_spot_em HTTP/1.1" 200 OK
INFO:     127.0.0.1:61887 - "GET /api/public/stock_zh_a_spot_em HTTP/1.1" 200 OK
INFO:     127.0.0.1:61887 - "GET /api/public/stock_zh_a_spot_em HTTP/1.1" 200 OK
INFO:     127.0.0.1:62737 - "GET /api/public/stock_zh_a_spot_em HTTP/1.1" 200 OK
INFO:     127.0.0.1:62737 - "GET /api/public/stock_zh_a_spot_em HTTP/1.1" 200 OK
ERROR:    Exception in ASGI application
Traceback (most recent call last):
  File "/Library/Frameworks/Python.framework/Versions/3.12/lib/python3.12/site-packages/aiohttp/connector.py", line 1122, in _wrap_create_connection
    return await self._loop.create_connection(*args, **kwargs, sock=sock)
           ^^^^^^^^^^^^^^^^^^^^^^^^^^^^^^^^^^^^^^^^^^^^^^^^^^^^^^^^^^^^^^
  File "/Library/Frameworks/Python.framework/Versions/3.12/lib/python3.12/asyncio/base_events.py", line 1148, in create_connection
    transport, protocol = await self._create_connection_transport(
                          ^^^^^^^^^^^^^^^^^^^^^^^^^^^^^^^^^^^^^^^^
  File "/Library/Frameworks/Python.framework/Versions/3.12/lib/python3.12/asyncio/base_events.py", line 1181, in _create_connection_transport
    await waiter
  File "/Library/Frameworks/Python.framework/Versions/3.12/lib/python3.12/asyncio/futures.py", line 291, in __await__
    yield self  # This tells Task to wait for completion.
    ^^^^^^^^^^
  File "/Library/Frameworks/Python.framework/Versions/3.12/lib/python3.12/asyncio/tasks.py", line 385, in __wakeup
    future.result()
  File "/Library/Frameworks/Python.framework/Versions/3.12/lib/python3.12/asyncio/futures.py", line 198, in result
    raise exc
asyncio.exceptions.CancelledError

The above exception was the direct cause of the following exception:

Traceback (most recent call last):
  File "/Library/Frameworks/Python.framework/Versions/3.12/lib/python3.12/site-packages/aiohttp/client.py", line 703, in _request
    conn = await self._connector.connect(
           ^^^^^^^^^^^^^^^^^^^^^^^^^^^^^^
  File "/Library/Frameworks/Python.framework/Versions/3.12/lib/python3.12/site-packages/aiohttp/connector.py", line 548, in connect
    proto = await self._create_connection(req, traces, timeout)
            ^^^^^^^^^^^^^^^^^^^^^^^^^^^^^^^^^^^^^^^^^^^^^^^^^^^
  File "/Library/Frameworks/Python.framework/Versions/3.12/lib/python3.12/site-packages/aiohttp/connector.py", line 1056, in _create_connection
    _, proto = await self._create_direct_connection(req, traces, timeout)
               ^^^^^^^^^^^^^^^^^^^^^^^^^^^^^^^^^^^^^^^^^^^^^^^^^^^^^^^^^^
  File "/Library/Frameworks/Python.framework/Versions/3.12/lib/python3.12/site-packages/aiohttp/connector.py", line 1400, in _create_direct_connection
    raise last_exc
  File "/Library/Frameworks/Python.framework/Versions/3.12/lib/python3.12/site-packages/aiohttp/connector.py", line 1369, in _create_direct_connection
    transp, proto = await self._wrap_create_connection(
                    ^^^^^^^^^^^^^^^^^^^^^^^^^^^^^^^^^^^
  File "/Library/Frameworks/Python.framework/Versions/3.12/lib/python3.12/site-packages/aiohttp/connector.py", line 1112, in _wrap_create_connection
    async with ceil_timeout(
               ^^^^^^^^^^^^^
  File "/Library/Frameworks/Python.framework/Versions/3.12/lib/python3.12/asyncio/timeouts.py", line 115, in __aexit__
    raise TimeoutError from exc_val
TimeoutError

The above exception was the direct cause of the following exception:

Traceback (most recent call last):
  File "/Library/Frameworks/Python.framework/Versions/3.12/lib/python3.12/site-packages/uvicorn/protocols/http/httptools_impl.py", line 401, in run_asgi
    result = await app(  # type: ignore[func-returns-value]
             ^^^^^^^^^^^^^^^^^^^^^^^^^^^^^^^^^^^^^^^^^^^^^^
  File "/Library/Frameworks/Python.framework/Versions/3.12/lib/python3.12/site-packages/uvicorn/middleware/proxy_headers.py", line 70, in __call__
    return await self.app(scope, receive, send)
           ^^^^^^^^^^^^^^^^^^^^^^^^^^^^^^^^^^^^
  File "/Library/Frameworks/Python.framework/Versions/3.12/lib/python3.12/site-packages/fastapi/applications.py", line 1054, in __call__
    await super().__call__(scope, receive, send)
  File "/Library/Frameworks/Python.framework/Versions/3.12/lib/python3.12/site-packages/starlette/applications.py", line 112, in __call__
    await self.middleware_stack(scope, receive, send)
  File "/Library/Frameworks/Python.framework/Versions/3.12/lib/python3.12/site-packages/starlette/middleware/errors.py", line 187, in __call__
    raise exc
  File "/Library/Frameworks/Python.framework/Versions/3.12/lib/python3.12/site-packages/starlette/middleware/errors.py", line 165, in __call__
    await self.app(scope, receive, _send)
  File "/Library/Frameworks/Python.framework/Versions/3.12/lib/python3.12/site-packages/starlette/middleware/cors.py", line 85, in __call__
    await self.app(scope, receive, send)
  File "/Library/Frameworks/Python.framework/Versions/3.12/lib/python3.12/site-packages/starlette/middleware/exceptions.py", line 62, in __call__
    await wrap_app_handling_exceptions(self.app, conn)(scope, receive, send)
  File "/Library/Frameworks/Python.framework/Versions/3.12/lib/python3.12/site-packages/starlette/_exception_handler.py", line 53, in wrapped_app
    raise exc
  File "/Library/Frameworks/Python.framework/Versions/3.12/lib/python3.12/site-packages/starlette/_exception_handler.py", line 42, in wrapped_app
    await app(scope, receive, sender)
  File "/Library/Frameworks/Python.framework/Versions/3.12/lib/python3.12/site-packages/starlette/routing.py", line 715, in __call__
    await self.middleware_stack(scope, receive, send)
  File "/Library/Frameworks/Python.framework/Versions/3.12/lib/python3.12/site-packages/starlette/routing.py", line 735, in app
    await route.handle(scope, receive, send)
  File "/Library/Frameworks/Python.framework/Versions/3.12/lib/python3.12/site-packages/starlette/routing.py", line 288, in handle
    await self.app(scope, receive, send)
  File "/Library/Frameworks/Python.framework/Versions/3.12/lib/python3.12/site-packages/starlette/routing.py", line 76, in app
    await wrap_app_handling_exceptions(app, request)(scope, receive, send)
  File "/Library/Frameworks/Python.framework/Versions/3.12/lib/python3.12/site-packages/starlette/_exception_handler.py", line 53, in wrapped_app
    raise exc
  File "/Library/Frameworks/Python.framework/Versions/3.12/lib/python3.12/site-packages/starlette/_exception_handler.py", line 42, in wrapped_app
    await app(scope, receive, sender)
  File "/Library/Frameworks/Python.framework/Versions/3.12/lib/python3.12/site-packages/starlette/routing.py", line 73, in app
    response = await f(request)
               ^^^^^^^^^^^^^^^^
  File "/Library/Frameworks/Python.framework/Versions/3.12/lib/python3.12/site-packages/fastapi/routing.py", line 301, in app
    raw_response = await run_endpoint_function(
                   ^^^^^^^^^^^^^^^^^^^^^^^^^^^^
  File "/Library/Frameworks/Python.framework/Versions/3.12/lib/python3.12/site-packages/fastapi/routing.py", line 214, in run_endpoint_function
    return await run_in_threadpool(dependant.call, **values)
           ^^^^^^^^^^^^^^^^^^^^^^^^^^^^^^^^^^^^^^^^^^^^^^^^^
  File "/Library/Frameworks/Python.framework/Versions/3.12/lib/python3.12/site-packages/starlette/concurrency.py", line 37, in run_in_threadpool
    return await anyio.to_thread.run_sync(func)
           ^^^^^^^^^^^^^^^^^^^^^^^^^^^^^^^^^^^^
  File "/Library/Frameworks/Python.framework/Versions/3.12/lib/python3.12/site-packages/anyio/to_thread.py", line 56, in run_sync
    return await get_async_backend().run_sync_in_worker_thread(
           ^^^^^^^^^^^^^^^^^^^^^^^^^^^^^^^^^^^^^^^^^^^^^^^^^^^^
  File "/Library/Frameworks/Python.framework/Versions/3.12/lib/python3.12/site-packages/anyio/_backends/_asyncio.py", line 2461, in run_sync_in_worker_thread
    return await future
           ^^^^^^^^^^^^
  File "/Library/Frameworks/Python.framework/Versions/3.12/lib/python3.12/asyncio/futures.py", line 291, in __await__
    yield self  # This tells Task to wait for completion.
    ^^^^^^^^^^
  File "/Library/Frameworks/Python.framework/Versions/3.12/lib/python3.12/asyncio/tasks.py", line 385, in __wakeup
    future.result()
  File "/Library/Frameworks/Python.framework/Versions/3.12/lib/python3.12/asyncio/futures.py", line 203, in result
    raise self._exception.with_traceback(self._exception_tb)
  File "/Library/Frameworks/Python.framework/Versions/3.12/lib/python3.12/site-packages/anyio/_backends/_asyncio.py", line 962, in run
    result = context.run(func, *args)
             ^^^^^^^^^^^^^^^^^^^^^^^^
  File "/Library/Frameworks/Python.framework/Versions/3.12/lib/python3.12/site-packages/aktools/core/api.py", line 141, in root
    received_df = eval("ak." + item_id + "()")
                  ^^^^^^^^^^^^^^^^^^^^^^^^^^^^
  File "<string>", line 1, in <module>
  File "/Library/Frameworks/Python.framework/Versions/3.12/lib/python3.12/site-packages/akshare/stock_a/stock_zh_a_spot.py", line 231, in stock_zh_a_spot_em
    return asyncio.run(stock_zh_a_spot_em_async())
           ^^^^^^^^^^^^^^^^^^^^^^^^^^^^^^^^^^^^^^^
  File "/Library/Frameworks/Python.framework/Versions/3.12/lib/python3.12/site-packages/nest_asyncio.py", line 30, in run
    return loop.run_until_complete(task)
           ^^^^^^^^^^^^^^^^^^^^^^^^^^^^^
  File "/Library/Frameworks/Python.framework/Versions/3.12/lib/python3.12/site-packages/nest_asyncio.py", line 98, in run_until_complete
    return f.result()
           ^^^^^^^^^^
  File "/Library/Frameworks/Python.framework/Versions/3.12/lib/python3.12/asyncio/futures.py", line 203, in result
    raise self._exception.with_traceback(self._exception_tb)
  File "/Library/Frameworks/Python.framework/Versions/3.12/lib/python3.12/asyncio/tasks.py", line 314, in __step_run_and_handle_result
    result = coro.send(None)
             ^^^^^^^^^^^^^^^
  File "/Library/Frameworks/Python.framework/Versions/3.12/lib/python3.12/site-packages/akshare/stock_a/stock_zh_a_spot.py", line 217, in stock_zh_a_spot_em_async
    results = await fetch_all_pages_async(url, params)
              ^^^^^^^^^^^^^^^^^^^^^^^^^^^^^^^^^^^^^^^^
  File "/Library/Frameworks/Python.framework/Versions/3.12/lib/python3.12/site-packages/akshare/stock_a/stock_zh_a_spot.py", line 53, in fetch_all_pages_async
    results = await asyncio.gather(*tasks)
              ^^^^^^^^^^^^^^^^^^^^^^^^^^^^
  File "/Library/Frameworks/Python.framework/Versions/3.12/lib/python3.12/asyncio/tasks.py", line 385, in __wakeup
    future.result()
  File "/Library/Frameworks/Python.framework/Versions/3.12/lib/python3.12/asyncio/tasks.py", line 316, in __step_run_and_handle_result
    result = coro.throw(exc)
             ^^^^^^^^^^^^^^^
  File "/Library/Frameworks/Python.framework/Versions/3.12/lib/python3.12/site-packages/akshare/stock_a/stock_zh_a_spot.py", line 21, in fetch_single_page
    async with session.get(url, params=params, ssl=False) as response:
               ^^^^^^^^^^^^^^^^^^^^^^^^^^^^^^^^^^^^^^^^^^
  File "/Library/Frameworks/Python.framework/Versions/3.12/lib/python3.12/site-packages/aiohttp/client.py", line 1425, in __aenter__
    self._resp: _RetType = await self._coro
                           ^^^^^^^^^^^^^^^^
  File "/Library/Frameworks/Python.framework/Versions/3.12/lib/python3.12/site-packages/aiohttp/client.py", line 707, in _request
    raise ConnectionTimeoutError(
aiohttp.client_exceptions.ConnectionTimeoutError: Connection timeout to host https://82.push2.eastmoney.com/api/qt/clist/get
